Process A [NEW] (arrival time 9 ms) 16 CPU bursts (tau 100ms)
Process B [NEW] (arrival time 18 ms) 21 CPU bursts (tau 100ms)
Process C [NEW] (arrival time 42 ms) 4 CPU bursts (tau 100ms)
Process D [NEW] (arrival time 156 ms) 11 CPU bursts (tau 100ms)
Process E [NEW] (arrival time 134 ms) 55 CPU bursts (tau 100ms)
Process F [NEW] (arrival time 106 ms) 34 CPU bursts (tau 100ms)
Process G [NEW] (arrival time 65 ms) 80 CPU bursts (tau 100ms)
Process H [NEW] (arrival time 11 ms) 83 CPU bursts (tau 100ms)
Process I [NEW] (arrival time 68 ms) 77 CPU bursts (tau 100ms)
Process J [NEW] (arrival time 0 ms) 10 CPU bursts (tau 100ms)
Process K [NEW] (arrival time 7 ms) 13 CPU bursts (tau 100ms)
Process L [NEW] (arrival time 189 ms) 7 CPU bursts (tau 100ms)
Process M [NEW] (arrival time 16 ms) 48 CPU bursts (tau 100ms)
Process N [NEW] (arrival time 122 ms) 31 CPU bursts (tau 100ms)
Process O [NEW] (arrival time 29 ms) 31 CPU bursts (tau 100ms)
Process P [NEW] (arrival time 159 ms) 16 CPU bursts (tau 100ms)
time 0ms: Simulator started for SJF [Q <empty>]
time 0ms: Process J (tau 100ms) arrived; added to ready queue [Q J]
time 2ms: Process J (tau 100ms) started using the CPU for 40ms burst [Q <empty>]
time 7ms: Process K (tau 100ms) arrived; added to ready queue [Q K]
time 9ms: Process A (tau 100ms) arrived; added to ready queue [Q A K]
time 11ms: Process H (tau 100ms) arrived; added to ready queue [Q A H K]
time 16ms: Process M (tau 100ms) arrived; added to ready queue [Q A H K M]
time 18ms: Process B (tau 100ms) arrived; added to ready queue [Q A B H K M]
time 29ms: Process O (tau 100ms) arrived; added to ready queue [Q A B H K M O]
time 42ms: Process J (tau 100ms) completed a CPU burst; 9 bursts to go [Q A B H K M O]
time 42ms: Recalculated tau = 55ms for process J [Q A B H K M O]
time 42ms: Process J switching out of CPU; will block on I/O until time 47ms [Q A B H K M O]
time 42ms: Process C (tau 100ms) arrived; added to ready queue [Q A B C H K M O]
time 46ms: Process A (tau 100ms) started using the CPU for 56ms burst [Q B C H K M O]
time 47ms: Process J (tau 55ms) completed I/O; added to ready queue [Q J B C H K M O]
time 65ms: Process G (tau 100ms) arrived; added to ready queue [Q J B C G H K M O]
time 68ms: Process I (tau 100ms) arrived; added to ready queue [Q J B C G H I K M O]
time 102ms: Process A (tau 100ms) completed a CPU burst; 15 bursts to go [Q J B C G H I K M O]
time 102ms: Recalculated tau = 67ms for process A [Q J B C G H I K M O]
time 102ms: Process A switching out of CPU; will block on I/O until time 127ms [Q J B C G H I K M O]
time 106ms: Process J (tau 55ms) started using the CPU for 204ms burst [Q B C G H I K M O]
time 106ms: Process F (tau 100ms) arrived; added to ready queue [Q B C F G H I K M O]
time 122ms: Process N (tau 100ms) arrived; added to ready queue [Q B C F G H I K M N O]
time 127ms: Process A (tau 67ms) completed I/O; added to ready queue [Q A B C F G H I K M N O]
time 134ms: Process E (tau 100ms) arrived; added to ready queue [Q A B C E F G H I K M N O]
time 156ms: Process D (tau 100ms) arrived; added to ready queue [Q A B C D E F G H I K M N O]
time 159ms: Process P (tau 100ms) arrived; added to ready queue [Q A B C D E F G H I K M N O P]
time 189ms: Process L (tau 100ms) arrived; added to ready queue [Q A B C D E F G H I K L M N O P]
time 310ms: Process J (tau 55ms) completed a CPU burst; 8 bursts to go [Q A B C D E F G H I K L M N O P]
time 310ms: Recalculated tau = 167ms for process J [Q A B C D E F G H I K L M N O P]
time 310ms: Process J switching out of CPU; will block on I/O until time 382ms [Q A B C D E F G H I K L M N O P]
time 314ms: Process A (tau 67ms) started using the CPU for 60ms burst [Q B C D E F G H I K L M N O P]
time 374ms: Process A (tau 67ms) completed a CPU burst; 14 bursts to go [Q B C D E F G H I K L M N O P]
time 374ms: Recalculated tau = 62ms for process A [Q B C D E F G H I K L M N O P]
time 374ms: Process A switching out of CPU; will block on I/O until time 529ms [Q B C D E F G H I K L M N O P]
time 378ms: Process B (tau 100ms) started using the CPU for 106ms burst [Q C D E F G H I K L M N O P]
time 382ms: Process J (tau 167ms) completed I/O; added to ready queue [Q C D E F G H I K L M N O P J]
time 484ms: Process B (tau 100ms) completed a CPU burst; 20 bursts to go [Q C D E F G H I K L M N O P J]
time 484ms: Recalculated tau = 105ms for process B [Q C D E F G H I K L M N O P J]
time 484ms: Process B switching out of CPU; will block on I/O until time 642ms [Q C D E F G H I K L M N O P J]
time 488ms: Process C (tau 100ms) started using the CPU for 94ms burst [Q D E F G H I K L M N O P J]
time 529ms: Process A (tau 62ms) completed I/O; added to ready queue [Q A D E F G H I K L M N O P J]
time 582ms: Process C (tau 100ms) completed a CPU burst; 3 bursts to go [Q A D E F G H I K L M N O P J]
time 582ms: Recalculated tau = 96ms for process C [Q A D E F G H I K L M N O P J]
time 582ms: Process C switching out of CPU; will block on I/O until time 742ms [Q A D E F G H I K L M N O P J]
time 586ms: Process A (tau 62ms) started using the CPU for 39ms burst [Q D E F G H I K L M N O P J]
time 625ms: Process A (tau 62ms) completed a CPU burst; 13 bursts to go [Q D E F G H I K L M N O P J]
time 625ms: Recalculated tau = 45ms for process A [Q D E F G H I K L M N O P J]
time 625ms: Process A switching out of CPU; will block on I/O until time 677ms [Q D E F G H I K L M N O P J]
time 629ms: Process D (tau 100ms) started using the CPU for 148ms burst [Q E F G H I K L M N O P J]
time 642ms: Process B (tau 105ms) completed I/O; added to ready queue [Q E F G H I K L M N O P B J]
time 677ms: Process A (tau 45ms) completed I/O; added to ready queue [Q A E F G H I K L M N O P B J]
time 742ms: Process C (tau 96ms) completed I/O; added to ready queue [Q A C E F G H I K L M N O P B J]
time 777ms: Process D (tau 100ms) completed a CPU burst; 10 bursts to go [Q A C E F G H I K L M N O P B J]
time 777ms: Recalculated tau = 136ms for process D [Q A C E F G H I K L M N O P B J]
time 777ms: Process D switching out of CPU; will block on I/O until time 781ms [Q A C E F G H I K L M N O P B J]
time 781ms: Process A (tau 45ms) started using the CPU for 47ms burst [Q C E F G H I K L M N O P B J]
time 781ms: Process D (tau 136ms) completed I/O; added to ready queue [Q C E F G H I K L M N O P B D J]
time 828ms: Process A (tau 45ms) completed a CPU burst; 12 bursts to go [Q C E F G H I K L M N O P B D J]
time 828ms: Recalculated tau = 47ms for process A [Q C E F G H I K L M N O P B D J]
time 828ms: Process A switching out of CPU; will block on I/O until time 832ms [Q C E F G H I K L M N O P B D J]
time 832ms: Process C (tau 96ms) started using the CPU for 117ms burst [Q E F G H I K L M N O P B D J]
time 832ms: Process A (tau 47ms) completed I/O; added to ready queue [Q A E F G H I K L M N O P B D J]
time 949ms: Process C (tau 96ms) completed a CPU burst; 2 bursts to go [Q A E F G H I K L M N O P B D J]
time 949ms: Recalculated tau = 112ms for process C [Q A E F G H I K L M N O P B D J]
time 949ms: Process C switching out of CPU; will block on I/O until time 968ms [Q A E F G H I K L M N O P B D J]
time 953ms: Process A (tau 47ms) started using the CPU for 137ms burst [Q E F G H I K L M N O P B D J]
time 968ms: Process C (tau 112ms) completed I/O; added to ready queue [Q E F G H I K L M N O P B C D J]
time 1090ms: Process A (tau 47ms) completed a CPU burst; 11 bursts to go [Q E F G H I K L M N O P B C D J]
time 1090ms: Recalculated tau = 115ms for process A [Q E F G H I K L M N O P B C D J]
time 1090ms: Process A switching out of CPU; will block on I/O until time 1116ms [Q E F G H I K L M N O P B C D J]
time 1094ms: Process E (tau 100ms) started using the CPU for 152ms burst [Q F G H I K L M N O P B C D J]
time 1116ms: Process A (tau 115ms) completed I/O; added to ready queue [Q F G H I K L M N O P B C A D J]
time 1246ms: Process E (tau 100ms) completed a CPU burst; 54 bursts to go [Q F G H I K L M N O P B C A D J]
time 1246ms: Recalculated tau = 139ms for process E [Q F G H I K L M N O P B C A D J]
time 1246ms: Process E switching out of CPU; will block on I/O until time 1294ms [Q F G H I K L M N O P B C A D J]
time 1250ms: Process F (tau 100ms) started using the CPU for 129ms burst [Q G H I K L M N O P B C A D J]
time 1294ms: Process E (tau 139ms) completed I/O; added to ready queue [Q G H I K L M N O P B C A D E J]
time 1379ms: Process F (tau 100ms) completed a CPU burst; 33 bursts to go [Q G H I K L M N O P B C A D E J]
time 1379ms: Recalculated tau = 122ms for process F [Q G H I K L M N O P B C A D E J]
time 1379ms: Process F switching out of CPU; will block on I/O until time 1438ms [Q G H I K L M N O P B C A D E J]
time 1383ms: Process G (tau 100ms) started using the CPU for 70ms burst [Q H I K L M N O P B C A D E J]
time 1438ms: Process F (tau 122ms) completed I/O; added to ready queue [Q H I K L M N O P B C A F D E J]
time 1453ms: Process G (tau 100ms) completed a CPU burst; 79 bursts to go [Q H I K L M N O P B C A F D E J]
time 1453ms: Recalculated tau = 78ms for process G [Q H I K L M N O P B C A F D E J]
time 1453ms: Process G switching out of CPU; will block on I/O until time 1486ms [Q H I K L M N O P B C A F D E J]
time 1457ms: Process H (tau 100ms) started using the CPU for 96ms burst [Q I K L M N O P B C A F D E J]
time 1486ms: Process G (tau 78ms) completed I/O; added to ready queue [Q G I K L M N O P B C A F D E J]
time 1553ms: Process H (tau 100ms) completed a CPU burst; 82 bursts to go [Q G I K L M N O P B C A F D E J]
time 1553ms: Recalculated tau = 97ms for process H [Q G I K L M N O P B C A F D E J]
time 1553ms: Process H switching out of CPU; will block on I/O until time 1622ms [Q G I K L M N O P B C A F D E J]
time 1557ms: Process G (tau 78ms) started using the CPU for 40ms burst [Q I K L M N O P B C A F D E J]
time 1597ms: Process G (tau 78ms) completed a CPU burst; 78 bursts to go [Q I K L M N O P B C A F D E J]
time 1597ms: Recalculated tau = 50ms for process G [Q I K L M N O P B C A F D E J]
time 1597ms: Process G switching out of CPU; will block on I/O until time 1605ms [Q I K L M N O P B C A F D E J]
time 1601ms: Process I (tau 100ms) started using the CPU for 220ms burst [Q K L M N O P B C A F D E J]
time 1605ms: Process G (tau 50ms) completed I/O; added to ready queue [Q G K L M N O P B C A F D E J]
time 1622ms: Process H (tau 97ms) completed I/O; added to ready queue [Q G H K L M N O P B C A F D E J]
time 1821ms: Process I (tau 100ms) completed a CPU burst; 76 bursts to go [Q G H K L M N O P B C A F D E J]
time 1821ms: Recalculated tau = 190ms for process I [Q G H K L M N O P B C A F D E J]
time 1821ms: Process I switching out of CPU; will block on I/O until time 1842ms [Q G H K L M N O P B C A F D E J]
time 1825ms: Process G (tau 50ms) started using the CPU for 65ms burst [Q H K L M N O P B C A F D E J]
time 1842ms: Process I (tau 190ms) completed I/O; added to ready queue [Q H K L M N O P B C A F D E J I]
time 1890ms: Process G (tau 50ms) completed a CPU burst; 77 bursts to go [Q H K L M N O P B C A F D E J I]
time 1890ms: Recalculated tau = 62ms for process G [Q H K L M N O P B C A F D E J I]
time 1890ms: Process G switching out of CPU; will block on I/O until time 1936ms [Q H K L M N O P B C A F D E J I]
time 1894ms: Process H (tau 97ms) started using the CPU for 48ms burst [Q K L M N O P B C A F D E J I]
time 1936ms: Process G (tau 62ms) completed I/O; added to ready queue [Q G K L M N O P B C A F D E J I]
time 1942ms: Process H (tau 97ms) completed a CPU burst; 81 bursts to go [Q G K L M N O P B C A F D E J I]
time 1942ms: Recalculated tau = 61ms for process H [Q G K L M N O P B C A F D E J I]
time 1942ms: Process H switching out of CPU; will block on I/O until time 1966ms [Q G K L M N O P B C A F D E J I]
time 1946ms: Process G (tau 62ms) started using the CPU for 13ms burst [Q K L M N O P B C A F D E J I]
time 1959ms: Process G (tau 62ms) completed a CPU burst; 76 bursts to go [Q K L M N O P B C A F D E J I]
time 1959ms: Recalculated tau = 26ms for process G [Q K L M N O P B C A F D E J I]
time 1959ms: Process G switching out of CPU; will block on I/O until time 1999ms [Q K L M N O P B C A F D E J I]
time 1963ms: Process K (tau 100ms) started using the CPU for 64ms burst [Q L M N O P B C A F D E J I]
time 1966ms: Process H (tau 61ms) completed I/O; added to ready queue [Q H L M N O P B C A F D E J I]
time 1999ms: Process G (tau 26ms) completed I/O; added to ready queue [Q G H L M N O P B C A F D E J I]
time 2027ms: Process K (tau 100ms) completed a CPU burst; 12 bursts to go [Q G H L M N O P B C A F D E J I]
time 2027ms: Recalculated tau = 73ms for process K [Q G H L M N O P B C A F D E J I]
time 2027ms: Process K switching out of CPU; will block on I/O until time 2125ms [Q G H L M N O P B C A F D E J I]
time 2031ms: Process G (tau 26ms) started using the CPU for 128ms burst [Q H L M N O P B C A F D E J I]
time 2125ms: Process K (tau 73ms) completed I/O; added to ready queue [Q H K L M N O P B C A F D E J I]
time 2159ms: Process G (tau 26ms) completed a CPU burst; 75 bursts to go [Q H K L M N O P B C A F D E J I]
time 2159ms: Recalculated tau = 103ms for process G [Q H K L M N O P B C A F D E J I]
time 2159ms: Process G switching out of CPU; will block on I/O until time 2383ms [Q H K L M N O P B C A F D E J I]
time 2163ms: Process H (tau 61ms) started using the CPU for 72ms burst [Q K L M N O P B C A F D E J I]
time 2235ms: Process H (tau 61ms) completed a CPU burst; 80 bursts to go [Q K L M N O P B C A F D E J I]
time 2235ms: Recalculated tau = 70ms for process H [Q K L M N O P B C A F D E J I]
time 2235ms: Process H switching out of CPU; will block on I/O until time 2279ms [Q K L M N O P B C A F D E J I]
time 2239ms: Process K (tau 73ms) started using the CPU for 56ms burst [Q L M N O P B C A F D E J I]
time 2279ms: Process H (tau 70ms) completed I/O; added to ready queue [Q H L M N O P B C A F D E J I]
time 2295ms: Process K (tau 73ms) completed a CPU burst; 11 bursts to go [Q H L M N O P B C A F D E J I]
time 2295ms: Recalculated tau = 61ms for process K [Q H L M N O P B C A F D E J I]
time 2295ms: Process K switching out of CPU; will block on I/O until time 2370ms [Q H L M N O P B C A F D E J I]
time 2299ms: Process H (tau 70ms) started using the CPU for 12ms burst [Q L M N O P B C A F D E J I]
time 2311ms: Process H (tau 70ms) completed a CPU burst; 79 bursts to go [Q L M N O P B C A F D E J I]
time 2311ms: Recalculated tau = 27ms for process H [Q L M N O P B C A F D E J I]
time 2311ms: Process H switching out of CPU; will block on I/O until time 2326ms [Q L M N O P B C A F D E J I]
time 2315ms: Process L (tau 100ms) started using the CPU for 135ms burst [Q M N O P B C A F D E J I]
time 2326ms: Process H (tau 27ms) completed I/O; added to ready queue [Q H M N O P B C A F D E J I]
time 2370ms: Process K (tau 61ms) completed I/O; added to ready queue [Q H K M N O P B C A F D E J I]
time 2383ms: Process G (tau 103ms) completed I/O; added to ready queue [Q H K M N O P G B C A F D E J I]
time 2450ms: Process L (tau 100ms) completed a CPU burst; 6 bursts to go [Q H K M N O P G B C A F D E J I]
time 2450ms: Recalculated tau = 127ms for process L [Q H K M N O P G B C A F D E J I]
time 2450ms: Process L switching out of CPU; will block on I/O until time 2526ms [Q H K M N O P G B C A F D E J I]
time 2454ms: Process H (tau 27ms) started using the CPU for 41ms burst [Q K M N O P G B C A F D E J I]
time 2495ms: Process H (tau 27ms) completed a CPU burst; 78 bursts to go [Q K M N O P G B C A F D E J I]
time 2495ms: Recalculated tau = 38ms for process H [Q K M N O P G B C A F D E J I]
time 2495ms: Process H switching out of CPU; will block on I/O until time 2518ms [Q K M N O P G B C A F D E J I]
time 2499ms: Process K (tau 61ms) started using the CPU for 6ms burst [Q M N O P G B C A F D E J I]
time 2505ms: Process K (tau 61ms) completed a CPU burst; 10 bursts to go [Q M N O P G B C A F D E J I]
time 2505ms: Recalculated tau = 20ms for process K [Q M N O P G B C A F D E J I]
time 2505ms: Process K switching out of CPU; will block on I/O until time 2577ms [Q M N O P G B C A F D E J I]
time 2509ms: Process M (tau 100ms) started using the CPU for 22ms burst [Q N O P G B C A F D E J I]
time 2518ms: Process H (tau 38ms) completed I/O; added to ready queue [Q H N O P G B C A F D E J I]
time 2526ms: Process L (tau 127ms) completed I/O; added to ready queue [Q H N O P G B C A F L D E J I]
time 2531ms: Process M (tau 100ms) completed a CPU burst; 47 bursts to go [Q H N O P G B C A F L D E J I]
time 2531ms: Recalculated tau = 42ms for process M [Q H N O P G B C A F L D E J I]
time 2531ms: Process M switching out of CPU; will block on I/O until time 2550ms [Q H N O P G B C A F L D E J I]
time 2535ms: Process H (tau 38ms) started using the CPU for 160ms burst [Q N O P G B C A F L D E J I]
time 2550ms: Process M (tau 42ms) completed I/O; added to ready queue [Q M N O P G B C A F L D E J I]
time 2577ms: Process K (tau 20ms) completed I/O; added to ready queue [Q K M N O P G B C A F L D E J I]
time 2695ms: Process H (tau 38ms) completed a CPU burst; 77 bursts to go [Q K M N O P G B C A F L D E J I]
time 2695ms: Recalculated tau = 130ms for process H [Q K M N O P G B C A F L D E J I]
time 2695ms: Process H switching out of CPU; will block on I/O until time 2757ms [Q K M N O P G B C A F L D E J I]
time 2699ms: Process K (tau 20ms) started using the CPU for 6ms burst [Q M N O P G B C A F L D E J I]
time 2705ms: Process K (tau 20ms) completed a CPU burst; 9 bursts to go [Q M N O P G B C A F L D E J I]
time 2705ms: Recalculated tau = 10ms for process K [Q M N O P G B C A F L D E J I]
time 2705ms: Process K switching out of CPU; will block on I/O until time 2782ms [Q M N O P G B C A F L D E J I]
time 2709ms: Process M (tau 42ms) started using the CPU for 93ms burst [Q N O P G B C A F L D E J I]
time 2757ms: Process H (tau 130ms) completed I/O; added to ready queue [Q N O P G B C A F L H D E J I]
time 2782ms: Process K (tau 10ms) completed I/O; added to ready queue [Q K N O P G B C A F L H D E J I]
time 2802ms: Process M (tau 42ms) completed a CPU burst; 46 bursts to go [Q K N O P G B C A F L H D E J I]
time 2802ms: Recalculated tau = 81ms for process M [Q K N O P G B C A F L H D E J I]
time 2802ms: Process M switching out of CPU; will block on I/O until time 2846ms [Q K N O P G B C A F L H D E J I]
time 2806ms: Process K (tau 10ms) started using the CPU for 157ms burst [Q N O P G B C A F L H D E J I]
time 2846ms: Process M (tau 81ms) completed I/O; added to ready queue [Q M N O P G B C A F L H D E J I]
time 2963ms: Process K (tau 10ms) completed a CPU burst; 8 bursts to go [Q M N O P G B C A F L H D E J I]
time 2963ms: Recalculated tau = 121ms for process K [Q M N O P G B C A F L H D E J I]
time 2963ms: Process K switching out of CPU; will block on I/O until time 2981ms [Q M N O P G B C A F L H D E J I]
time 2967ms: Process M (tau 81ms) started using the CPU for 79ms burst [Q N O P G B C A F L H D E J I]
time 2981ms: Process K (tau 121ms) completed I/O; added to ready queue [Q N O P G B C A K F L H D E J I]
time 3046ms: Process M (tau 81ms) completed a CPU burst; 45 bursts to go [Q N O P G B C A K F L H D E J I]
time 3046ms: Recalculated tau = 80ms for process M [Q N O P G B C A K F L H D E J I]
time 3046ms: Process M switching out of CPU; will block on I/O until time 3162ms [Q N O P G B C A K F L H D E J I]
time 3050ms: Process N (tau 100ms) started using the CPU for 213ms burst [Q O P G B C A K F L H D E J I]
time 3162ms: Process M (tau 80ms) completed I/O; added to ready queue [Q M O P G B C A K F L H D E J I]
time 3263ms: Process N (tau 100ms) completed a CPU burst; 30 bursts to go [Q M O P G B C A K F L H D E J I]
time 3263ms: Recalculated tau = 185ms for process N [Q M O P G B C A K F L H D E J I]
time 3263ms: Process N switching out of CPU; will block on I/O until time 3280ms [Q M O P G B C A K F L H D E J I]
time 3267ms: Process M (tau 80ms) started using the CPU for 18ms burst [Q O P G B C A K F L H D E J I]
time 3280ms: Process N (tau 185ms) completed I/O; added to ready queue [Q O P G B C A K F L H D E J N I]
time 3285ms: Process M (tau 80ms) completed a CPU burst; 44 bursts to go [Q O P G B C A K F L H D E J N I]
time 3285ms: Recalculated tau = 34ms for process M [Q O P G B C A K F L H D E J N I]
time 3285ms: Process M switching out of CPU; will block on I/O until time 3484ms [Q O P G B C A K F L H D E J N I]
time 3289ms: Process O (tau 100ms) started using the CPU for 156ms burst [Q P G B C A K F L H D E J N I]
time 3445ms: Process O (tau 100ms) completed a CPU burst; 30 bursts to go [Q P G B C A K F L H D E J N I]
time 3445ms: Recalculated tau = 142ms for process O [Q P G B C A K F L H D E J N I]
time 3445ms: Process O switching out of CPU; will block on I/O until time 3514ms [Q P G B C A K F L H D E J N I]
time 3449ms: Process P (tau 100ms) started using the CPU for 4ms burst [Q G B C A K F L H D E J N I]
time 3453ms: Process P (tau 100ms) completed a CPU burst; 15 bursts to go [Q G B C A K F L H D E J N I]
time 3453ms: Recalculated tau = 28ms for process P [Q G B C A K F L H D E J N I]
time 3453ms: Process P switching out of CPU; will block on I/O until time 3640ms [Q G B C A K F L H D E J N I]
time 3457ms: Process G (tau 103ms) started using the CPU for 15ms burst [Q B C A K F L H D E J N I]
time 3472ms: Process G (tau 103ms) completed a CPU burst; 74 bursts to go [Q B C A K F L H D E J N I]
time 3472ms: Recalculated tau = 37ms for process G [Q B C A K F L H D E J N I]
time 3472ms: Process G switching out of CPU; will block on I/O until time 3568ms [Q B C A K F L H D E J N I]
time 3476ms: Process B (tau 105ms) started using the CPU for 198ms burst [Q C A K F L H D E J N I]
time 3484ms: Process M (tau 34ms) completed I/O; added to ready queue [Q M C A K F L H D E J N I]
time 3514ms: Process O (tau 142ms) completed I/O; added to ready queue [Q M C A K F L H D E O J N I]
time 3568ms: Process G (tau 37ms) completed I/O; added to ready queue [Q M G C A K F L H D E O J N I]
time 3640ms: Process P (tau 28ms) completed I/O; added to ready queue [Q P M G C A K F L H D E O J N I]
time 3674ms: Process B (tau 105ms) completed a CPU burst; 19 bursts to go [Q P M G C A K F L H D E O J N I]
time 3674ms: Recalculated tau = 175ms for process B [Q P M G C A K F L H D E O J N I]
time 3674ms: Process B switching out of CPU; will block on I/O until time 3789ms [Q P M G C A K F L H D E O J N I]
time 3678ms: Process P (tau 28ms) started using the CPU for 52ms burst [Q M G C A K F L H D E O J N I]
time 3730ms: Process P (tau 28ms) completed a CPU burst; 14 bursts to go [Q M G C A K F L H D E O J N I]
time 3730ms: Recalculated tau = 46ms for process P [Q M G C A K F L H D E O J N I]
time 3730ms: Process P switching out of CPU; will block on I/O until time 3841ms [Q M G C A K F L H D E O J N I]
time 3734ms: Process M (tau 34ms) started using the CPU for 66ms burst [Q G C A K F L H D E O J N I]
time 3789ms: Process B (tau 175ms) completed I/O; added to ready queue [Q G C A K F L H D E O J B N I]
time 3800ms: Process M (tau 34ms) completed a CPU burst; 43 bursts to go [Q G C A K F L H D E O J B N I]
time 3800ms: Recalculated tau = 58ms for process M [Q G C A K F L H D E O J B N I]
time 3800ms: Process M switching out of CPU; will block on I/O until time 3983ms [Q G C A K F L H D E O J B N I]
time 3804ms: Process G (tau 37ms) started using the CPU for 112ms burst [Q C A K F L H D E O J B N I]
time 3841ms: Process P (tau 46ms) completed I/O; added to ready queue [Q P C A K F L H D E O J B N I]
time 3916ms: Process G (tau 37ms) completed a CPU burst; 73 bursts to go [Q P C A K F L H D E O J B N I]
time 3916ms: Recalculated tau = 94ms for process G [Q P C A K F L H D E O J B N I]
time 3916ms: Process G switching out of CPU; will block on I/O until time 3961ms [Q P C A K F L H D E O J B N I]
time 3920ms: Process P (tau 46ms) started using the CPU for 56ms burst [Q C A K F L H D E O J B N I]
time 3961ms: Process G (tau 94ms) completed I/O; added to ready queue [Q G C A K F L H D E O J B N I]
time 3976ms: Process P (tau 46ms) completed a CPU burst; 13 bursts to go [Q G C A K F L H D E O J B N I]
time 3976ms: Recalculated tau = 54ms for process P [Q G C A K F L H D E O J B N I]
time 3976ms: Process P switching out of CPU; will block on I/O until time 4099ms [Q G C A K F L H D E O J B N I]
time 3980ms: Process G (tau 94ms) started using the CPU for 30ms burst [Q C A K F L H D E O J B N I]
time 3983ms: Process M (tau 58ms) completed I/O; added to ready queue [Q M C A K F L H D E O J B N I]
time 4010ms: Process G (tau 94ms) completed a CPU burst; 72 bursts to go [Q M C A K F L H D E O J B N I]
time 4010ms: Recalculated tau = 46ms for process G [Q M C A K F L H D E O J B N I]
time 4010ms: Process G switching out of CPU; will block on I/O until time 4059ms [Q M C A K F L H D E O J B N I]
time 4014ms: Process M (tau 58ms) started using the CPU for 103ms burst [Q C A K F L H D E O J B N I]
time 4059ms: Process G (tau 46ms) completed I/O; added to ready queue [Q G C A K F L H D E O J B N I]
time 4099ms: Process P (tau 54ms) completed I/O; added to ready queue [Q G P C A K F L H D E O J B N I]
time 4117ms: Process M (tau 58ms) completed a CPU burst; 42 bursts to go [Q G P C A K F L H D E O J B N I]
time 4117ms: Recalculated tau = 92ms for process M [Q G P C A K F L H D E O J B N I]
time 4117ms: Process M switching out of CPU; will block on I/O until time 4159ms [Q G P C A K F L H D E O J B N I]
time 4121ms: Process G (tau 46ms) started using the CPU for 50ms burst [Q P C A K F L H D E O J B N I]
time 4159ms: Process M (tau 92ms) completed I/O; added to ready queue [Q P M C A K F L H D E O J B N I]
time 4171ms: Process G (tau 46ms) completed a CPU burst; 71 bursts to go [Q P M C A K F L H D E O J B N I]
time 4171ms: Recalculated tau = 49ms for process G [Q P M C A K F L H D E O J B N I]
time 4171ms: Process G switching out of CPU; will block on I/O until time 4393ms [Q P M C A K F L H D E O J B N I]
time 4175ms: Process P (tau 54ms) started using the CPU for 155ms burst [Q M C A K F L H D E O J B N I]
time 4330ms: Process P (tau 54ms) completed a CPU burst; 12 bursts to go [Q M C A K F L H D E O J B N I]
time 4330ms: Recalculated tau = 130ms for process P [Q M C A K F L H D E O J B N I]
time 4330ms: Process P switching out of CPU; will block on I/O until time 4450ms [Q M C A K F L H D E O J B N I]
time 4334ms: Process M (tau 92ms) started using the CPU for 171ms burst [Q C A K F L H D E O J B N I]
time 4393ms: Process G (tau 49ms) completed I/O; added to ready queue [Q G C A K F L H D E O J B N I]
time 4450ms: Process P (tau 130ms) completed I/O; added to ready queue [Q G C A K F L H P D E O J B N I]
time 4505ms: Process M (tau 92ms) completed a CPU burst; 41 bursts to go [Q G C A K F L H P D E O J B N I]
time 4505ms: Recalculated tau = 152ms for process M [Q G C A K F L H P D E O J B N I]
time 4505ms: Process M switching out of CPU; will block on I/O until time 4528ms [Q G C A K F L H P D E O J B N I]
time 4509ms: Process G (tau 49ms) started using the CPU for 5ms burst [Q C A K F L H P D E O J B N I]
time 4514ms: Process G (tau 49ms) completed a CPU burst; 70 bursts to go [Q C A K F L H P D E O J B N I]
time 4514ms: Recalculated tau = 16ms for process G [Q C A K F L H P D E O J B N I]
time 4514ms: Process G switching out of CPU; will block on I/O until time 4714ms [Q C A K F L H P D E O J B N I]
time 4518ms: Process C (tau 112ms) started using the CPU for 85ms burst [Q A K F L H P D E O J B N I]
time 4528ms: Process M (tau 152ms) completed I/O; added to ready queue [Q A K F L H P D E O M J B N I]
time 4603ms: Process C (tau 112ms) completed a CPU burst; 1 burst to go [Q A K F L H P D E O M J B N I]
time 4603ms: Recalculated tau = 92ms for process C [Q A K F L H P D E O M J B N I]
time 4603ms: Process C switching out of CPU; will block on I/O until time 4626ms [Q A K F L H P D E O M J B N I]
time 4607ms: Process A (tau 115ms) started using the CPU for 64ms burst [Q K F L H P D E O M J B N I]
time 4626ms: Process C (tau 92ms) completed I/O; added to ready queue [Q C K F L H P D E O M J B N I]
time 4671ms: Process A (tau 115ms) completed a CPU burst; 10 bursts to go [Q C K F L H P D E O M J B N I]
time 4671ms: Recalculated tau = 77ms for process A [Q C K F L H P D E O M J B N I]
time 4671ms: Process A switching out of CPU; will block on I/O until time 4688ms [Q C K F L H P D E O M J B N I]
time 4675ms: Process C (tau 92ms) started using the CPU for 79ms burst [Q K F L H P D E O M J B N I]
time 4688ms: Process A (tau 77ms) completed I/O; added to ready queue [Q A K F L H P D E O M J B N I]
time 4714ms: Process G (tau 16ms) completed I/O; added to ready queue [Q G A K F L H P D E O M J B N I]
time 4754ms: Process C terminated [Q G A K F L H P D E O M J B N I]
time 4758ms: Process G (tau 16ms) started using the CPU for 122ms burst [Q A K F L H P D E O M J B N I]
time 4880ms: Process G (tau 16ms) completed a CPU burst; 69 bursts to go [Q A K F L H P D E O M J B N I]
time 4880ms: Recalculated tau = 96ms for process G [Q A K F L H P D E O M J B N I]
time 4880ms: Process G switching out of CPU; will block on I/O until time 4917ms [Q A K F L H P D E O M J B N I]
time 4884ms: Process A (tau 77ms) started using the CPU for 68ms burst [Q K F L H P D E O M J B N I]
time 4917ms: Process G (tau 96ms) completed I/O; added to ready queue [Q G K F L H P D E O M J B N I]
time 4952ms: Process A (tau 77ms) completed a CPU burst; 9 bursts to go [Q G K F L H P D E O M J B N I]
time 4952ms: Recalculated tau = 71ms for process A [Q G K F L H P D E O M J B N I]
time 4952ms: Process A switching out of CPU; will block on I/O until time 5018ms [Q G K F L H P D E O M J B N I]
time 4956ms: Process G (tau 96ms) started using the CPU for 31ms burst [Q K F L H P D E O M J B N I]
time 4987ms: Process G (tau 96ms) completed a CPU burst; 68 bursts to go [Q K F L H P D E O M J B N I]
time 4987ms: Recalculated tau = 48ms for process G [Q K F L H P D E O M J B N I]
time 4987ms: Process G switching out of CPU; will block on I/O until time 4996ms [Q K F L H P D E O M J B N I]
time 4991ms: Process K (tau 121ms) started using the CPU for 104ms burst [Q F L H P D E O M J B N I]
time 4996ms: Process G (tau 48ms) completed I/O; added to ready queue [Q G F L H P D E O M J B N I]
time 5018ms: Process A (tau 71ms) completed I/O; added to ready queue [Q G A F L H P D E O M J B N I]
time 5095ms: Process K (tau 121ms) completed a CPU burst; 7 bursts to go [Q G A F L H P D E O M J B N I]
time 5095ms: Recalculated tau = 109ms for process K [Q G A F L H P D E O M J B N I]
time 5095ms: Process K switching out of CPU; will block on I/O until time 5242ms [Q G A F L H P D E O M J B N I]
time 5099ms: Process G (tau 48ms) started using the CPU for 61ms burst [Q A F L H P D E O M J B N I]
time 5160ms: Process G (tau 48ms) completed a CPU burst; 67 bursts to go [Q A F L H P D E O M J B N I]
time 5160ms: Recalculated tau = 58ms for process G [Q A F L H P D E O M J B N I]
time 5160ms: Process G switching out of CPU; will block on I/O until time 5236ms [Q A F L H P D E O M J B N I]
time 5164ms: Process A (tau 71ms) started using the CPU for 113ms burst [Q F L H P D E O M J B N I]
time 5236ms: Process G (tau 58ms) completed I/O; added to ready queue [Q G F L H P D E O M J B N I]
time 5242ms: Process K (tau 109ms) completed I/O; added to ready queue [Q G K F L H P D E O M J B N I]
time 5277ms: Process A (tau 71ms) completed a CPU burst; 8 bursts to go [Q G K F L H P D E O M J B N I]
time 5277ms: Recalculated tau = 103ms for process A [Q G K F L H P D E O M J B N I]
time 5277ms: Process A switching out of CPU; will block on I/O until time 5295ms [Q G K F L H P D E O M J B N I]
time 5281ms: Process G (tau 58ms) started using the CPU for 7ms burst [Q K F L H P D E O M J B N I]
time 5288ms: Process G (tau 58ms) completed a CPU burst; 66 bursts to go [Q K F L H P D E O M J B N I]
time 5288ms: Recalculated tau = 20ms for process G [Q K F L H P D E O M J B N I]
time 5288ms: Process G switching out of CPU; will block on I/O until time 5454ms [Q K F L H P D E O M J B N I]
time 5292ms: Process K (tau 109ms) started using the CPU for 86ms burst [Q F L H P D E O M J B N I]
time 5295ms: Process A (tau 103ms) completed I/O; added to ready queue [Q A F L H P D E O M J B N I]
time 5378ms: Process K (tau 109ms) completed a CPU burst; 6 bursts to go [Q A F L H P D E O M J B N I]
time 5378ms: Recalculated tau = 92ms for process K [Q A F L H P D E O M J B N I]
time 5378ms: Process K switching out of CPU; will block on I/O until time 5408ms [Q A F L H P D E O M J B N I]
time 5382ms: Process A (tau 103ms) started using the CPU for 11ms burst [Q F L H P D E O M J B N I]
time 5393ms: Process A (tau 103ms) completed a CPU burst; 7 bursts to go [Q F L H P D E O M J B N I]
time 5393ms: Recalculated tau = 34ms for process A [Q F L H P D E O M J B N I]
time 5393ms: Process A switching out of CPU; will block on I/O until time 5557ms [Q F L H P D E O M J B N I]
time 5397ms: Process F (tau 122ms) started using the CPU for 39ms burst [Q L H P D E O M J B N I]
time 5408ms: Process K (tau 92ms) completed I/O; added to ready queue [Q K L H P D E O M J B N I]
time 5436ms: Process F (tau 122ms) completed a CPU burst; 32 bursts to go [Q K L H P D E O M J B N I]
time 5436ms: Recalculated tau = 60ms for process F [Q K L H P D E O M J B N I]
time 5436ms: Process F switching out of CPU; will block on I/O until time 5503ms [Q K L H P D E O M J B N I]
time 5440ms: Process K (tau 92ms) started using the CPU for 50ms burst [Q L H P D E O M J B N I]
time 5454ms: Process G (tau 20ms) completed I/O; added to ready queue [Q G L H P D E O M J B N I]
time 5490ms: Process K (tau 92ms) completed a CPU burst; 5 bursts to go [Q G L H P D E O M J B N I]
time 5490ms: Recalculated tau = 61ms for process K [Q G L H P D E O M J B N I]
time 5490ms: Process K switching out of CPU; will block on I/O until time 5542ms [Q G L H P D E O M J B N I]
time 5494ms: Process G (tau 20ms) started using the CPU for 2ms burst [Q L H P D E O M J B N I]
time 5496ms: Process G (tau 20ms) completed a CPU burst; 65 bursts to go [Q L H P D E O M J B N I]
time 5496ms: Recalculated tau = 7ms for process G [Q L H P D E O M J B N I]
time 5496ms: Process G switching out of CPU; will block on I/O until time 5509ms [Q L H P D E O M J B N I]
time 5500ms: Process L (tau 127ms) started using the CPU for 4ms burst [Q H P D E O M J B N I]
time 5503ms: Process F (tau 60ms) completed I/O; added to ready queue [Q F H P D E O M J B N I]
time 5504ms: Process L (tau 127ms) completed a CPU burst; 5 bursts to go [Q F H P D E O M J B N I]
time 5504ms: Recalculated tau = 35ms for process L [Q F H P D E O M J B N I]
time 5504ms: Process L switching out of CPU; will block on I/O until time 5548ms [Q F H P D E O M J B N I]
time 5508ms: Process F (tau 60ms) started using the CPU for 195ms burst [Q H P D E O M J B N I]
time 5509ms: Process G (tau 7ms) completed I/O; added to ready queue [Q G H P D E O M J B N I]
time 5542ms: Process K (tau 61ms) completed I/O; added to ready queue [Q G K H P D E O M J B N I]
time 5548ms: Process L (tau 35ms) completed I/O; added to ready queue [Q G L K H P D E O M J B N I]
time 5557ms: Process A (tau 34ms) completed I/O; added to ready queue [Q G A L K H P D E O M J B N I]
time 5703ms: Process F (tau 60ms) completed a CPU burst; 31 bursts to go [Q G A L K H P D E O M J B N I]
time 5703ms: Recalculated tau = 162ms for process F [Q G A L K H P D E O M J B N I]
time 5703ms: Process F switching out of CPU; will block on I/O until time 5706ms [Q G A L K H P D E O M J B N I]
time 5706ms: Process F (tau 162ms) completed I/O; added to ready queue [Q A L K H P D E O M F J B N I]
time 5707ms: Process G (tau 7ms) started using the CPU for 209ms burst [Q A L K H P D E O M F J B N I]
time 5916ms: Process G (tau 7ms) completed a CPU burst; 64 bursts to go [Q A L K H P D E O M F J B N I]
time 5916ms: Recalculated tau = 159ms for process G [Q A L K H P D E O M F J B N I]
time 5916ms: Process G switching out of CPU; will block on I/O until time 5966ms [Q A L K H P D E O M F J B N I]
time 5920ms: Process A (tau 34ms) started using the CPU for 24ms burst [Q L K H P D E O M F J B N I]
time 5944ms: Process A (tau 34ms) completed a CPU burst; 6 bursts to go [Q L K H P D E O M F J B N I]
time 5944ms: Recalculated tau = 27ms for process A [Q L K H P D E O M F J B N I]
time 5944ms: Process A switching out of CPU; will block on I/O until time 6063ms [Q L K H P D E O M F J B N I]
time 5948ms: Process L (tau 35ms) started using the CPU for 69ms burst [Q K H P D E O M F J B N I]
time 5966ms: Process G (tau 159ms) completed I/O; added to ready queue [Q K H P D E O M G F J B N I]
time 6017ms: Process L (tau 35ms) completed a CPU burst; 4 bursts to go [Q K H P D E O M G F J B N I]
time 6017ms: Recalculated tau = 61ms for process L [Q K H P D E O M G F J B N I]
time 6017ms: Process L switching out of CPU; will block on I/O until time 6114ms [Q K H P D E O M G F J B N I]
time 6021ms: Process K (tau 61ms) started using the CPU for 4ms burst [Q H P D E O M G F J B N I]
time 6025ms: Process K (tau 61ms) completed a CPU burst; 4 bursts to go [Q H P D E O M G F J B N I]
time 6025ms: Recalculated tau = 19ms for process K [Q H P D E O M G F J B N I]
time 6025ms: Process K switching out of CPU; will block on I/O until time 6087ms [Q H P D E O M G F J B N I]
time 6029ms: Process H (tau 130ms) started using the CPU for 28ms burst [Q P D E O M G F J B N I]
time 6057ms: Process H (tau 130ms) completed a CPU burst; 76 bursts to go [Q P D E O M G F J B N I]
time 6057ms: Recalculated tau = 54ms for process H [Q P D E O M G F J B N I]
time 6057ms: Process H switching out of CPU; will block on I/O until time 6155ms [Q P D E O M G F J B N I]
time 6061ms: Process P (tau 130ms) started using the CPU for 4ms burst [Q D E O M G F J B N I]
time 6063ms: Process A (tau 27ms) completed I/O; added to ready queue [Q A D E O M G F J B N I]
time 6065ms: Process P (tau 130ms) completed a CPU burst; 11 bursts to go [Q A D E O M G F J B N I]
time 6065ms: Recalculated tau = 36ms for process P [Q A D E O M G F J B N I]
time 6065ms: Process P switching out of CPU; will block on I/O until time 6246ms [Q A D E O M G F J B N I]
time 6069ms: Process A (tau 27ms) started using the CPU for 76ms burst [Q D E O M G F J B N I]
time 6087ms: Process K (tau 19ms) completed I/O; added to ready queue [Q K D E O M G F J B N I]
time 6114ms: Process L (tau 61ms) completed I/O; added to ready queue [Q K L D E O M G F J B N I]
time 6145ms: Process A (tau 27ms) completed a CPU burst; 5 bursts to go [Q K L D E O M G F J B N I]
time 6145ms: Recalculated tau = 64ms for process A [Q K L D E O M G F J B N I]
time 6145ms: Process A switching out of CPU; will block on I/O until time 6175ms [Q K L D E O M G F J B N I]
time 6149ms: Process K (tau 19ms) started using the CPU for 21ms burst [Q L D E O M G F J B N I]
time 6155ms: Process H (tau 54ms) completed I/O; added to ready queue [Q H L D E O M G F J B N I]
time 6170ms: Process K (tau 19ms) completed a CPU burst; 3 bursts to go [Q H L D E O M G F J B N I]
time 6170ms: Recalculated tau = 21ms for process K [Q H L D E O M G F J B N I]
time 6170ms: Process K switching out of CPU; will block on I/O until time 6237ms [Q H L D E O M G F J B N I]
time 6174ms: Process H (tau 54ms) started using the CPU for 51ms burst [Q L D E O M G F J B N I]
time 6175ms: Process A (tau 64ms) completed I/O; added to ready queue [Q L A D E O M G F J B N I]
time 6225ms: Process H (tau 54ms) completed a CPU burst; 75 bursts to go [Q L A D E O M G F J B N I]
time 6225ms: Recalculated tau = 52ms for process H [Q L A D E O M G F J B N I]
time 6225ms: Process H switching out of CPU; will block on I/O until time 6250ms [Q L A D E O M G F J B N I]
time 6229ms: Process L (tau 61ms) started using the CPU for 25ms burst [Q A D E O M G F J B N I]
time 6237ms: Process K (tau 21ms) completed I/O; added to ready queue [Q K A D E O M G F J B N I]
time 6246ms: Process P (tau 36ms) completed I/O; added to ready queue [Q K P A D E O M G F J B N I]
time 6250ms: Process H (tau 52ms) completed I/O; added to ready queue [Q K P H A D E O M G F J B N I]
time 6254ms: Process L (tau 61ms) completed a CPU burst; 3 bursts to go [Q K P H A D E O M G F J B N I]
time 6254ms: Recalculated tau = 34ms for process L [Q K P H A D E O M G F J B N I]
time 6254ms: Process L switching out of CPU; will block on I/O until time 6375ms [Q K P H A D E O M G F J B N I]
time 6258ms: Process K (tau 21ms) started using the CPU for 120ms burst [Q P H A D E O M G F J B N I]
time 6375ms: Process L (tau 34ms) completed I/O; added to ready queue [Q L P H A D E O M G F J B N I]
time 6378ms: Process K (tau 21ms) completed a CPU burst; 2 bursts to go [Q L P H A D E O M G F J B N I]
time 6378ms: Recalculated tau = 96ms for process K [Q L P H A D E O M G F J B N I]
time 6378ms: Process K switching out of CPU; will block on I/O until time 6449ms [Q L P H A D E O M G F J B N I]
time 6382ms: Process L (tau 34ms) started using the CPU for 2ms burst [Q P H A D E O M G F J B N I]
time 6384ms: Process L (tau 34ms) completed a CPU burst; 2 bursts to go [Q P H A D E O M G F J B N I]
time 6384ms: Recalculated tau = 10ms for process L [Q P H A D E O M G F J B N I]
time 6384ms: Process L switching out of CPU; will block on I/O until time 6423ms [Q P H A D E O M G F J B N I]
time 6388ms: Process P (tau 36ms) started using the CPU for 105ms burst [Q H A D E O M G F J B N I]
time 6423ms: Process L (tau 10ms) completed I/O; added to ready queue [Q L H A D E O M G F J B N I]
time 6449ms: Process K (tau 96ms) completed I/O; added to ready queue [Q L H A K D E O M G F J B N I]
time 6493ms: Process P (tau 36ms) completed a CPU burst; 10 bursts to go [Q L H A K D E O M G F J B N I]
time 6493ms: Recalculated tau = 88ms for process P [Q L H A K D E O M G F J B N I]
time 6493ms: Process P switching out of CPU; will block on I/O until time 6554ms [Q L H A K D E O M G F J B N I]
time 6497ms: Process L (tau 10ms) started using the CPU for 164ms burst [Q H A K D E O M G F J B N I]
time 6554ms: Process P (tau 88ms) completed I/O; added to ready queue [Q H A P K D E O M G F J B N I]
time 6661ms: Process L (tau 10ms) completed a CPU burst; 1 burst to go [Q H A P K D E O M G F J B N I]
time 6661ms: Recalculated tau = 126ms for process L [Q H A P K D E O M G F J B N I]
time 6661ms: Process L switching out of CPU; will block on I/O until time 6713ms [Q H A P K D E O M G F J B N I]
time 6665ms: Process H (tau 52ms) started using the CPU for 87ms burst [Q A P K D E O M G F J B N I]
time 6713ms: Process L (tau 126ms) completed I/O; added to ready queue [Q A P K L D E O M G F J B N I]
time 6752ms: Process H (tau 52ms) completed a CPU burst; 74 bursts to go [Q A P K L D E O M G F J B N I]
time 6752ms: Recalculated tau = 79ms for process H [Q A P K L D E O M G F J B N I]
time 6752ms: Process H switching out of CPU; will block on I/O until time 6811ms [Q A P K L D E O M G F J B N I]
time 6756ms: Process A (tau 64ms) started using the CPU for 122ms burst [Q P K L D E O M G F J B N I]
time 6811ms: Process H (tau 79ms) completed I/O; added to ready queue [Q H P K L D E O M G F J B N I]
time 6878ms: Process A (tau 64ms) completed a CPU burst; 4 bursts to go [Q H P K L D E O M G F J B N I]
time 6878ms: Recalculated tau = 108ms for process A [Q H P K L D E O M G F J B N I]
time 6878ms: Process A switching out of CPU; will block on I/O until time 6913ms [Q H P K L D E O M G F J B N I]
time 6882ms: Process H (tau 79ms) started using the CPU for 156ms burst [Q P K L D E O M G F J B N I]
time 6913ms: Process A (tau 108ms) completed I/O; added to ready queue [Q P K A L D E O M G F J B N I]
time 7038ms: Process H (tau 79ms) completed a CPU burst; 73 bursts to go [Q P K A L D E O M G F J B N I]
time 7038ms: Recalculated tau = 137ms for process H [Q P K A L D E O M G F J B N I]
time 7038ms: Process H switching out of CPU; will block on I/O until time 7096ms [Q P K A L D E O M G F J B N I]
time 7042ms: Process P (tau 88ms) started using the CPU for 16ms burst [Q K A L D E O M G F J B N I]
time 7058ms: Process P (tau 88ms) completed a CPU burst; 9 bursts to go [Q K A L D E O M G F J B N I]
time 7058ms: Recalculated tau = 34ms for process P [Q K A L D E O M G F J B N I]
time 7058ms: Process P switching out of CPU; will block on I/O until time 7125ms [Q K A L D E O M G F J B N I]
time 7062ms: Process K (tau 96ms) started using the CPU for 199ms burst [Q A L D E O M G F J B N I]
time 7096ms: Process H (tau 137ms) completed I/O; added to ready queue [Q A L D H E O M G F J B N I]
time 7125ms: Process P (tau 34ms) completed I/O; added to ready queue [Q P A L D H E O M G F J B N I]
time 7261ms: Process K (tau 96ms) completed a CPU burst; 1 burst to go [Q P A L D H E O M G F J B N I]
time 7261ms: Recalculated tau = 174ms for process K [Q P A L D H E O M G F J B N I]
time 7261ms: Process K switching out of CPU; will block on I/O until time 7328ms [Q P A L D H E O M G F J B N I]
time 7265ms: Process P (tau 34ms) started using the CPU for 219ms burst [Q A L D H E O M G F J B N I]
time 7328ms: Process K (tau 174ms) completed I/O; added to ready queue [Q A L D H E O M G F J K B N I]
time 7484ms: Process P (tau 34ms) completed a CPU burst; 8 bursts to go [Q A L D H E O M G F J K B N I]
time 7484ms: Recalculated tau = 173ms for process P [Q A L D H E O M G F J K B N I]
time 7484ms: Process P switching out of CPU; will block on I/O until time 7691ms [Q A L D H E O M G F J K B N I]
time 7488ms: Process A (tau 108ms) started using the CPU for 9ms burst [Q L D H E O M G F J K B N I]
time 7497ms: Process A (tau 108ms) completed a CPU burst; 3 bursts to go [Q L D H E O M G F J K B N I]
time 7497ms: Recalculated tau = 34ms for process A [Q L D H E O M G F J K B N I]
time 7497ms: Process A switching out of CPU; will block on I/O until time 7567ms [Q L D H E O M G F J K B N I]
time 7501ms: Process L (tau 126ms) started using the CPU for 111ms burst [Q D H E O M G F J K B N I]
time 7567ms: Process A (tau 34ms) completed I/O; added to ready queue [Q A D H E O M G F J K B N I]
time 7612ms: Process L terminated [Q A D H E O M G F J K B N I]
time 7616ms: Process A (tau 34ms) started using the CPU for 62ms burst [Q D H E O M G F J K B N I]
time 7678ms: Process A (tau 34ms) completed a CPU burst; 2 bursts to go [Q D H E O M G F J K B N I]
time 7678ms: Recalculated tau = 55ms for process A [Q D H E O M G F J K B N I]
time 7678ms: Process A switching out of CPU; will block on I/O until time 7757ms [Q D H E O M G F J K B N I]
time 7682ms: Process D (tau 136ms) started using the CPU for 211ms burst [Q H E O M G F J K B N I]
time 7691ms: Process P (tau 173ms) completed I/O; added to ready queue [Q H E O M G F J P K B N I]
time 7757ms: Process A (tau 55ms) completed I/O; added to ready queue [Q A H E O M G F J P K B N I]
time 7893ms: Process D (tau 136ms) completed a CPU burst; 9 bursts to go [Q A H E O M G F J P K B N I]
time 7893ms: Recalculated tau = 193ms for process D [Q A H E O M G F J P K B N I]
time 7893ms: Process D switching out of CPU; will block on I/O until time 8109ms [Q A H E O M G F J P K B N I]
time 7897ms: Process A (tau 55ms) started using the CPU for 200ms burst [Q H E O M G F J P K B N I]
time 8097ms: Process A (tau 55ms) completed a CPU burst; 1 burst to go [Q H E O M G F J P K B N I]
time 8097ms: Recalculated tau = 164ms for process A [Q H E O M G F J P K B N I]
time 8097ms: Process A switching out of CPU; will block on I/O until time 8110ms [Q H E O M G F J P K B N I]
time 8101ms: Process H (tau 137ms) started using the CPU for 184ms burst [Q E O M G F J P K B N I]
time 8109ms: Process D (tau 193ms) completed I/O; added to ready queue [Q E O M G F J P K B N I D]
time 8110ms: Process A (tau 164ms) completed I/O; added to ready queue [Q E O M G F A J P K B N I D]
time 8285ms: Process H (tau 137ms) completed a CPU burst; 72 bursts to go [Q E O M G F A J P K B N I D]
time 8285ms: Recalculated tau = 173ms for process H [Q E O M G F A J P K B N I D]
time 8285ms: Process H switching out of CPU; will block on I/O until time 8313ms [Q E O M G F A J P K B N I D]
time 8289ms: Process E (tau 139ms) started using the CPU for 44ms burst [Q O M G F A J P K B N I D]
time 8313ms: Process H (tau 173ms) completed I/O; added to ready queue [Q O M G F A J H P K B N I D]
time 8333ms: Process E (tau 139ms) completed a CPU burst; 53 bursts to go [Q O M G F A J H P K B N I D]
time 8333ms: Recalculated tau = 68ms for process E [Q O M G F A J H P K B N I D]
time 8333ms: Process E switching out of CPU; will block on I/O until time 8391ms [Q O M G F A J H P K B N I D]
time 8337ms: Process O (tau 142ms) started using the CPU for 106ms burst [Q M G F A J H P K B N I D]
time 8391ms: Process E (tau 68ms) completed I/O; added to ready queue [Q E M G F A J H P K B N I D]
time 8443ms: Process O (tau 142ms) completed a CPU burst; 29 bursts to go [Q E M G F A J H P K B N I D]
time 8443ms: Recalculated tau = 115ms for process O [Q E M G F A J H P K B N I D]
time 8443ms: Process O switching out of CPU; will block on I/O until time 8694ms [Q E M G F A J H P K B N I D]
time 8447ms: Process E (tau 68ms) started using the CPU for 2ms burst [Q M G F A J H P K B N I D]
time 8449ms: Process E (tau 68ms) completed a CPU burst; 52 bursts to go [Q M G F A J H P K B N I D]
time 8449ms: Recalculated tau = 19ms for process E [Q M G F A J H P K B N I D]
time 8449ms: Process E switching out of CPU; will block on I/O until time 8476ms [Q M G F A J H P K B N I D]
time 8453ms: Process M (tau 152ms) started using the CPU for 200ms burst [Q G F A J H P K B N I D]
time 8476ms: Process E (tau 19ms) completed I/O; added to ready queue [Q E G F A J H P K B N I D]
time 8653ms: Process M (tau 152ms) completed a CPU burst; 40 bursts to go [Q E G F A J H P K B N I D]
time 8653ms: Recalculated tau = 188ms for process M [Q E G F A J H P K B N I D]
time 8653ms: Process M switching out of CPU; will block on I/O until time 8786ms [Q E G F A J H P K B N I D]
time 8657ms: Process E (tau 19ms) started using the CPU for 42ms burst [Q G F A J H P K B N I D]
time 8694ms: Process O (tau 115ms) completed I/O; added to ready queue [Q O G F A J H P K B N I D]
time 8699ms: Process E (tau 19ms) completed a CPU burst; 51 bursts to go [Q O G F A J H P K B N I D]
time 8699ms: Recalculated tau = 37ms for process E [Q O G F A J H P K B N I D]
time 8699ms: Process E switching out of CPU; will block on I/O until time 8706ms [Q O G F A J H P K B N I D]
time 8703ms: Process O (tau 115ms) started using the CPU for 57ms burst [Q G F A J H P K B N I D]
time 8706ms: Process E (tau 37ms) completed I/O; added to ready queue [Q E G F A J H P K B N I D]
time 8760ms: Process O (tau 115ms) completed a CPU burst; 28 bursts to go [Q E G F A J H P K B N I D]
time 8760ms: Recalculated tau = 72ms for process O [Q E G F A J H P K B N I D]
time 8760ms: Process O switching out of CPU; will block on I/O until time 8799ms [Q E G F A J H P K B N I D]
time 8764ms: Process E (tau 37ms) started using the CPU for 108ms burst [Q G F A J H P K B N I D]
time 8786ms: Process M (tau 188ms) completed I/O; added to ready queue [Q G F A J H P K B N M I D]
time 8799ms: Process O (tau 72ms) completed I/O; added to ready queue [Q O G F A J H P K B N M I D]
time 8872ms: Process E (tau 37ms) completed a CPU burst; 50 bursts to go [Q O G F A J H P K B N M I D]
time 8872ms: Recalculated tau = 91ms for process E [Q O G F A J H P K B N M I D]
time 8872ms: Process E switching out of CPU; will block on I/O until time 8883ms [Q O G F A J H P K B N M I D]
time 8876ms: Process O (tau 72ms) started using the CPU for 13ms burst [Q G F A J H P K B N M I D]
time 8883ms: Process E (tau 91ms) completed I/O; added to ready queue [Q E G F A J H P K B N M I D]
time 8889ms: Process O (tau 72ms) completed a CPU burst; 27 bursts to go [Q E G F A J H P K B N M I D]
time 8889ms: Recalculated tau = 28ms for process O [Q E G F A J H P K B N M I D]
time 8889ms: Process O switching out of CPU; will block on I/O until time 9024ms [Q E G F A J H P K B N M I D]
time 8893ms: Process E (tau 91ms) started using the CPU for 6ms burst [Q G F A J H P K B N M I D]
time 8899ms: Process E (tau 91ms) completed a CPU burst; 49 bursts to go [Q G F A J H P K B N M I D]
time 8899ms: Recalculated tau = 28ms for process E [Q G F A J H P K B N M I D]
time 8899ms: Process E switching out of CPU; will block on I/O until time 8933ms [Q G F A J H P K B N M I D]
time 8903ms: Process G (tau 159ms) started using the CPU for 6ms burst [Q F A J H P K B N M I D]
time 8909ms: Process G (tau 159ms) completed a CPU burst; 63 bursts to go [Q F A J H P K B N M I D]
time 8909ms: Recalculated tau = 45ms for process G [Q F A J H P K B N M I D]
time 8909ms: Process G switching out of CPU; will block on I/O until time 9059ms [Q F A J H P K B N M I D]
time 8913ms: Process F (tau 162ms) started using the CPU for 72ms burst [Q A J H P K B N M I D]
time 8933ms: Process E (tau 28ms) completed I/O; added to ready queue [Q E A J H P K B N M I D]
time 8985ms: Process F (tau 162ms) completed a CPU burst; 30 bursts to go [Q E A J H P K B N M I D]
time 8985ms: Recalculated tau = 95ms for process F [Q E A J H P K B N M I D]
time 8985ms: Process F switching out of CPU; will block on I/O until time 9013ms [Q E A J H P K B N M I D]
time 8989ms: Process E (tau 28ms) started using the CPU for 112ms burst [Q A J H P K B N M I D]
time 9013ms: Process F (tau 95ms) completed I/O; added to ready queue [Q F A J H P K B N M I D]
time 9024ms: Process O (tau 28ms) completed I/O; added to ready queue [Q O F A J H P K B N M I D]
time 9059ms: Process G (tau 45ms) completed I/O; added to ready queue [Q O G F A J H P K B N M I D]
time 9101ms: Process E (tau 28ms) completed a CPU burst; 48 bursts to go [Q O G F A J H P K B N M I D]
time 9101ms: Recalculated tau = 91ms for process E [Q O G F A J H P K B N M I D]
time 9101ms: Process E switching out of CPU; will block on I/O until time 9214ms [Q O G F A J H P K B N M I D]
time 9105ms: Process O (tau 28ms) started using the CPU for 130ms burst [Q G F A J H P K B N M I D]
time 9214ms: Process E (tau 91ms) completed I/O; added to ready queue [Q G E F A J H P K B N M I D]
time 9235ms: Process O (tau 28ms) completed a CPU burst; 26 bursts to go [Q G E F A J H P K B N M I D]
time 9235ms: Recalculated tau = 105ms for process O [Q G E F A J H P K B N M I D]
time 9235ms: Process O switching out of CPU; will block on I/O until time 9308ms [Q G E F A J H P K B N M I D]
time 9239ms: Process G (tau 45ms) started using the CPU for 37ms burst [Q E F A J H P K B N M I D]
time 9276ms: Process G (tau 45ms) completed a CPU burst; 62 bursts to go [Q E F A J H P K B N M I D]
time 9276ms: Recalculated tau = 39ms for process G [Q E F A J H P K B N M I D]
time 9276ms: Process G switching out of CPU; will block on I/O until time 9409ms [Q E F A J H P K B N M I D]
time 9280ms: Process E (tau 91ms) started using the CPU for 12ms burst [Q F A J H P K B N M I D]
time 9292ms: Process E (tau 91ms) completed a CPU burst; 47 bursts to go [Q F A J H P K B N M I D]
time 9292ms: Recalculated tau = 32ms for process E [Q F A J H P K B N M I D]
time 9292ms: Process E switching out of CPU; will block on I/O until time 9339ms [Q F A J H P K B N M I D]
time 9296ms: Process F (tau 95ms) started using the CPU for 8ms burst [Q A J H P K B N M I D]
time 9304ms: Process F (tau 95ms) completed a CPU burst; 29 bursts to go [Q A J H P K B N M I D]
time 9304ms: Recalculated tau = 30ms for process F [Q A J H P K B N M I D]
time 9304ms: Process F switching out of CPU; will block on I/O until time 9339ms [Q A J H P K B N M I D]
time 9308ms: Process A (tau 164ms) started using the CPU for 197ms burst [Q J H P K B N M I D]
time 9308ms: Process O (tau 105ms) completed I/O; added to ready queue [Q O J H P K B N M I D]
time 9339ms: Process E (tau 32ms) completed I/O; added to ready queue [Q E O J H P K B N M I D]
time 9339ms: Process F (tau 30ms) completed I/O; added to ready queue [Q F E O J H P K B N M I D]
time 9409ms: Process G (tau 39ms) completed I/O; added to ready queue [Q F E G O J H P K B N M I D]
time 9505ms: Process A terminated [Q F E G O J H P K B N M I D]
time 9509ms: Process F (tau 30ms) started using the CPU for 230ms burst [Q E G O J H P K B N M I D]
time 9739ms: Process F (tau 30ms) completed a CPU burst; 28 bursts to go [Q E G O J H P K B N M I D]
time 9739ms: Recalculated tau = 180ms for process F [Q E G O J H P K B N M I D]
time 9739ms: Process F switching out of CPU; will block on I/O until time 9744ms [Q E G O J H P K B N M I D]
time 9743ms: Process E (tau 32ms) started using the CPU for 9ms burst [Q G O J H P K B N M I D]
time 9744ms: Process F (tau 180ms) completed I/O; added to ready queue [Q G O J H P K B F N M I D]
time 9752ms: Process E (tau 32ms) completed a CPU burst; 46 bursts to go [Q G O J H P K B F N M I D]
time 9752ms: Recalculated tau = 15ms for process E [Q G O J H P K B F N M I D]
time 9752ms: Process E switching out of CPU; will block on I/O until time 9821ms [Q G O J H P K B F N M I D]
time 9756ms: Process G (tau 39ms) started using the CPU for 15ms burst [Q O J H P K B F N M I D]
time 9771ms: Process G (tau 39ms) completed a CPU burst; 61 bursts to go [Q O J H P K B F N M I D]
time 9771ms: Recalculated tau = 21ms for process G [Q O J H P K B F N M I D]
time 9771ms: Process G switching out of CPU; will block on I/O until time 9795ms [Q O J H P K B F N M I D]
time 9775ms: Process O (tau 105ms) started using the CPU for 68ms burst [Q J H P K B F N M I D]
time 9795ms: Process G (tau 21ms) completed I/O; added to ready queue [Q G J H P K B F N M I D]
time 9821ms: Process E (tau 15ms) completed I/O; added to ready queue [Q E G J H P K B F N M I D]
time 9843ms: Process O (tau 105ms) completed a CPU burst; 25 bursts to go [Q E G J H P K B F N M I D]
time 9843ms: Recalculated tau = 78ms for process O [Q E G J H P K B F N M I D]
time 9843ms: Process O switching out of CPU; will block on I/O until time 9962ms [Q E G J H P K B F N M I D]
time 9847ms: Process E (tau 15ms) started using the CPU for 62ms burst [Q G J H P K B F N M I D]
time 9909ms: Process E (tau 15ms) completed a CPU burst; 45 bursts to go [Q G J H P K B F N M I D]
time 9909ms: Recalculated tau = 51ms for process E [Q G J H P K B F N M I D]
time 9909ms: Process E switching out of CPU; will block on I/O until time 9971ms [Q G J H P K B F N M I D]
time 9913ms: Process G (tau 21ms) started using the CPU for 47ms burst [Q J H P K B F N M I D]
time 9960ms: Process G (tau 21ms) completed a CPU burst; 60 bursts to go [Q J H P K B F N M I D]
time 9960ms: Recalculated tau = 41ms for process G [Q J H P K B F N M I D]
time 9960ms: Process G switching out of CPU; will block on I/O until time 10038ms [Q J H P K B F N M I D]
time 9962ms: Process O (tau 78ms) completed I/O; added to ready queue [Q O J H P K B F N M I D]
time 9964ms: Process O (tau 78ms) started using the CPU for 136ms burst [Q J H P K B F N M I D]
time 9971ms: Process E (tau 51ms) completed I/O; added to ready queue [Q E J H P K B F N M I D]
time 10038ms: Process G (tau 41ms) completed I/O; added to ready queue [Q G E J H P K B F N M I D]
time 10100ms: Process O (tau 78ms) completed a CPU burst; 24 bursts to go [Q G E J H P K B F N M I D]
time 10100ms: Recalculated tau = 122ms for process O [Q G E J H P K B F N M I D]
time 10100ms: Process O switching out of CPU; will block on I/O until time 10207ms [Q G E J H P K B F N M I D]
time 10104ms: Process G (tau 41ms) started using the CPU for 82ms burst [Q E J H P K B F N M I D]
time 10186ms: Process G (tau 41ms) completed a CPU burst; 59 bursts to go [Q E J H P K B F N M I D]
time 10186ms: Recalculated tau = 72ms for process G [Q E J H P K B F N M I D]
time 10186ms: Process G switching out of CPU; will block on I/O until time 10191ms [Q E J H P K B F N M I D]
time 10190ms: Process E (tau 51ms) started using the CPU for 213ms burst [Q J H P K B F N M I D]
time 10191ms: Process G (tau 72ms) completed I/O; added to ready queue [Q G J H P K B F N M I D]
time 10207ms: Process O (tau 122ms) completed I/O; added to ready queue [Q G O J H P K B F N M I D]
time 10403ms: Process E (tau 51ms) completed a CPU burst; 44 bursts to go [Q G O J H P K B F N M I D]
time 10403ms: Recalculated tau = 173ms for process E [Q G O J H P K B F N M I D]
time 10403ms: Process E switching out of CPU; will block on I/O until time 10598ms [Q G O J H P K B F N M I D]
time 10407ms: Process G (tau 72ms) started using the CPU for 57ms burst [Q O J H P K B F N M I D]
time 10464ms: Process G (tau 72ms) completed a CPU burst; 58 bursts to go [Q O J H P K B F N M I D]
time 10464ms: Recalculated tau = 61ms for process G [Q O J H P K B F N M I D]
time 10464ms: Process G switching out of CPU; will block on I/O until time 10487ms [Q O J H P K B F N M I D]
time 10468ms: Process O (tau 122ms) started using the CPU for 69ms burst [Q J H P K B F N M I D]
time 10487ms: Process G (tau 61ms) completed I/O; added to ready queue [Q G J H P K B F N M I D]
time 10537ms: Process O (tau 122ms) completed a CPU burst; 23 bursts to go [Q G J H P K B F N M I D]
time 10537ms: Recalculated tau = 83ms for process O [Q G J H P K B F N M I D]
time 10537ms: Process O switching out of CPU; will block on I/O until time 10614ms [Q G J H P K B F N M I D]
time 10541ms: Process G (tau 61ms) started using the CPU for 89ms burst [Q J H P K B F N M I D]
time 10598ms: Process E (tau 173ms) completed I/O; added to ready queue [Q J E H P K B F N M I D]
time 10614ms: Process O (tau 83ms) completed I/O; added to ready queue [Q O J E H P K B F N M I D]
time 10630ms: Process G (tau 61ms) completed a CPU burst; 57 bursts to go [Q O J E H P K B F N M I D]
time 10630ms: Recalculated tau = 82ms for process G [Q O J E H P K B F N M I D]
time 10630ms: Process G switching out of CPU; will block on I/O until time 10724ms [Q O J E H P K B F N M I D]
time 10634ms: Process O (tau 83ms) started using the CPU for 6ms burst [Q J E H P K B F N M I D]
time 10640ms: Process O (tau 83ms) completed a CPU burst; 22 bursts to go [Q J E H P K B F N M I D]
time 10640ms: Recalculated tau = 26ms for process O [Q J E H P K B F N M I D]
time 10640ms: Process O switching out of CPU; will block on I/O until time 10806ms [Q J E H P K B F N M I D]
time 10644ms: Process J (tau 167ms) started using the CPU for 28ms burst [Q E H P K B F N M I D]
time 10672ms: Process J (tau 167ms) completed a CPU burst; 7 bursts to go [Q E H P K B F N M I D]
time 10672ms: Recalculated tau = 63ms for process J [Q E H P K B F N M I D]
time 10672ms: Process J switching out of CPU; will block on I/O until time 10696ms [Q E H P K B F N M I D]
time 10676ms: Process E (tau 173ms) started using the CPU for 54ms burst [Q H P K B F N M I D]
time 10696ms: Process J (tau 63ms) completed I/O; added to ready queue [Q J H P K B F N M I D]
time 10724ms: Process G (tau 82ms) completed I/O; added to ready queue [Q J G H P K B F N M I D]
time 10730ms: Process E (tau 173ms) completed a CPU burst; 43 bursts to go [Q J G H P K B F N M I D]
time 10730ms: Recalculated tau = 84ms for process E [Q J G H P K B F N M I D]
time 10730ms: Process E switching out of CPU; will block on I/O until time 10827ms [Q J G H P K B F N M I D]
time 10734ms: Process J (tau 63ms) started using the CPU for 120ms burst [Q G H P K B F N M I D]
time 10806ms: Process O (tau 26ms) completed I/O; added to ready queue [Q O G H P K B F N M I D]
time 10827ms: Process E (tau 84ms) completed I/O; added to ready queue [Q O G E H P K B F N M I D]
time 10854ms: Process J (tau 63ms) completed a CPU burst; 6 bursts to go [Q O G E H P K B F N M I D]
time 10854ms: Recalculated tau = 106ms for process J [Q O G E H P K B F N M I D]
time 10854ms: Process J switching out of CPU; will block on I/O until time 10912ms [Q O G E H P K B F N M I D]
time 10858ms: Process O (tau 26ms) started using the CPU for 187ms burst [Q G E H P K B F N M I D]
time 10912ms: Process J (tau 106ms) completed I/O; added to ready queue [Q G E J H P K B F N M I D]
time 11045ms: Process O (tau 26ms) completed a CPU burst; 21 bursts to go [Q G E J H P K B F N M I D]
time 11045ms: Recalculated tau = 147ms for process O [Q G E J H P K B F N M I D]
time 11045ms: Process O switching out of CPU; will block on I/O until time 11214ms [Q G E J H P K B F N M I D]
time 11049ms: Process G (tau 82ms) started using the CPU for 3ms burst [Q E J H P K B F N M I D]
time 11052ms: Process G (tau 82ms) completed a CPU burst; 56 bursts to go [Q E J H P K B F N M I D]
time 11052ms: Recalculated tau = 23ms for process G [Q E J H P K B F N M I D]
time 11052ms: Process G switching out of CPU; will block on I/O until time 11190ms [Q E J H P K B F N M I D]
time 11056ms: Process E (tau 84ms) started using the CPU for 126ms burst [Q J H P K B F N M I D]
time 11182ms: Process E (tau 84ms) completed a CPU burst; 42 bursts to go [Q J H P K B F N M I D]
time 11182ms: Recalculated tau = 116ms for process E [Q J H P K B F N M I D]
time 11182ms: Process E switching out of CPU; will block on I/O until time 11382ms [Q J H P K B F N M I D]
time 11186ms: Process J (tau 106ms) started using the CPU for 31ms burst [Q H P K B F N M I D]
time 11190ms: Process G (tau 23ms) completed I/O; added to ready queue [Q G H P K B F N M I D]
time 11214ms: Process O (tau 147ms) completed I/O; added to ready queue [Q G O H P K B F N M I D]
time 11217ms: Process J (tau 106ms) completed a CPU burst; 5 bursts to go [Q G O H P K B F N M I D]
time 11217ms: Recalculated tau = 50ms for process J [Q G O H P K B F N M I D]
time 11217ms: Process J switching out of CPU; will block on I/O until time 11305ms [Q G O H P K B F N M I D]
time 11221ms: Process G (tau 23ms) started using the CPU for 11ms burst [Q O H P K B F N M I D]
time 11232ms: Process G (tau 23ms) completed a CPU burst; 55 bursts to go [Q O H P K B F N M I D]
time 11232ms: Recalculated tau = 14ms for process G [Q O H P K B F N M I D]
time 11232ms: Process G switching out of CPU; will block on I/O until time 11479ms [Q O H P K B F N M I D]
time 11236ms: Process O (tau 147ms) started using the CPU for 89ms burst [Q H P K B F N M I D]
time 11305ms: Process J (tau 50ms) completed I/O; added to ready queue [Q J H P K B F N M I D]
time 11325ms: Process O (tau 147ms) completed a CPU burst; 20 bursts to go [Q J H P K B F N M I D]
time 11325ms: Recalculated tau = 104ms for process O [Q J H P K B F N M I D]
time 11325ms: Process O switching out of CPU; will block on I/O until time 11467ms [Q J H P K B F N M I D]
time 11329ms: Process J (tau 50ms) started using the CPU for 32ms burst [Q H P K B F N M I D]
time 11361ms: Process J (tau 50ms) completed a CPU burst; 4 bursts to go [Q H P K B F N M I D]
time 11361ms: Recalculated tau = 37ms for process J [Q H P K B F N M I D]
time 11361ms: Process J switching out of CPU; will block on I/O until time 11376ms [Q H P K B F N M I D]
time 11365ms: Process H (tau 173ms) started using the CPU for 2ms burst [Q P K B F N M I D]
time 11367ms: Process H (tau 173ms) completed a CPU burst; 71 bursts to go [Q P K B F N M I D]
time 11367ms: Recalculated tau = 45ms for process H [Q P K B F N M I D]
time 11367ms: Process H switching out of CPU; will block on I/O until time 11383ms [Q P K B F N M I D]
time 11371ms: Process P (tau 173ms) started using the CPU for 70ms burst [Q K B F N M I D]
time 11376ms: Process J (tau 37ms) completed I/O; added to ready queue [Q J K B F N M I D]
time 11382ms: Process E (tau 116ms) completed I/O; added to ready queue [Q J E K B F N M I D]
time 11383ms: Process H (tau 45ms) completed I/O; added to ready queue [Q J H E K B F N M I D]
time 11441ms: Process P (tau 173ms) completed a CPU burst; 7 bursts to go [Q J H E K B F N M I D]
time 11441ms: Recalculated tau = 96ms for process P [Q J H E K B F N M I D]
time 11441ms: Process P switching out of CPU; will block on I/O until time 11570ms [Q J H E K B F N M I D]
time 11445ms: Process J (tau 37ms) started using the CPU for 23ms burst [Q H E K B F N M I D]
time 11467ms: Process O (tau 104ms) completed I/O; added to ready queue [Q H O E K B F N M I D]
time 11468ms: Process J (tau 37ms) completed a CPU burst; 3 bursts to go [Q H O E K B F N M I D]
time 11468ms: Recalculated tau = 27ms for process J [Q H O E K B F N M I D]
time 11468ms: Process J switching out of CPU; will block on I/O until time 11486ms [Q H O E K B F N M I D]
time 11472ms: Process H (tau 45ms) started using the CPU for 29ms burst [Q O E K B F N M I D]
time 11479ms: Process G (tau 14ms) completed I/O; added to ready queue [Q G O E K B F N M I D]
time 11486ms: Process J (tau 27ms) completed I/O; added to ready queue [Q G J O E K B F N M I D]
time 11501ms: Process H (tau 45ms) completed a CPU burst; 70 bursts to go [Q G J O E K B F N M I D]
time 11501ms: Recalculated tau = 33ms for process H [Q G J O E K B F N M I D]
time 11501ms: Process H switching out of CPU; will block on I/O until time 11725ms [Q G J O E K B F N M I D]
time 11505ms: Process G (tau 14ms) started using the CPU for 17ms burst [Q J O E K B F N M I D]
time 11522ms: Process G (tau 14ms) completed a CPU burst; 54 bursts to go [Q J O E K B F N M I D]
time 11522ms: Recalculated tau = 17ms for process G [Q J O E K B F N M I D]
time 11522ms: Process G switching out of CPU; will block on I/O until time 11589ms [Q J O E K B F N M I D]
time 11526ms: Process J (tau 27ms) started using the CPU for 51ms burst [Q O E K B F N M I D]
time 11570ms: Process P (tau 96ms) completed I/O; added to ready queue [Q P O E K B F N M I D]
time 11577ms: Process J (tau 27ms) completed a CPU burst; 2 bursts to go [Q P O E K B F N M I D]
time 11577ms: Recalculated tau = 45ms for process J [Q P O E K B F N M I D]
time 11577ms: Process J switching out of CPU; will block on I/O until time 11676ms [Q P O E K B F N M I D]
time 11581ms: Process P (tau 96ms) started using the CPU for 55ms burst [Q O E K B F N M I D]
time 11589ms: Process G (tau 17ms) completed I/O; added to ready queue [Q G O E K B F N M I D]
time 11636ms: Process P (tau 96ms) completed a CPU burst; 6 bursts to go [Q G O E K B F N M I D]
time 11636ms: Recalculated tau = 66ms for process P [Q G O E K B F N M I D]
time 11636ms: Process P switching out of CPU; will block on I/O until time 11883ms [Q G O E K B F N M I D]
time 11640ms: Process G (tau 17ms) started using the CPU for 55ms burst [Q O E K B F N M I D]
time 11676ms: Process J (tau 45ms) completed I/O; added to ready queue [Q J O E K B F N M I D]
time 11695ms: Process G (tau 17ms) completed a CPU burst; 53 bursts to go [Q J O E K B F N M I D]
time 11695ms: Recalculated tau = 46ms for process G [Q J O E K B F N M I D]
time 11695ms: Process G switching out of CPU; will block on I/O until time 11901ms [Q J O E K B F N M I D]
time 11699ms: Process J (tau 45ms) started using the CPU for 216ms burst [Q O E K B F N M I D]
time 11725ms: Process H (tau 33ms) completed I/O; added to ready queue [Q H O E K B F N M I D]
time 11883ms: Process P (tau 66ms) completed I/O; added to ready queue [Q H P O E K B F N M I D]
time 11901ms: Process G (tau 46ms) completed I/O; added to ready queue [Q H G P O E K B F N M I D]
time 11915ms: Process J (tau 45ms) completed a CPU burst; 1 burst to go [Q H G P O E K B F N M I D]
time 11915ms: Recalculated tau = 174ms for process J [Q H G P O E K B F N M I D]
time 11915ms: Process J switching out of CPU; will block on I/O until time 11925ms [Q H G P O E K B F N M I D]
time 11919ms: Process H (tau 33ms) started using the CPU for 76ms burst [Q G P O E K B F N M I D]
time 11925ms: Process J (tau 174ms) completed I/O; added to ready queue [Q G P O E J K B F N M I D]
time 11995ms: Process H (tau 33ms) completed a CPU burst; 69 bursts to go [Q G P O E J K B F N M I D]
time 11995ms: Recalculated tau = 66ms for process H [Q G P O E J K B F N M I D]
time 11995ms: Process H switching out of CPU; will block on I/O until time 12209ms [Q G P O E J K B F N M I D]
time 11999ms: Process G (tau 46ms) started using the CPU for 52ms burst [Q P O E J K B F N M I D]
time 12051ms: Process G (tau 46ms) completed a CPU burst; 52 bursts to go [Q P O E J K B F N M I D]
time 12051ms: Recalculated tau = 51ms for process G [Q P O E J K B F N M I D]
time 12051ms: Process G switching out of CPU; will block on I/O until time 12149ms [Q P O E J K B F N M I D]
time 12055ms: Process P (tau 66ms) started using the CPU for 212ms burst [Q O E J K B F N M I D]
time 12149ms: Process G (tau 51ms) completed I/O; added to ready queue [Q G O E J K B F N M I D]
time 12209ms: Process H (tau 66ms) completed I/O; added to ready queue [Q G H O E J K B F N M I D]
time 12267ms: Process P (tau 66ms) completed a CPU burst; 5 bursts to go [Q G H O E J K B F N M I D]
time 12267ms: Recalculated tau = 176ms for process P [Q G H O E J K B F N M I D]
time 12267ms: Process P switching out of CPU; will block on I/O until time 12486ms [Q G H O E J K B F N M I D]
time 12271ms: Process G (tau 51ms) started using the CPU for 199ms burst [Q H O E J K B F N M I D]
time 12470ms: Process G (tau 51ms) completed a CPU burst; 51 bursts to go [Q H O E J K B F N M I D]
time 12470ms: Recalculated tau = 162ms for process G [Q H O E J K B F N M I D]
time 12470ms: Process G switching out of CPU; will block on I/O until time 12482ms [Q H O E J K B F N M I D]
time 12474ms: Process H (tau 66ms) started using the CPU for 143ms burst [Q O E J K B F N M I D]
time 12482ms: Process G (tau 162ms) completed I/O; added to ready queue [Q O E G J K B F N M I D]
time 12486ms: Process P (tau 176ms) completed I/O; added to ready queue [Q O E G J K B P F N M I D]
time 12617ms: Process H (tau 66ms) completed a CPU burst; 68 bursts to go [Q O E G J K B P F N M I D]
time 12617ms: Recalculated tau = 124ms for process H [Q O E G J K B P F N M I D]
time 12617ms: Process H switching out of CPU; will block on I/O until time 12803ms [Q O E G J K B P F N M I D]
time 12621ms: Process O (tau 104ms) started using the CPU for 45ms burst [Q E G J K B P F N M I D]
time 12666ms: Process O (tau 104ms) completed a CPU burst; 19 bursts to go [Q E G J K B P F N M I D]
time 12666ms: Recalculated tau = 60ms for process O [Q E G J K B P F N M I D]
time 12666ms: Process O switching out of CPU; will block on I/O until time 12714ms [Q E G J K B P F N M I D]
time 12670ms: Process E (tau 116ms) started using the CPU for 168ms burst [Q G J K B P F N M I D]
time 12714ms: Process O (tau 60ms) completed I/O; added to ready queue [Q O G J K B P F N M I D]
time 12803ms: Process H (tau 124ms) completed I/O; added to ready queue [Q O H G J K B P F N M I D]
time 12838ms: Process E (tau 116ms) completed a CPU burst; 41 bursts to go [Q O H G J K B P F N M I D]
time 12838ms: Recalculated tau = 155ms for process E [Q O H G J K B P F N M I D]
time 12838ms: Process E switching out of CPU; will block on I/O until time 12890ms [Q O H G J K B P F N M I D]
time 12842ms: Process O (tau 60ms) started using the CPU for 50ms burst [Q H G J K B P F N M I D]
time 12890ms: Process E (tau 155ms) completed I/O; added to ready queue [Q H E G J K B P F N M I D]
time 12892ms: Process O (tau 60ms) completed a CPU burst; 18 bursts to go [Q H E G J K B P F N M I D]
time 12892ms: Recalculated tau = 53ms for process O [Q H E G J K B P F N M I D]
time 12892ms: Process O switching out of CPU; will block on I/O until time 13005ms [Q H E G J K B P F N M I D]
time 12896ms: Process H (tau 124ms) started using the CPU for 32ms burst [Q E G J K B P F N M I D]
time 12928ms: Process H (tau 124ms) completed a CPU burst; 67 bursts to go [Q E G J K B P F N M I D]
time 12928ms: Recalculated tau = 55ms for process H [Q E G J K B P F N M I D]
time 12928ms: Process H switching out of CPU; will block on I/O until time 13012ms [Q E G J K B P F N M I D]
time 12932ms: Process E (tau 155ms) started using the CPU for 23ms burst [Q G J K B P F N M I D]
time 12955ms: Process E (tau 155ms) completed a CPU burst; 40 bursts to go [Q G J K B P F N M I D]
time 12955ms: Recalculated tau = 56ms for process E [Q G J K B P F N M I D]
time 12955ms: Process E switching out of CPU; will block on I/O until time 12966ms [Q G J K B P F N M I D]
time 12959ms: Process G (tau 162ms) started using the CPU for 35ms burst [Q J K B P F N M I D]
time 12966ms: Process E (tau 56ms) completed I/O; added to ready queue [Q E J K B P F N M I D]
time 12994ms: Process G (tau 162ms) completed a CPU burst; 50 bursts to go [Q E J K B P F N M I D]
time 12994ms: Recalculated tau = 67ms for process G [Q E J K B P F N M I D]
time 12994ms: Process G switching out of CPU; will block on I/O until time 13067ms [Q E J K B P F N M I D]
time 12998ms: Process E (tau 56ms) started using the CPU for 68ms burst [Q J K B P F N M I D]
time 13005ms: Process O (tau 53ms) completed I/O; added to ready queue [Q O J K B P F N M I D]
time 13012ms: Process H (tau 55ms) completed I/O; added to ready queue [Q O H J K B P F N M I D]
time 13066ms: Process E (tau 56ms) completed a CPU burst; 39 bursts to go [Q O H J K B P F N M I D]
time 13066ms: Recalculated tau = 65ms for process E [Q O H J K B P F N M I D]
time 13066ms: Process E switching out of CPU; will block on I/O until time 13126ms [Q O H J K B P F N M I D]
time 13067ms: Process G (tau 67ms) completed I/O; added to ready queue [Q O H G J K B P F N M I D]
time 13070ms: Process O (tau 53ms) started using the CPU for 133ms burst [Q H G J K B P F N M I D]
time 13126ms: Process E (tau 65ms) completed I/O; added to ready queue [Q H E G J K B P F N M I D]
time 13203ms: Process O (tau 53ms) completed a CPU burst; 17 bursts to go [Q H E G J K B P F N M I D]
time 13203ms: Recalculated tau = 113ms for process O [Q H E G J K B P F N M I D]
time 13203ms: Process O switching out of CPU; will block on I/O until time 13333ms [Q H E G J K B P F N M I D]
time 13207ms: Process H (tau 55ms) started using the CPU for 78ms burst [Q E G J K B P F N M I D]
time 13285ms: Process H (tau 55ms) completed a CPU burst; 66 bursts to go [Q E G J K B P F N M I D]
time 13285ms: Recalculated tau = 73ms for process H [Q E G J K B P F N M I D]
time 13285ms: Process H switching out of CPU; will block on I/O until time 13293ms [Q E G J K B P F N M I D]
time 13289ms: Process E (tau 65ms) started using the CPU for 41ms burst [Q G J K B P F N M I D]
time 13293ms: Process H (tau 73ms) completed I/O; added to ready queue [Q G H J K B P F N M I D]
time 13330ms: Process E (tau 65ms) completed a CPU burst; 38 bursts to go [Q G H J K B P F N M I D]
time 13330ms: Recalculated tau = 47ms for process E [Q G H J K B P F N M I D]
time 13330ms: Process E switching out of CPU; will block on I/O until time 13352ms [Q G H J K B P F N M I D]
time 13333ms: Process O (tau 113ms) completed I/O; added to ready queue [Q H O J K B P F N M I D]
time 13334ms: Process G (tau 67ms) started using the CPU for 44ms burst [Q H O J K B P F N M I D]
time 13352ms: Process E (tau 47ms) completed I/O; added to ready queue [Q E H O J K B P F N M I D]
time 13378ms: Process G (tau 67ms) completed a CPU burst; 49 bursts to go [Q E H O J K B P F N M I D]
time 13378ms: Recalculated tau = 50ms for process G [Q E H O J K B P F N M I D]
time 13378ms: Process G switching out of CPU; will block on I/O until time 13404ms [Q E H O J K B P F N M I D]
time 13382ms: Process E (tau 47ms) started using the CPU for 44ms burst [Q H O J K B P F N M I D]
time 13404ms: Process G (tau 50ms) completed I/O; added to ready queue [Q G H O J K B P F N M I D]
time 13426ms: Process E (tau 47ms) completed a CPU burst; 37 bursts to go [Q G H O J K B P F N M I D]
time 13426ms: Recalculated tau = 45ms for process E [Q G H O J K B P F N M I D]
time 13426ms: Process E switching out of CPU; will block on I/O until time 13489ms [Q G H O J K B P F N M I D]
time 13430ms: Process G (tau 50ms) started using the CPU for 27ms burst [Q H O J K B P F N M I D]
time 13457ms: Process G (tau 50ms) completed a CPU burst; 48 bursts to go [Q H O J K B P F N M I D]
time 13457ms: Recalculated tau = 33ms for process G [Q H O J K B P F N M I D]
time 13457ms: Process G switching out of CPU; will block on I/O until time 13582ms [Q H O J K B P F N M I D]
time 13461ms: Process H (tau 73ms) started using the CPU for 16ms burst [Q O J K B P F N M I D]
time 13477ms: Process H (tau 73ms) completed a CPU burst; 65 bursts to go [Q O J K B P F N M I D]
time 13477ms: Recalculated tau = 31ms for process H [Q O J K B P F N M I D]
time 13477ms: Process H switching out of CPU; will block on I/O until time 13534ms [Q O J K B P F N M I D]
time 13481ms: Process O (tau 113ms) started using the CPU for 74ms burst [Q J K B P F N M I D]
time 13489ms: Process E (tau 45ms) completed I/O; added to ready queue [Q E J K B P F N M I D]
time 13534ms: Process H (tau 31ms) completed I/O; added to ready queue [Q H E J K B P F N M I D]
time 13555ms: Process O (tau 113ms) completed a CPU burst; 16 bursts to go [Q H E J K B P F N M I D]
time 13555ms: Recalculated tau = 84ms for process O [Q H E J K B P F N M I D]
time 13555ms: Process O switching out of CPU; will block on I/O until time 13646ms [Q H E J K B P F N M I D]
time 13559ms: Process H (tau 31ms) started using the CPU for 142ms burst [Q E J K B P F N M I D]
time 13582ms: Process G (tau 33ms) completed I/O; added to ready queue [Q G E J K B P F N M I D]
time 13646ms: Process O (tau 84ms) completed I/O; added to ready queue [Q G E O J K B P F N M I D]
time 13701ms: Process H (tau 31ms) completed a CPU burst; 64 bursts to go [Q G E O J K B P F N M I D]
time 13701ms: Recalculated tau = 115ms for process H [Q G E O J K B P F N M I D]
time 13701ms: Process H switching out of CPU; will block on I/O until time 13800ms [Q G E O J K B P F N M I D]
time 13705ms: Process G (tau 33ms) started using the CPU for 171ms burst [Q E O J K B P F N M I D]
time 13800ms: Process H (tau 115ms) completed I/O; added to ready queue [Q E O H J K B P F N M I D]
time 13876ms: Process G (tau 33ms) completed a CPU burst; 47 bursts to go [Q E O H J K B P F N M I D]
time 13876ms: Recalculated tau = 137ms for process G [Q E O H J K B P F N M I D]
time 13876ms: Process G switching out of CPU; will block on I/O until time 13907ms [Q E O H J K B P F N M I D]
time 13880ms: Process E (tau 45ms) started using the CPU for 74ms burst [Q O H J K B P F N M I D]
time 13907ms: Process G (tau 137ms) completed I/O; added to ready queue [Q O H G J K B P F N M I D]
time 13954ms: Process E (tau 45ms) completed a CPU burst; 36 bursts to go [Q O H G J K B P F N M I D]
time 13954ms: Recalculated tau = 67ms for process E [Q O H G J K B P F N M I D]
time 13954ms: Process E switching out of CPU; will block on I/O until time 14142ms [Q O H G J K B P F N M I D]
time 13958ms: Process O (tau 84ms) started using the CPU for 41ms burst [Q H G J K B P F N M I D]
time 13999ms: Process O (tau 84ms) completed a CPU burst; 15 bursts to go [Q H G J K B P F N M I D]
time 13999ms: Recalculated tau = 52ms for process O [Q H G J K B P F N M I D]
time 13999ms: Process O switching out of CPU; will block on I/O until time 14058ms [Q H G J K B P F N M I D]
time 14003ms: Process H (tau 115ms) started using the CPU for 62ms burst [Q G J K B P F N M I D]
time 14058ms: Process O (tau 52ms) completed I/O; added to ready queue [Q O G J K B P F N M I D]
time 14065ms: Process H (tau 115ms) completed a CPU burst; 63 bursts to go [Q O G J K B P F N M I D]
time 14065ms: Recalculated tau = 76ms for process H [Q O G J K B P F N M I D]
time 14065ms: Process H switching out of CPU; will block on I/O until time 14092ms [Q O G J K B P F N M I D]
time 14069ms: Process O (tau 52ms) started using the CPU for 57ms burst [Q G J K B P F N M I D]
time 14092ms: Process H (tau 76ms) completed I/O; added to ready queue [Q H G J K B P F N M I D]
time 14126ms: Process O (tau 52ms) completed a CPU burst; 14 bursts to go [Q H G J K B P F N M I D]
time 14126ms: Recalculated tau = 56ms for process O [Q H G J K B P F N M I D]
time 14126ms: Process O switching out of CPU; will block on I/O until time 14156ms [Q H G J K B P F N M I D]
time 14130ms: Process H (tau 76ms) started using the CPU for 248ms burst [Q G J K B P F N M I D]
time 14142ms: Process E (tau 67ms) completed I/O; added to ready queue [Q E G J K B P F N M I D]
time 14156ms: Process O (tau 56ms) completed I/O; added to ready queue [Q O E G J K B P F N M I D]
time 14378ms: Process H (tau 76ms) completed a CPU burst; 62 bursts to go [Q O E G J K B P F N M I D]
time 14378ms: Recalculated tau = 205ms for process H [Q O E G J K B P F N M I D]
time 14378ms: Process H switching out of CPU; will block on I/O until time 14462ms [Q O E G J K B P F N M I D]
time 14382ms: Process O (tau 56ms) started using the CPU for 159ms burst [Q E G J K B P F N M I D]
time 14462ms: Process H (tau 205ms) completed I/O; added to ready queue [Q E G J K B P F N M I D H]
time 14541ms: Process O (tau 56ms) completed a CPU burst; 13 bursts to go [Q E G J K B P F N M I D H]
time 14541ms: Recalculated tau = 134ms for process O [Q E G J K B P F N M I D H]
time 14541ms: Process O switching out of CPU; will block on I/O until time 14644ms [Q E G J K B P F N M I D H]
time 14545ms: Process E (tau 67ms) started using the CPU for 117ms burst [Q G J K B P F N M I D H]
time 14644ms: Process O (tau 134ms) completed I/O; added to ready queue [Q O G J K B P F N M I D H]
time 14662ms: Process E (tau 67ms) completed a CPU burst; 35 bursts to go [Q O G J K B P F N M I D H]
time 14662ms: Recalculated tau = 105ms for process E [Q O G J K B P F N M I D H]
time 14662ms: Process E switching out of CPU; will block on I/O until time 14764ms [Q O G J K B P F N M I D H]
time 14666ms: Process O (tau 134ms) started using the CPU for 87ms burst [Q G J K B P F N M I D H]
time 14753ms: Process O (tau 134ms) completed a CPU burst; 12 bursts to go [Q G J K B P F N M I D H]
time 14753ms: Recalculated tau = 99ms for process O [Q G J K B P F N M I D H]
time 14753ms: Process O switching out of CPU; will block on I/O until time 14916ms [Q G J K B P F N M I D H]
time 14757ms: Process G (tau 137ms) started using the CPU for 3ms burst [Q J K B P F N M I D H]
time 14760ms: Process G (tau 137ms) completed a CPU burst; 46 bursts to go [Q J K B P F N M I D H]
time 14760ms: Recalculated tau = 37ms for process G [Q J K B P F N M I D H]
time 14760ms: Process G switching out of CPU; will block on I/O until time 14892ms [Q J K B P F N M I D H]
time 14764ms: Process J (tau 174ms) started using the CPU for 7ms burst [Q K B P F N M I D H]
time 14764ms: Process E (tau 105ms) completed I/O; added to ready queue [Q E K B P F N M I D H]
time 14771ms: Process J terminated [Q E K B P F N M I D H]
time 14775ms: Process E (tau 105ms) started using the CPU for 14ms burst [Q K B P F N M I D H]
time 14789ms: Process E (tau 105ms) completed a CPU burst; 34 bursts to go [Q K B P F N M I D H]
time 14789ms: Recalculated tau = 37ms for process E [Q K B P F N M I D H]
time 14789ms: Process E switching out of CPU; will block on I/O until time 14793ms [Q K B P F N M I D H]
time 14793ms: Process K (tau 174ms) started using the CPU for 47ms burst [Q B P F N M I D H]
time 14793ms: Process E (tau 37ms) completed I/O; added to ready queue [Q E B P F N M I D H]
time 14840ms: Process K terminated [Q E B P F N M I D H]
time 14844ms: Process E (tau 37ms) started using the CPU for 156ms burst [Q B P F N M I D H]
time 14892ms: Process G (tau 37ms) completed I/O; added to ready queue [Q G B P F N M I D H]
time 14916ms: Process O (tau 99ms) completed I/O; added to ready queue [Q G O B P F N M I D H]
time 15000ms: Process E (tau 37ms) completed a CPU burst; 33 bursts to go [Q G O B P F N M I D H]
time 15000ms: Recalculated tau = 127ms for process E [Q G O B P F N M I D H]
time 15000ms: Process E switching out of CPU; will block on I/O until time 15102ms [Q G O B P F N M I D H]
time 15004ms: Process G (tau 37ms) started using the CPU for 107ms burst [Q O B P F N M I D H]
time 15102ms: Process E (tau 127ms) completed I/O; added to ready queue [Q O E B P F N M I D H]
time 15111ms: Process G (tau 37ms) completed a CPU burst; 45 bursts to go [Q O E B P F N M I D H]
time 15111ms: Recalculated tau = 90ms for process G [Q O E B P F N M I D H]
time 15111ms: Process G switching out of CPU; will block on I/O until time 15130ms [Q O E B P F N M I D H]
time 15115ms: Process O (tau 99ms) started using the CPU for 127ms burst [Q E B P F N M I D H]
time 15130ms: Process G (tau 90ms) completed I/O; added to ready queue [Q G E B P F N M I D H]
time 15242ms: Process O (tau 99ms) completed a CPU burst; 11 bursts to go [Q G E B P F N M I D H]
time 15242ms: Recalculated tau = 120ms for process O [Q G E B P F N M I D H]
time 15242ms: Process O switching out of CPU; will block on I/O until time 15460ms [Q G E B P F N M I D H]
time 15246ms: Process G (tau 90ms) started using the CPU for 111ms burst [Q E B P F N M I D H]
time 15357ms: Process G (tau 90ms) completed a CPU burst; 44 bursts to go [Q E B P F N M I D H]
time 15357ms: Recalculated tau = 106ms for process G [Q E B P F N M I D H]
time 15357ms: Process G switching out of CPU; will block on I/O until time 15390ms [Q E B P F N M I D H]
time 15361ms: Process E (tau 127ms) started using the CPU for 18ms burst [Q B P F N M I D H]
time 15379ms: Process E (tau 127ms) completed a CPU burst; 32 bursts to go [Q B P F N M I D H]
time 15379ms: Recalculated tau = 46ms for process E [Q B P F N M I D H]
time 15379ms: Process E switching out of CPU; will block on I/O until time 15425ms [Q B P F N M I D H]
time 15383ms: Process B (tau 175ms) started using the CPU for 208ms burst [Q P F N M I D H]
time 15390ms: Process G (tau 106ms) completed I/O; added to ready queue [Q G P F N M I D H]
time 15425ms: Process E (tau 46ms) completed I/O; added to ready queue [Q E G P F N M I D H]
time 15460ms: Process O (tau 120ms) completed I/O; added to ready queue [Q E G O P F N M I D H]
time 15591ms: Process B (tau 175ms) completed a CPU burst; 18 bursts to go [Q E G O P F N M I D H]
time 15591ms: Recalculated tau = 200ms for process B [Q E G O P F N M I D H]
time 15591ms: Process B switching out of CPU; will block on I/O until time 15755ms [Q E G O P F N M I D H]
time 15595ms: Process E (tau 46ms) started using the CPU for 215ms burst [Q G O P F N M I D H]
time 15755ms: Process B (tau 200ms) completed I/O; added to ready queue [Q G O P F N M I D B H]
time 15810ms: Process E (tau 46ms) completed a CPU burst; 31 bursts to go [Q G O P F N M I D B H]
time 15810ms: Recalculated tau = 173ms for process E [Q G O P F N M I D B H]
time 15810ms: Process E switching out of CPU; will block on I/O until time 15821ms [Q G O P F N M I D B H]
time 15814ms: Process G (tau 106ms) started using the CPU for 11ms burst [Q O P F N M I D B H]
time 15821ms: Process E (tau 173ms) completed I/O; added to ready queue [Q O E P F N M I D B H]
time 15825ms: Process G (tau 106ms) completed a CPU burst; 43 bursts to go [Q O E P F N M I D B H]
time 15825ms: Recalculated tau = 35ms for process G [Q O E P F N M I D B H]
time 15825ms: Process G switching out of CPU; will block on I/O until time 15905ms [Q O E P F N M I D B H]
time 15829ms: Process O (tau 120ms) started using the CPU for 9ms burst [Q E P F N M I D B H]
time 15838ms: Process O (tau 120ms) completed a CPU burst; 10 bursts to go [Q E P F N M I D B H]
time 15838ms: Recalculated tau = 37ms for process O [Q E P F N M I D B H]
time 15838ms: Process O switching out of CPU; will block on I/O until time 15847ms [Q E P F N M I D B H]
time 15842ms: Process E (tau 173ms) started using the CPU for 224ms burst [Q P F N M I D B H]
time 15847ms: Process O (tau 37ms) completed I/O; added to ready queue [Q O P F N M I D B H]
time 15905ms: Process G (tau 35ms) completed I/O; added to ready queue [Q G O P F N M I D B H]
time 16066ms: Process E (tau 173ms) completed a CPU burst; 30 bursts to go [Q G O P F N M I D B H]
time 16066ms: Recalculated tau = 212ms for process E [Q G O P F N M I D B H]
time 16066ms: Process E switching out of CPU; will block on I/O until time 16176ms [Q G O P F N M I D B H]
time 16070ms: Process G (tau 35ms) started using the CPU for 28ms burst [Q O P F N M I D B H]
time 16098ms: Process G (tau 35ms) completed a CPU burst; 42 bursts to go [Q O P F N M I D B H]
time 16098ms: Recalculated tau = 30ms for process G [Q O P F N M I D B H]
time 16098ms: Process G switching out of CPU; will block on I/O until time 16106ms [Q O P F N M I D B H]
time 16102ms: Process O (tau 37ms) started using the CPU for 54ms burst [Q P F N M I D B H]
time 16106ms: Process G (tau 30ms) completed I/O; added to ready queue [Q G P F N M I D B H]
time 16156ms: Process O (tau 37ms) completed a CPU burst; 9 bursts to go [Q G P F N M I D B H]
time 16156ms: Recalculated tau = 50ms for process O [Q G P F N M I D B H]
time 16156ms: Process O switching out of CPU; will block on I/O until time 16181ms [Q G P F N M I D B H]
time 16160ms: Process G (tau 30ms) started using the CPU for 137ms burst [Q P F N M I D B H]
time 16176ms: Process E (tau 212ms) completed I/O; added to ready queue [Q P F N M I D B H E]
time 16181ms: Process O (tau 50ms) completed I/O; added to ready queue [Q O P F N M I D B H E]
time 16297ms: Process G (tau 30ms) completed a CPU burst; 41 bursts to go [Q O P F N M I D B H E]
time 16297ms: Recalculated tau = 111ms for process G [Q O P F N M I D B H E]
time 16297ms: Process G switching out of CPU; will block on I/O until time 16354ms [Q O P F N M I D B H E]
time 16301ms: Process O (tau 50ms) started using the CPU for 41ms burst [Q P F N M I D B H E]
time 16342ms: Process O (tau 50ms) completed a CPU burst; 8 bursts to go [Q P F N M I D B H E]
time 16342ms: Recalculated tau = 44ms for process O [Q P F N M I D B H E]
time 16342ms: Process O switching out of CPU; will block on I/O until time 16371ms [Q P F N M I D B H E]
time 16346ms: Process P (tau 176ms) started using the CPU for 83ms burst [Q F N M I D B H E]
time 16354ms: Process G (tau 111ms) completed I/O; added to ready queue [Q G F N M I D B H E]
time 16371ms: Process O (tau 44ms) completed I/O; added to ready queue [Q O G F N M I D B H E]
time 16429ms: Process P (tau 176ms) completed a CPU burst; 4 bursts to go [Q O G F N M I D B H E]
time 16429ms: Recalculated tau = 107ms for process P [Q O G F N M I D B H E]
time 16429ms: Process P switching out of CPU; will block on I/O until time 16458ms [Q O G F N M I D B H E]
time 16433ms: Process O (tau 44ms) started using the CPU for 190ms burst [Q G F N M I D B H E]
time 16458ms: Process P (tau 107ms) completed I/O; added to ready queue [Q P G F N M I D B H E]
time 16623ms: Process O (tau 44ms) completed a CPU burst; 7 bursts to go [Q P G F N M I D B H E]
time 16623ms: Recalculated tau = 154ms for process O [Q P G F N M I D B H E]
time 16623ms: Process O switching out of CPU; will block on I/O until time 16647ms [Q P G F N M I D B H E]
time 16627ms: Process P (tau 107ms) started using the CPU for 75ms burst [Q G F N M I D B H E]
time 16647ms: Process O (tau 154ms) completed I/O; added to ready queue [Q G O F N M I D B H E]
time 16702ms: Process P (tau 107ms) completed a CPU burst; 3 bursts to go [Q G O F N M I D B H E]
time 16702ms: Recalculated tau = 83ms for process P [Q G O F N M I D B H E]
time 16702ms: Process P switching out of CPU; will block on I/O until time 16722ms [Q G O F N M I D B H E]
time 16706ms: Process G (tau 111ms) started using the CPU for 124ms burst [Q O F N M I D B H E]
time 16722ms: Process P (tau 83ms) completed I/O; added to ready queue [Q P O F N M I D B H E]
time 16830ms: Process G (tau 111ms) completed a CPU burst; 40 bursts to go [Q P O F N M I D B H E]
time 16830ms: Recalculated tau = 121ms for process G [Q P O F N M I D B H E]
time 16830ms: Process G switching out of CPU; will block on I/O until time 16907ms [Q P O F N M I D B H E]
time 16834ms: Process P (tau 83ms) started using the CPU for 1ms burst [Q O F N M I D B H E]
time 16835ms: Process P (tau 83ms) completed a CPU burst; 2 bursts to go [Q O F N M I D B H E]
time 16835ms: Recalculated tau = 22ms for process P [Q O F N M I D B H E]
time 16835ms: Process P switching out of CPU; will block on I/O until time 16855ms [Q O F N M I D B H E]
time 16839ms: Process O (tau 154ms) started using the CPU for 30ms burst [Q F N M I D B H E]
time 16855ms: Process P (tau 22ms) completed I/O; added to ready queue [Q P F N M I D B H E]
time 16869ms: Process O (tau 154ms) completed a CPU burst; 6 bursts to go [Q P F N M I D B H E]
time 16869ms: Recalculated tau = 61ms for process O [Q P F N M I D B H E]
time 16869ms: Process O switching out of CPU; will block on I/O until time 16902ms [Q P F N M I D B H E]
time 16873ms: Process P (tau 22ms) started using the CPU for 131ms burst [Q F N M I D B H E]
time 16902ms: Process O (tau 61ms) completed I/O; added to ready queue [Q O F N M I D B H E]
time 16907ms: Process G (tau 121ms) completed I/O; added to ready queue [Q O G F N M I D B H E]
time 17004ms: Process P (tau 22ms) completed a CPU burst; 1 burst to go [Q O G F N M I D B H E]
time 17004ms: Recalculated tau = 104ms for process P [Q O G F N M I D B H E]
time 17004ms: Process P switching out of CPU; will block on I/O until time 17051ms [Q O G F N M I D B H E]
time 17008ms: Process O (tau 61ms) started using the CPU for 250ms burst [Q G F N M I D B H E]
time 17051ms: Process P (tau 104ms) completed I/O; added to ready queue [Q P G F N M I D B H E]
time 17258ms: Process O (tau 61ms) completed a CPU burst; 5 bursts to go [Q P G F N M I D B H E]
time 17258ms: Recalculated tau = 203ms for process O [Q P G F N M I D B H E]
time 17258ms: Process O switching out of CPU; will block on I/O until time 17312ms [Q P G F N M I D B H E]
time 17262ms: Process P (tau 104ms) started using the CPU for 9ms burst [Q G F N M I D B H E]
time 17271ms: Process P terminated [Q G F N M I D B H E]
time 17275ms: Process G (tau 121ms) started using the CPU for 108ms burst [Q F N M I D B H E]
time 17312ms: Process O (tau 203ms) completed I/O; added to ready queue [Q F N M I D B O H E]
time 17383ms: Process G (tau 121ms) completed a CPU burst; 39 bursts to go [Q F N M I D B O H E]
time 17383ms: Recalculated tau = 112ms for process G [Q F N M I D B O H E]
time 17383ms: Process G switching out of CPU; will block on I/O until time 17502ms [Q F N M I D B O H E]
time 17387ms: Process F (tau 180ms) started using the CPU for 33ms burst [Q N M I D B O H E]
time 17420ms: Process F (tau 180ms) completed a CPU burst; 27 bursts to go [Q N M I D B O H E]
time 17420ms: Recalculated tau = 70ms for process F [Q N M I D B O H E]
time 17420ms: Process F switching out of CPU; will block on I/O until time 17478ms [Q N M I D B O H E]
time 17424ms: Process N (tau 185ms) started using the CPU for 132ms burst [Q M I D B O H E]
time 17478ms: Process F (tau 70ms) completed I/O; added to ready queue [Q F M I D B O H E]
time 17502ms: Process G (tau 112ms) completed I/O; added to ready queue [Q F G M I D B O H E]
time 17556ms: Process N (tau 185ms) completed a CPU burst; 29 bursts to go [Q F G M I D B O H E]
time 17556ms: Recalculated tau = 146ms for process N [Q F G M I D B O H E]
