Process A [NEW] (arrival time 9 ms) 16 CPU bursts (tau 100ms)
Process B [NEW] (arrival time 18 ms) 21 CPU bursts (tau 100ms)
Process C [NEW] (arrival time 42 ms) 4 CPU bursts (tau 100ms)
Process D [NEW] (arrival time 156 ms) 11 CPU bursts (tau 100ms)
Process E [NEW] (arrival time 134 ms) 55 CPU bursts (tau 100ms)
Process F [NEW] (arrival time 106 ms) 34 CPU bursts (tau 100ms)
Process G [NEW] (arrival time 65 ms) 80 CPU bursts (tau 100ms)
Process H [NEW] (arrival time 11 ms) 83 CPU bursts (tau 100ms)
Process I [NEW] (arrival time 68 ms) 77 CPU bursts (tau 100ms)
Process J [NEW] (arrival time 0 ms) 10 CPU bursts (tau 100ms)
Process K [NEW] (arrival time 7 ms) 13 CPU bursts (tau 100ms)
Process L [NEW] (arrival time 189 ms) 7 CPU bursts (tau 100ms)
Process M [NEW] (arrival time 16 ms) 48 CPU bursts (tau 100ms)
Process N [NEW] (arrival time 122 ms) 31 CPU bursts (tau 100ms)
Process O [NEW] (arrival time 29 ms) 31 CPU bursts (tau 100ms)
Process P [NEW] (arrival time 159 ms) 16 CPU bursts (tau 100ms)
time 0ms: Simulator started for SJF [Q J]
time 0ms: Process J (tau 100ms) arrived; added to ready queue [Q J]
time 2ms: Process J (tau 100ms) started using the CPU for 40ms burst [Q <empty>]
time 7ms: Process K (tau 100ms) arrived; added to ready queue [Q K]
time 9ms: Process A (tau 100ms) arrived; added to ready queue [Q A K]
time 11ms: Process H (tau 100ms) arrived; added to ready queue [Q A H K]
time 16ms: Process M (tau 100ms) arrived; added to ready queue [Q A H K M]
time 18ms: Process B (tau 100ms) arrived; added to ready queue [Q A B H K M]
time 29ms: Process O (tau 100ms) arrived; added to ready queue [Q A B H K M O]
time 42ms: Process J (tau 100ms) completed a CPU burst; 9 bursts to go [Q A B H K M O]
time 42ms: Recalculated tau = 55ms for process J [Q A B H K M O]
time 42ms: Process J switching out of CPU; will block on I/O until time 47ms [Q A B H K M O]
time 42ms: Process C (tau 100ms) arrived; added to ready queue [Q A B C H K M O]
time 46ms: Process A (tau 100ms) started using the CPU for 56ms burst [Q B C H K M O]
time 47ms: Process J (tau 55ms) completed I/O; added to ready queue [Q B C H J K M O]
time 65ms: Process G (tau 100ms) arrived; added to ready queue [Q B C G H J K M O]
time 68ms: Process I (tau 100ms) arrived; added to ready queue [Q B C G H I J K M O]
time 102ms: Process A (tau 100ms) completed a CPU burst; 15 bursts to go [Q B C G H I J K M O]
time 102ms: Recalculated tau = 67ms for process A [Q B C G H I J K M O]
time 102ms: Process A switching out of CPU; will block on I/O until time 127ms [Q B C G H I J K M O]
time 106ms: Process J (tau 55ms) started using the CPU for 204ms burst [Q B C G H I K M O]
time 106ms: Process F (tau 100ms) arrived; added to ready queue [Q B C F G H I K M O]
time 122ms: Process N (tau 100ms) arrived; added to ready queue [Q B C F G H I K M N O]
time 127ms: Process A (tau 67ms) completed I/O; added to ready queue [Q A B C F G H I K M N O]
time 134ms: Process E (tau 100ms) arrived; added to ready queue [Q A B C E F G H I K M N O]
time 156ms: Process D (tau 100ms) arrived; added to ready queue [Q A B C D E F G H I K M N O]
time 159ms: Process P (tau 100ms) arrived; added to ready queue [Q A B C D E F G H I K M N O P]
time 189ms: Process L (tau 100ms) arrived; added to ready queue [Q A B C D E F G H I K L M N O P]
time 310ms: Process J (tau 55ms) completed a CPU burst; 8 bursts to go [Q A B C D E F G H I K L M N O P]
time 310ms: Recalculated tau = 167ms for process J [Q A B C D E F G H I K L M N O P]
time 310ms: Process J switching out of CPU; will block on I/O until time 382ms [Q A B C D E F G H I K L M N O P]
time 314ms: Process A (tau 67ms) started using the CPU for 60ms burst [Q B C D E F G H I K L M N O P]
time 374ms: Process A (tau 67ms) completed a CPU burst; 14 bursts to go [Q B C D E F G H I K L M N O P]
time 374ms: Recalculated tau = 62ms for process A [Q B C D E F G H I K L M N O P]
time 374ms: Process A switching out of CPU; will block on I/O until time 529ms [Q B C D E F G H I K L M N O P]
time 378ms: Process B (tau 100ms) started using the CPU for 106ms burst [Q C D E F G H I K L M N O P]
time 382ms: Process J (tau 167ms) completed I/O; added to ready queue [Q C D E F G H I J K L M N O P]
time 484ms: Process B (tau 100ms) completed a CPU burst; 20 bursts to go [Q C D E F G H I J K L M N O P]
time 484ms: Recalculated tau = 105ms for process B [Q C D E F G H I J K L M N O P]
time 484ms: Process B switching out of CPU; will block on I/O until time 642ms [Q C D E F G H I J K L M N O P]
time 488ms: Process C (tau 100ms) started using the CPU for 94ms burst [Q D E F G H I J K L M N O P]
time 529ms: Process A (tau 62ms) completed I/O; added to ready queue [Q A D E F G H I J K L M N O P]
time 582ms: Process C (tau 100ms) completed a CPU burst; 3 bursts to go [Q A D E F G H I J K L M N O P]
time 582ms: Recalculated tau = 96ms for process C [Q A D E F G H I J K L M N O P]
time 582ms: Process C switching out of CPU; will block on I/O until time 742ms [Q A D E F G H I J K L M N O P]
time 586ms: Process A (tau 62ms) started using the CPU for 39ms burst [Q D E F G H I J K L M N O P]
time 625ms: Process A (tau 62ms) completed a CPU burst; 13 bursts to go [Q D E F G H I J K L M N O P]
time 625ms: Recalculated tau = 45ms for process A [Q D E F G H I J K L M N O P]
time 625ms: Process A switching out of CPU; will block on I/O until time 677ms [Q D E F G H I J K L M N O P]
time 629ms: Process D (tau 100ms) started using the CPU for 148ms burst [Q E F G H I J K L M N O P]
time 642ms: Process B (tau 105ms) completed I/O; added to ready queue [Q B E F G H I J K L M N O P]
time 677ms: Process A (tau 45ms) completed I/O; added to ready queue [Q A B E F G H I J K L M N O P]
time 742ms: Process C (tau 96ms) completed I/O; added to ready queue [Q A B C E F G H I J K L M N O P]
time 777ms: Process D (tau 100ms) completed a CPU burst; 10 bursts to go [Q A B C E F G H I J K L M N O P]
time 777ms: Recalculated tau = 136ms for process D [Q A B C E F G H I J K L M N O P]
time 777ms: Process D switching out of CPU; will block on I/O until time 781ms [Q A B C E F G H I J K L M N O P]
time 781ms: Process A (tau 45ms) started using the CPU for 47ms burst [Q B C E F G H I J K L M N O P]
time 781ms: Process D (tau 136ms) completed I/O; added to ready queue [Q B C D E F G H I J K L M N O P]
time 828ms: Process A (tau 45ms) completed a CPU burst; 12 bursts to go [Q B C D E F G H I J K L M N O P]
time 828ms: Recalculated tau = 47ms for process A [Q B C D E F G H I J K L M N O P]
time 828ms: Process A switching out of CPU; will block on I/O until time 832ms [Q B C D E F G H I J K L M N O P]
time 832ms: Process C (tau 96ms) started using the CPU for 117ms burst [Q B D E F G H I J K L M N O P]
time 832ms: Process A (tau 47ms) completed I/O; added to ready queue [Q A B D E F G H I J K L M N O P]
time 949ms: Process C (tau 96ms) completed a CPU burst; 2 bursts to go [Q A B D E F G H I J K L M N O P]
time 949ms: Recalculated tau = 112ms for process C [Q A B D E F G H I J K L M N O P]
time 949ms: Process C switching out of CPU; will block on I/O until time 968ms [Q A B D E F G H I J K L M N O P]
time 953ms: Process A (tau 47ms) started using the CPU for 137ms burst [Q B D E F G H I J K L M N O P]
time 968ms: Process C (tau 112ms) completed I/O; added to ready queue [Q B C D E F G H I J K L M N O P]
time 1090ms: Process A (tau 47ms) completed a CPU burst; 11 bursts to go [Q B C D E F G H I J K L M N O P]
time 1090ms: Recalculated tau = 115ms for process A [Q B C D E F G H I J K L M N O P]
time 1090ms: Process A switching out of CPU; will block on I/O until time 1116ms [Q B C D E F G H I J K L M N O P]
time 1094ms: Process E (tau 100ms) started using the CPU for 152ms burst [Q B C D F G H I J K L M N O P]
time 1116ms: Process A (tau 115ms) completed I/O; added to ready queue [Q A B C D F G H I J K L M N O P]
time 1246ms: Process E (tau 100ms) completed a CPU burst; 54 bursts to go [Q A B C D F G H I J K L M N O P]
time 1246ms: Recalculated tau = 139ms for process E [Q A B C D F G H I J K L M N O P]
time 1246ms: Process E switching out of CPU; will block on I/O until time 1294ms [Q A B C D F G H I J K L M N O P]
time 1250ms: Process F (tau 100ms) started using the CPU for 129ms burst [Q A B C D G H I J K L M N O P]
time 1294ms: Process E (tau 139ms) completed I/O; added to ready queue [Q A B C D E G H I J K L M N O P]
time 1379ms: Process F (tau 100ms) completed a CPU burst; 33 bursts to go [Q A B C D E G H I J K L M N O P]
time 1379ms: Recalculated tau = 122ms for process F [Q A B C D E G H I J K L M N O P]
time 1379ms: Process F switching out of CPU; will block on I/O until time 1438ms [Q A B C D E G H I J K L M N O P]
time 1383ms: Process G (tau 100ms) started using the CPU for 70ms burst [Q A B C D E H I J K L M N O P]
time 1438ms: Process F (tau 122ms) completed I/O; added to ready queue [Q A B C D E F H I J K L M N O P]
time 1453ms: Process G (tau 100ms) completed a CPU burst; 79 bursts to go [Q A B C D E F H I J K L M N O P]
time 1453ms: Recalculated tau = 78ms for process G [Q A B C D E F H I J K L M N O P]
time 1453ms: Process G switching out of CPU; will block on I/O until time 1486ms [Q A B C D E F H I J K L M N O P]
time 1457ms: Process H (tau 100ms) started using the CPU for 96ms burst [Q A B C D E F I J K L M N O P]
time 1486ms: Process G (tau 78ms) completed I/O; added to ready queue [Q A B C D E F G I J K L M N O P]
time 1553ms: Process H (tau 100ms) completed a CPU burst; 82 bursts to go [Q A B C D E F G I J K L M N O P]
time 1553ms: Recalculated tau = 97ms for process H [Q A B C D E F G I J K L M N O P]
time 1553ms: Process H switching out of CPU; will block on I/O until time 1622ms [Q A B C D E F G I J K L M N O P]
time 1557ms: Process G (tau 78ms) started using the CPU for 40ms burst [Q A B C D E F I J K L M N O P]
time 1597ms: Process G (tau 78ms) completed a CPU burst; 78 bursts to go [Q A B C D E F I J K L M N O P]
time 1597ms: Recalculated tau = 50ms for process G [Q A B C D E F I J K L M N O P]
time 1597ms: Process G switching out of CPU; will block on I/O until time 1605ms [Q A B C D E F I J K L M N O P]
time 1601ms: Process I (tau 100ms) started using the CPU for 220ms burst [Q A B C D E F J K L M N O P]
time 1605ms: Process G (tau 50ms) completed I/O; added to ready queue [Q A B C D E F G J K L M N O P]
time 1622ms: Process H (tau 97ms) completed I/O; added to ready queue [Q A B C D E F G H J K L M N O P]
time 1821ms: Process I (tau 100ms) completed a CPU burst; 76 bursts to go [Q A B C D E F G H J K L M N O P]
time 1821ms: Recalculated tau = 190ms for process I [Q A B C D E F G H J K L M N O P]
time 1821ms: Process I switching out of CPU; will block on I/O until time 1842ms [Q A B C D E F G H J K L M N O P]
time 1825ms: Process G (tau 50ms) started using the CPU for 65ms burst [Q A B C D E F H J K L M N O P]
time 1842ms: Process I (tau 190ms) completed I/O; added to ready queue [Q A B C D E F H I J K L M N O P]
time 1890ms: Process G (tau 50ms) completed a CPU burst; 77 bursts to go [Q A B C D E F H I J K L M N O P]
time 1890ms: Recalculated tau = 61ms for process G [Q A B C D E F H I J K L M N O P]
time 1890ms: Process G switching out of CPU; will block on I/O until time 1936ms [Q A B C D E F H I J K L M N O P]
time 1894ms: Process H (tau 97ms) started using the CPU for 48ms burst [Q A B C D E F I J K L M N O P]
time 1936ms: Process G (tau 61ms) completed I/O; added to ready queue [Q A B C D E F G I J K L M N O P]
time 1942ms: Process H (tau 97ms) completed a CPU burst; 81 bursts to go [Q A B C D E F G I J K L M N O P]
time 1942ms: Recalculated tau = 60ms for process H [Q A B C D E F G I J K L M N O P]
time 1942ms: Process H switching out of CPU; will block on I/O until time 1966ms [Q A B C D E F G I J K L M N O P]
time 1946ms: Process G (tau 61ms) started using the CPU for 13ms burst [Q A B C D E F I J K L M N O P]
time 1959ms: Process G (tau 61ms) completed a CPU burst; 76 bursts to go [Q A B C D E F I J K L M N O P]
time 1959ms: Recalculated tau = 25ms for process G [Q A B C D E F I J K L M N O P]
time 1959ms: Process G switching out of CPU; will block on I/O until time 1999ms [Q A B C D E F I J K L M N O P]
time 1963ms: Process K (tau 100ms) started using the CPU for 64ms burst [Q A B C D E F I J L M N O P]
time 1966ms: Process H (tau 60ms) completed I/O; added to ready queue [Q A B C D E F H I J L M N O P]
time 1999ms: Process G (tau 25ms) completed I/O; added to ready queue [Q A B C D E F G H I J L M N O P]
time 2027ms: Process K (tau 100ms) completed a CPU burst; 12 bursts to go [Q A B C D E F G H I J L M N O P]
time 2027ms: Recalculated tau = 73ms for process K [Q A B C D E F G H I J L M N O P]
time 2027ms: Process K switching out of CPU; will block on I/O until time 2125ms [Q A B C D E F G H I J L M N O P]
time 2031ms: Process G (tau 25ms) started using the CPU for 128ms burst [Q A B C D E F H I J L M N O P]
time 2125ms: Process K (tau 73ms) completed I/O; added to ready queue [Q A B C D E F H I J K L M N O P]
time 2159ms: Process G (tau 25ms) completed a CPU burst; 75 bursts to go [Q A B C D E F H I J K L M N O P]
time 2159ms: Recalculated tau = 102ms for process G [Q A B C D E F H I J K L M N O P]
time 2159ms: Process G switching out of CPU; will block on I/O until time 2383ms [Q A B C D E F H I J K L M N O P]
time 2163ms: Process H (tau 60ms) started using the CPU for 72ms burst [Q A B C D E F I J K L M N O P]
time 2235ms: Process H (tau 60ms) completed a CPU burst; 80 bursts to go [Q A B C D E F I J K L M N O P]
time 2235ms: Recalculated tau = 69ms for process H [Q A B C D E F I J K L M N O P]
time 2235ms: Process H switching out of CPU; will block on I/O until time 2279ms [Q A B C D E F I J K L M N O P]
time 2239ms: Process K (tau 73ms) started using the CPU for 56ms burst [Q A B C D E F I J L M N O P]
time 2279ms: Process H (tau 69ms) completed I/O; added to ready queue [Q A B C D E F H I J L M N O P]
time 2295ms: Process K (tau 73ms) completed a CPU burst; 11 bursts to go [Q A B C D E F H I J L M N O P]
time 2295ms: Recalculated tau = 60ms for process K [Q A B C D E F H I J L M N O P]
time 2295ms: Process K switching out of CPU; will block on I/O until time 2370ms [Q A B C D E F H I J L M N O P]
time 2299ms: Process H (tau 69ms) started using the CPU for 12ms burst [Q A B C D E F I J L M N O P]
time 2311ms: Process H (tau 69ms) completed a CPU burst; 79 bursts to go [Q A B C D E F I J L M N O P]
time 2311ms: Recalculated tau = 26ms for process H [Q A B C D E F I J L M N O P]
time 2311ms: Process H switching out of CPU; will block on I/O until time 2326ms [Q A B C D E F I J L M N O P]
time 2315ms: Process L (tau 100ms) started using the CPU for 135ms burst [Q A B C D E F I J M N O P]
time 2326ms: Process H (tau 26ms) completed I/O; added to ready queue [Q A B C D E F H I J M N O P]
time 2370ms: Process K (tau 60ms) completed I/O; added to ready queue [Q A B C D E F H I J K M N O P]
time 2383ms: Process G (tau 102ms) completed I/O; added to ready queue [Q A B C D E F G H I J K M N O P]
time 2450ms: Process L (tau 100ms) completed a CPU burst; 6 bursts to go [Q A B C D E F G H I J K M N O P]
time 2450ms: Recalculated tau = 126ms for process L [Q A B C D E F G H I J K M N O P]
time 2450ms: Process L switching out of CPU; will block on I/O until time 2526ms [Q A B C D E F G H I J K M N O P]
time 2454ms: Process H (tau 26ms) started using the CPU for 41ms burst [Q A B C D E F G I J K M N O P]
time 2495ms: Process H (tau 26ms) completed a CPU burst; 78 bursts to go [Q A B C D E F G I J K M N O P]
time 2495ms: Recalculated tau = 37ms for process H [Q A B C D E F G I J K M N O P]
time 2495ms: Process H switching out of CPU; will block on I/O until time 2518ms [Q A B C D E F G I J K M N O P]
time 2499ms: Process K (tau 60ms) started using the CPU for 6ms burst [Q A B C D E F G I J M N O P]
time 2505ms: Process K (tau 60ms) completed a CPU burst; 10 bursts to go [Q A B C D E F G I J M N O P]
time 2505ms: Recalculated tau = 20ms for process K [Q A B C D E F G I J M N O P]
time 2505ms: Process K switching out of CPU; will block on I/O until time 2577ms [Q A B C D E F G I J M N O P]
time 2509ms: Process M (tau 100ms) started using the CPU for 22ms burst [Q A B C D E F G I J N O P]
time 2518ms: Process H (tau 37ms) completed I/O; added to ready queue [Q A B C D E F G H I J N O P]
time 2526ms: Process L (tau 126ms) completed I/O; added to ready queue [Q A B C D E F G H I J L N O P]
time 2531ms: Process M (tau 100ms) completed a CPU burst; 47 bursts to go [Q A B C D E F G H I J L N O P]
time 2531ms: Recalculated tau = 42ms for process M [Q A B C D E F G H I J L N O P]
time 2531ms: Process M switching out of CPU; will block on I/O until time 2550ms [Q A B C D E F G H I J L N O P]
time 2535ms: Process H (tau 37ms) started using the CPU for 160ms burst [Q A B C D E F G I J L N O P]
time 2550ms: Process M (tau 42ms) completed I/O; added to ready queue [Q A B C D E F G I J L M N O P]
time 2577ms: Process K (tau 20ms) completed I/O; added to ready queue [Q A B C D E F G I J K L M N O P]
time 2695ms: Process H (tau 37ms) completed a CPU burst; 77 bursts to go [Q A B C D E F G I J K L M N O P]
time 2695ms: Recalculated tau = 129ms for process H [Q A B C D E F G I J K L M N O P]
time 2695ms: Process H switching out of CPU; will block on I/O until time 2757ms [Q A B C D E F G I J K L M N O P]
time 2699ms: Process K (tau 20ms) started using the CPU for 6ms burst [Q A B C D E F G I J L M N O P]
time 2705ms: Process K (tau 20ms) completed a CPU burst; 9 bursts to go [Q A B C D E F G I J L M N O P]
time 2705ms: Recalculated tau = 10ms for process K [Q A B C D E F G I J L M N O P]
time 2705ms: Process K switching out of CPU; will block on I/O until time 2782ms [Q A B C D E F G I J L M N O P]
time 2709ms: Process M (tau 42ms) started using the CPU for 93ms burst [Q A B C D E F G I J L N O P]
time 2757ms: Process H (tau 129ms) completed I/O; added to ready queue [Q A B C D E F G H I J L N O P]
time 2782ms: Process K (tau 10ms) completed I/O; added to ready queue [Q A B C D E F G H I J K L N O P]
time 2802ms: Process M (tau 42ms) completed a CPU burst; 46 bursts to go [Q A B C D E F G H I J K L N O P]
time 2802ms: Recalculated tau = 80ms for process M [Q A B C D E F G H I J K L N O P]
time 2802ms: Process M switching out of CPU; will block on I/O until time 2846ms [Q A B C D E F G H I J K L N O P]
time 2806ms: Process K (tau 10ms) started using the CPU for 157ms burst [Q A B C D E F G H I J L N O P]
time 2846ms: Process M (tau 80ms) completed I/O; added to ready queue [Q A B C D E F G H I J L M N O P]
time 2963ms: Process K (tau 10ms) completed a CPU burst; 8 bursts to go [Q A B C D E F G H I J L M N O P]
time 2963ms: Recalculated tau = 120ms for process K [Q A B C D E F G H I J L M N O P]
time 2963ms: Process K switching out of CPU; will block on I/O until time 2981ms [Q A B C D E F G H I J L M N O P]
time 2967ms: Process M (tau 80ms) started using the CPU for 79ms burst [Q A B C D E F G H I J L N O P]
time 2981ms: Process K (tau 120ms) completed I/O; added to ready queue [Q A B C D E F G H I J K L N O P]
time 3046ms: Process M (tau 80ms) completed a CPU burst; 45 bursts to go [Q A B C D E F G H I J K L N O P]
time 3046ms: Recalculated tau = 79ms for process M [Q A B C D E F G H I J K L N O P]
time 3046ms: Process M switching out of CPU; will block on I/O until time 3162ms [Q A B C D E F G H I J K L N O P]
time 3050ms: Process N (tau 100ms) started using the CPU for 213ms burst [Q A B C D E F G H I J K L O P]
time 3162ms: Process M (tau 79ms) completed I/O; added to ready queue [Q A B C D E F G H I J K L M O P]
time 3263ms: Process N (tau 100ms) completed a CPU burst; 30 bursts to go [Q A B C D E F G H I J K L M O P]
time 3263ms: Recalculated tau = 185ms for process N [Q A B C D E F G H I J K L M O P]
time 3263ms: Process N switching out of CPU; will block on I/O until time 3280ms [Q A B C D E F G H I J K L M O P]
time 3267ms: Process M (tau 79ms) started using the CPU for 18ms burst [Q A B C D E F G H I J K L O P]
time 3280ms: Process N (tau 185ms) completed I/O; added to ready queue [Q A B C D E F G H I J K L N O P]
time 3285ms: Process M (tau 79ms) completed a CPU burst; 44 bursts to go [Q A B C D E F G H I J K L N O P]
time 3285ms: Recalculated tau = 33ms for process M [Q A B C D E F G H I J K L N O P]
time 3285ms: Process M switching out of CPU; will block on I/O until time 3484ms [Q A B C D E F G H I J K L N O P]
time 3289ms: Process O (tau 100ms) started using the CPU for 156ms burst [Q A B C D E F G H I J K L N P]
time 3445ms: Process O (tau 100ms) completed a CPU burst; 30 bursts to go [Q A B C D E F G H I J K L N P]
time 3445ms: Recalculated tau = 142ms for process O [Q A B C D E F G H I J K L N P]
time 3445ms: Process O switching out of CPU; will block on I/O until time 3514ms [Q A B C D E F G H I J K L N P]
time 3449ms: Process P (tau 100ms) started using the CPU for 4ms burst [Q A B C D E F G H I J K L N]
time 3453ms: Process P (tau 100ms) completed a CPU burst; 15 bursts to go [Q A B C D E F G H I J K L N]
time 3453ms: Recalculated tau = 28ms for process P [Q A B C D E F G H I J K L N]
time 3453ms: Process P switching out of CPU; will block on I/O until time 3640ms [Q A B C D E F G H I J K L N]
time 3457ms: Process G (tau 102ms) started using the CPU for 15ms burst [Q A B C D E F H I J K L N]
time 3472ms: Process G (tau 102ms) completed a CPU burst; 74 bursts to go [Q A B C D E F H I J K L N]
time 3472ms: Recalculated tau = 37ms for process G [Q A B C D E F H I J K L N]
time 3472ms: Process G switching out of CPU; will block on I/O until time 3568ms [Q A B C D E F H I J K L N]
time 3476ms: Process B (tau 105ms) started using the CPU for 198ms burst [Q A C D E F H I J K L N]
time 3484ms: Process M (tau 33ms) completed I/O; added to ready queue [Q A C D E F H I J K L M N]
time 3514ms: Process O (tau 142ms) completed I/O; added to ready queue [Q A C D E F H I J K L M N O]
time 3568ms: Process G (tau 37ms) completed I/O; added to ready queue [Q A C D E F G H I J K L M N O]
time 3640ms: Process P (tau 28ms) completed I/O; added to ready queue [Q A C D E F G H I J K L M N O P]
time 3674ms: Process B (tau 105ms) completed a CPU burst; 19 bursts to go [Q A C D E F G H I J K L M N O P]
time 3674ms: Recalculated tau = 175ms for process B [Q A C D E F G H I J K L M N O P]
time 3674ms: Process B switching out of CPU; will block on I/O until time 3789ms [Q A C D E F G H I J K L M N O P]
time 3678ms: Process P (tau 28ms) started using the CPU for 52ms burst [Q A C D E F G H I J K L M N O]
time 3730ms: Process P (tau 28ms) completed a CPU burst; 14 bursts to go [Q A C D E F G H I J K L M N O]
time 3730ms: Recalculated tau = 46ms for process P [Q A C D E F G H I J K L M N O]
time 3730ms: Process P switching out of CPU; will block on I/O until time 3841ms [Q A C D E F G H I J K L M N O]
time 3734ms: Process M (tau 33ms) started using the CPU for 66ms burst [Q A C D E F G H I J K L N O]
time 3789ms: Process B (tau 175ms) completed I/O; added to ready queue [Q A B C D E F G H I J K L N O]
time 3800ms: Process M (tau 33ms) completed a CPU burst; 43 bursts to go [Q A B C D E F G H I J K L N O]
time 3800ms: Recalculated tau = 58ms for process M [Q A B C D E F G H I J K L N O]
time 3800ms: Process M switching out of CPU; will block on I/O until time 3983ms [Q A B C D E F G H I J K L N O]
time 3804ms: Process G (tau 37ms) started using the CPU for 112ms burst [Q A B C D E F H I J K L N O]
time 3841ms: Process P (tau 46ms) completed I/O; added to ready queue [Q A B C D E F H I J K L N O P]
time 3916ms: Process G (tau 37ms) completed a CPU burst; 73 bursts to go [Q A B C D E F H I J K L N O P]
time 3916ms: Recalculated tau = 93ms for process G [Q A B C D E F H I J K L N O P]
time 3916ms: Process G switching out of CPU; will block on I/O until time 3961ms [Q A B C D E F H I J K L N O P]
time 3920ms: Process P (tau 46ms) started using the CPU for 56ms burst [Q A B C D E F H I J K L N O]
time 3961ms: Process G (tau 93ms) completed I/O; added to ready queue [Q A B C D E F G H I J K L N O]
time 3976ms: Process P (tau 46ms) completed a CPU burst; 13 bursts to go [Q A B C D E F G H I J K L N O]
time 3976ms: Recalculated tau = 54ms for process P [Q A B C D E F G H I J K L N O]
time 3976ms: Process P switching out of CPU; will block on I/O until time 4099ms [Q A B C D E F G H I J K L N O]
time 3980ms: Process G (tau 93ms) started using the CPU for 30ms burst [Q A B C D E F H I J K L N O]
time 3983ms: Process M (tau 58ms) completed I/O; added to ready queue [Q A B C D E F H I J K L M N O]
time 4010ms: Process G (tau 93ms) completed a CPU burst; 72 bursts to go [Q A B C D E F H I J K L M N O]
time 4010ms: Recalculated tau = 46ms for process G [Q A B C D E F H I J K L M N O]
time 4010ms: Process G switching out of CPU; will block on I/O until time 4059ms [Q A B C D E F H I J K L M N O]
time 4014ms: Process M (tau 58ms) started using the CPU for 103ms burst [Q A B C D E F H I J K L N O]
time 4059ms: Process G (tau 46ms) completed I/O; added to ready queue [Q A B C D E F G H I J K L N O]
time 4099ms: Process P (tau 54ms) completed I/O; added to ready queue [Q A B C D E F G H I J K L N O P]
time 4117ms: Process M (tau 58ms) completed a CPU burst; 42 bursts to go [Q A B C D E F G H I J K L N O P]
time 4117ms: Recalculated tau = 92ms for process M [Q A B C D E F G H I J K L N O P]
time 4117ms: Process M switching out of CPU; will block on I/O until time 4159ms [Q A B C D E F G H I J K L N O P]
time 4121ms: Process G (tau 46ms) started using the CPU for 50ms burst [Q A B C D E F H I J K L N O P]
time 4159ms: Process M (tau 92ms) completed I/O; added to ready queue [Q A B C D E F H I J K L M N O P]
time 4171ms: Process G (tau 46ms) completed a CPU burst; 71 bursts to go [Q A B C D E F H I J K L M N O P]
time 4171ms: Recalculated tau = 49ms for process G [Q A B C D E F H I J K L M N O P]
time 4171ms: Process G switching out of CPU; will block on I/O until time 4393ms [Q A B C D E F H I J K L M N O P]
time 4175ms: Process P (tau 54ms) started using the CPU for 155ms burst [Q A B C D E F H I J K L M N O]
time 4330ms: Process P (tau 54ms) completed a CPU burst; 12 bursts to go [Q A B C D E F H I J K L M N O]
time 4330ms: Recalculated tau = 130ms for process P [Q A B C D E F H I J K L M N O]
time 4330ms: Process P switching out of CPU; will block on I/O until time 4450ms [Q A B C D E F H I J K L M N O]
time 4334ms: Process M (tau 92ms) started using the CPU for 171ms burst [Q A B C D E F H I J K L N O]
time 4393ms: Process G (tau 49ms) completed I/O; added to ready queue [Q A B C D E F G H I J K L N O]
time 4450ms: Process P (tau 130ms) completed I/O; added to ready queue [Q A B C D E F G H I J K L N O P]
time 4505ms: Process M (tau 92ms) completed a CPU burst; 41 bursts to go [Q A B C D E F G H I J K L N O P]
time 4505ms: Recalculated tau = 151ms for process M [Q A B C D E F G H I J K L N O P]
time 4505ms: Process M switching out of CPU; will block on I/O until time 4528ms [Q A B C D E F G H I J K L N O P]
time 4509ms: Process G (tau 49ms) started using the CPU for 5ms burst [Q A B C D E F H I J K L N O P]
time 4514ms: Process G (tau 49ms) completed a CPU burst; 70 bursts to go [Q A B C D E F H I J K L N O P]
time 4514ms: Recalculated tau = 16ms for process G [Q A B C D E F H I J K L N O P]
time 4514ms: Process G switching out of CPU; will block on I/O until time 4714ms [Q A B C D E F H I J K L N O P]
time 4518ms: Process C (tau 112ms) started using the CPU for 85ms burst [Q A B D E F H I J K L N O P]
time 4528ms: Process M (tau 151ms) completed I/O; added to ready queue [Q A B D E F H I J K L M N O P]
time 4603ms: Process C (tau 112ms) completed a CPU burst; 1 burst to go [Q A B D E F H I J K L M N O P]
time 4603ms: Recalculated tau = 92ms for process C [Q A B D E F H I J K L M N O P]
time 4603ms: Process C switching out of CPU; will block on I/O until time 4626ms [Q A B D E F H I J K L M N O P]
time 4607ms: Process A (tau 115ms) started using the CPU for 64ms burst [Q B D E F H I J K L M N O P]
time 4626ms: Process C (tau 92ms) completed I/O; added to ready queue [Q B C D E F H I J K L M N O P]
time 4671ms: Process A (tau 115ms) completed a CPU burst; 10 bursts to go [Q B C D E F H I J K L M N O P]
time 4671ms: Recalculated tau = 77ms for process A [Q B C D E F H I J K L M N O P]
time 4671ms: Process A switching out of CPU; will block on I/O until time 4688ms [Q B C D E F H I J K L M N O P]
time 4675ms: Process C (tau 92ms) started using the CPU for 79ms burst [Q B D E F H I J K L M N O P]
time 4688ms: Process A (tau 77ms) completed I/O; added to ready queue [Q A B D E F H I J K L M N O P]
time 4714ms: Process G (tau 16ms) completed I/O; added to ready queue [Q A B D E F G H I J K L M N O P]
time 4754ms: Process C terminated [Q A B D E F G H I J K L M N O P]
time 4758ms: Process G (tau 16ms) started using the CPU for 122ms burst [Q A B D E F H I J K L M N O P]
time 4880ms: Process G (tau 16ms) completed a CPU burst; 69 bursts to go [Q A B D E F H I J K L M N O P]
time 4880ms: Recalculated tau = 96ms for process G [Q A B D E F H I J K L M N O P]
time 4880ms: Process G switching out of CPU; will block on I/O until time 4917ms [Q A B D E F H I J K L M N O P]
time 4884ms: Process A (tau 77ms) started using the CPU for 68ms burst [Q B D E F H I J K L M N O P]
time 4917ms: Process G (tau 96ms) completed I/O; added to ready queue [Q B D E F G H I J K L M N O P]
time 4952ms: Process A (tau 77ms) completed a CPU burst; 9 bursts to go [Q B D E F G H I J K L M N O P]
time 4952ms: Recalculated tau = 70ms for process A [Q B D E F G H I J K L M N O P]
time 4952ms: Process A switching out of CPU; will block on I/O until time 5018ms [Q B D E F G H I J K L M N O P]
time 4956ms: Process G (tau 96ms) started using the CPU for 31ms burst [Q B D E F H I J K L M N O P]
time 4987ms: Process G (tau 96ms) completed a CPU burst; 68 bursts to go [Q B D E F H I J K L M N O P]
time 4987ms: Recalculated tau = 47ms for process G [Q B D E F H I J K L M N O P]
time 4987ms: Process G switching out of CPU; will block on I/O until time 4996ms [Q B D E F H I J K L M N O P]
time 4991ms: Process K (tau 120ms) started using the CPU for 104ms burst [Q B D E F H I J L M N O P]
time 4996ms: Process G (tau 47ms) completed I/O; added to ready queue [Q B D E F G H I J L M N O P]
time 5018ms: Process A (tau 70ms) completed I/O; added to ready queue [Q A B D E F G H I J L M N O P]
time 5095ms: Process K (tau 120ms) completed a CPU burst; 7 bursts to go [Q A B D E F G H I J L M N O P]
time 5095ms: Recalculated tau = 108ms for process K [Q A B D E F G H I J L M N O P]
time 5095ms: Process K switching out of CPU; will block on I/O until time 5242ms [Q A B D E F G H I J L M N O P]
time 5099ms: Process G (tau 47ms) started using the CPU for 61ms burst [Q A B D E F H I J L M N O P]
time 5160ms: Process G (tau 47ms) completed a CPU burst; 67 bursts to go [Q A B D E F H I J L M N O P]
time 5160ms: Recalculated tau = 58ms for process G [Q A B D E F H I J L M N O P]
time 5160ms: Process G switching out of CPU; will block on I/O until time 5236ms [Q A B D E F H I J L M N O P]
time 5164ms: Process A (tau 70ms) started using the CPU for 113ms burst [Q B D E F H I J L M N O P]
time 5236ms: Process G (tau 58ms) completed I/O; added to ready queue [Q B D E F G H I J L M N O P]
time 5242ms: Process K (tau 108ms) completed I/O; added to ready queue [Q B D E F G H I J K L M N O P]
time 5277ms: Process A (tau 70ms) completed a CPU burst; 8 bursts to go [Q B D E F G H I J K L M N O P]
time 5277ms: Recalculated tau = 102ms for process A [Q B D E F G H I J K L M N O P]
time 5277ms: Process A switching out of CPU; will block on I/O until time 5295ms [Q B D E F G H I J K L M N O P]
time 5281ms: Process G (tau 58ms) started using the CPU for 7ms burst [Q B D E F H I J K L M N O P]
time 5288ms: Process G (tau 58ms) completed a CPU burst; 66 bursts to go [Q B D E F H I J K L M N O P]
time 5288ms: Recalculated tau = 20ms for process G [Q B D E F H I J K L M N O P]
time 5288ms: Process G switching out of CPU; will block on I/O until time 5454ms [Q B D E F H I J K L M N O P]
time 5292ms: Process K (tau 108ms) started using the CPU for 86ms burst [Q B D E F H I J L M N O P]
time 5295ms: Process A (tau 102ms) completed I/O; added to ready queue [Q A B D E F H I J L M N O P]
time 5378ms: Process K (tau 108ms) completed a CPU burst; 6 bursts to go [Q A B D E F H I J L M N O P]
time 5378ms: Recalculated tau = 92ms for process K [Q A B D E F H I J L M N O P]
time 5378ms: Process K switching out of CPU; will block on I/O until time 5408ms [Q A B D E F H I J L M N O P]
time 5382ms: Process A (tau 102ms) started using the CPU for 11ms burst [Q B D E F H I J L M N O P]
time 5393ms: Process A (tau 102ms) completed a CPU burst; 7 bursts to go [Q B D E F H I J L M N O P]
time 5393ms: Recalculated tau = 34ms for process A [Q B D E F H I J L M N O P]
time 5393ms: Process A switching out of CPU; will block on I/O until time 5557ms [Q B D E F H I J L M N O P]
time 5397ms: Process F (tau 122ms) started using the CPU for 39ms burst [Q B D E H I J L M N O P]
time 5408ms: Process K (tau 92ms) completed I/O; added to ready queue [Q B D E H I J K L M N O P]
time 5436ms: Process F (tau 122ms) completed a CPU burst; 32 bursts to go [Q B D E H I J K L M N O P]
time 5436ms: Recalculated tau = 60ms for process F [Q B D E H I J K L M N O P]
time 5436ms: Process F switching out of CPU; will block on I/O until time 5503ms [Q B D E H I J K L M N O P]
time 5440ms: Process K (tau 92ms) started using the CPU for 50ms burst [Q B D E H I J L M N O P]
time 5454ms: Process G (tau 20ms) completed I/O; added to ready queue [Q B D E G H I J L M N O P]
time 5490ms: Process K (tau 92ms) completed a CPU burst; 5 bursts to go [Q B D E G H I J L M N O P]
time 5490ms: Recalculated tau = 61ms for process K [Q B D E G H I J L M N O P]
time 5490ms: Process K switching out of CPU; will block on I/O until time 5542ms [Q B D E G H I J L M N O P]
time 5494ms: Process G (tau 20ms) started using the CPU for 2ms burst [Q B D E H I J L M N O P]
time 5496ms: Process G (tau 20ms) completed a CPU burst; 65 bursts to go [Q B D E H I J L M N O P]
time 5496ms: Recalculated tau = 7ms for process G [Q B D E H I J L M N O P]
time 5496ms: Process G switching out of CPU; will block on I/O until time 5509ms [Q B D E H I J L M N O P]
time 5500ms: Process L (tau 126ms) started using the CPU for 4ms burst [Q B D E H I J M N O P]
time 5503ms: Process F (tau 60ms) completed I/O; added to ready queue [Q B D E F H I J M N O P]
time 5504ms: Process L (tau 126ms) completed a CPU burst; 5 bursts to go [Q B D E F H I J M N O P]
time 5504ms: Recalculated tau = 35ms for process L [Q B D E F H I J M N O P]
time 5504ms: Process L switching out of CPU; will block on I/O until time 5548ms [Q B D E F H I J M N O P]
time 5508ms: Process F (tau 60ms) started using the CPU for 195ms burst [Q B D E H I J M N O P]
time 5509ms: Process G (tau 7ms) completed I/O; added to ready queue [Q B D E G H I J M N O P]
time 5542ms: Process K (tau 61ms) completed I/O; added to ready queue [Q B D E G H I J K M N O P]
time 5548ms: Process L (tau 35ms) completed I/O; added to ready queue [Q B D E G H I J K L M N O P]
time 5557ms: Process A (tau 34ms) completed I/O; added to ready queue [Q A B D E G H I J K L M N O P]
time 5703ms: Process F (tau 60ms) completed a CPU burst; 31 bursts to go [Q A B D E G H I J K L M N O P]
time 5703ms: Recalculated tau = 161ms for process F [Q A B D E G H I J K L M N O P]
time 5703ms: Process F switching out of CPU; will block on I/O until time 5706ms [Q A B D E G H I J K L M N O P]
time 5706ms: Process F (tau 161ms) completed I/O; added to ready queue [Q A B D E F H I J K L M N O P]
time 5707ms: Process G (tau 7ms) started using the CPU for 209ms burst [Q A B D E F H I J K L M N O P]
time 5916ms: Process G (tau 7ms) completed a CPU burst; 64 bursts to go [Q A B D E F H I J K L M N O P]
time 5916ms: Recalculated tau = 159ms for process G [Q A B D E F H I J K L M N O P]
time 5916ms: Process G switching out of CPU; will block on I/O until time 5966ms [Q A B D E F H I J K L M N O P]
time 5920ms: Process A (tau 34ms) started using the CPU for 24ms burst [Q B D E F H I J K L M N O P]
time 5944ms: Process A (tau 34ms) completed a CPU burst; 6 bursts to go [Q B D E F H I J K L M N O P]
time 5944ms: Recalculated tau = 27ms for process A [Q B D E F H I J K L M N O P]
time 5944ms: Process A switching out of CPU; will block on I/O until time 6063ms [Q B D E F H I J K L M N O P]
time 5948ms: Process L (tau 35ms) started using the CPU for 69ms burst [Q B D E F H I J K M N O P]
time 5966ms: Process G (tau 159ms) completed I/O; added to ready queue [Q B D E F G H I J K M N O P]
time 6017ms: Process L (tau 35ms) completed a CPU burst; 4 bursts to go [Q B D E F G H I J K M N O P]
time 6017ms: Recalculated tau = 61ms for process L [Q B D E F G H I J K M N O P]
time 6017ms: Process L switching out of CPU; will block on I/O until time 6114ms [Q B D E F G H I J K M N O P]
time 6021ms: Process K (tau 61ms) started using the CPU for 4ms burst [Q B D E F G H I J M N O P]
time 6025ms: Process K (tau 61ms) completed a CPU burst; 4 bursts to go [Q B D E F G H I J M N O P]
time 6025ms: Recalculated tau = 18ms for process K [Q B D E F G H I J M N O P]
time 6025ms: Process K switching out of CPU; will block on I/O until time 6087ms [Q B D E F G H I J M N O P]
time 6029ms: Process H (tau 129ms) started using the CPU for 28ms burst [Q B D E F G I J M N O P]
time 6057ms: Process H (tau 129ms) completed a CPU burst; 76 bursts to go [Q B D E F G I J M N O P]
time 6057ms: Recalculated tau = 53ms for process H [Q B D E F G I J M N O P]
time 6057ms: Process H switching out of CPU; will block on I/O until time 6155ms [Q B D E F G I J M N O P]
time 6061ms: Process P (tau 130ms) started using the CPU for 4ms burst [Q B D E F G I J M N O]
time 6063ms: Process A (tau 27ms) completed I/O; added to ready queue [Q A B D E F G I J M N O]
time 6065ms: Process P (tau 130ms) completed a CPU burst; 11 bursts to go [Q A B D E F G I J M N O]
time 6065ms: Recalculated tau = 36ms for process P [Q A B D E F G I J M N O]
time 6065ms: Process P switching out of CPU; will block on I/O until time 6246ms [Q A B D E F G I J M N O]
time 6069ms: Process A (tau 27ms) started using the CPU for 76ms burst [Q B D E F G I J M N O]
time 6087ms: Process K (tau 18ms) completed I/O; added to ready queue [Q B D E F G I J K M N O]
time 6114ms: Process L (tau 61ms) completed I/O; added to ready queue [Q B D E F G I J K L M N O]
time 6145ms: Process A (tau 27ms) completed a CPU burst; 5 bursts to go [Q B D E F G I J K L M N O]
time 6145ms: Recalculated tau = 64ms for process A [Q B D E F G I J K L M N O]
time 6145ms: Process A switching out of CPU; will block on I/O until time 6175ms [Q B D E F G I J K L M N O]
time 6149ms: Process K (tau 18ms) started using the CPU for 21ms burst [Q B D E F G I J L M N O]
time 6155ms: Process H (tau 53ms) completed I/O; added to ready queue [Q B D E F G H I J L M N O]
time 6170ms: Process K (tau 18ms) completed a CPU burst; 3 bursts to go [Q B D E F G H I J L M N O]
time 6170ms: Recalculated tau = 20ms for process K [Q B D E F G H I J L M N O]
time 6170ms: Process K switching out of CPU; will block on I/O until time 6237ms [Q B D E F G H I J L M N O]
time 6174ms: Process H (tau 53ms) started using the CPU for 51ms burst [Q B D E F G I J L M N O]
time 6175ms: Process A (tau 64ms) completed I/O; added to ready queue [Q A B D E F G I J L M N O]
time 6225ms: Process H (tau 53ms) completed a CPU burst; 75 bursts to go [Q A B D E F G I J L M N O]
time 6225ms: Recalculated tau = 52ms for process H [Q A B D E F G I J L M N O]
time 6225ms: Process H switching out of CPU; will block on I/O until time 6250ms [Q A B D E F G I J L M N O]
time 6229ms: Process L (tau 61ms) started using the CPU for 25ms burst [Q A B D E F G I J M N O]
time 6237ms: Process K (tau 20ms) completed I/O; added to ready queue [Q A B D E F G I J K M N O]
time 6246ms: Process P (tau 36ms) completed I/O; added to ready queue [Q A B D E F G I J K M N O P]
time 6250ms: Process H (tau 52ms) completed I/O; added to ready queue [Q A B D E F G H I J K M N O P]
time 6254ms: Process L (tau 61ms) completed a CPU burst; 3 bursts to go [Q A B D E F G H I J K M N O P]
time 6254ms: Recalculated tau = 34ms for process L [Q A B D E F G H I J K M N O P]
time 6254ms: Process L switching out of CPU; will block on I/O until time 6375ms [Q A B D E F G H I J K M N O P]
time 6258ms: Process K (tau 20ms) started using the CPU for 120ms burst [Q A B D E F G H I J M N O P]
time 6375ms: Process L (tau 34ms) completed I/O; added to ready queue [Q A B D E F G H I J L M N O P]
time 6378ms: Process K (tau 20ms) completed a CPU burst; 2 bursts to go [Q A B D E F G H I J L M N O P]
time 6378ms: Recalculated tau = 95ms for process K [Q A B D E F G H I J L M N O P]
time 6378ms: Process K switching out of CPU; will block on I/O until time 6449ms [Q A B D E F G H I J L M N O P]
time 6382ms: Process L (tau 34ms) started using the CPU for 2ms burst [Q A B D E F G H I J M N O P]
time 6384ms: Process L (tau 34ms) completed a CPU burst; 2 bursts to go [Q A B D E F G H I J M N O P]
time 6384ms: Recalculated tau = 10ms for process L [Q A B D E F G H I J M N O P]
time 6384ms: Process L switching out of CPU; will block on I/O until time 6423ms [Q A B D E F G H I J M N O P]
time 6388ms: Process P (tau 36ms) started using the CPU for 105ms burst [Q A B D E F G H I J M N O]
time 6423ms: Process L (tau 10ms) completed I/O; added to ready queue [Q A B D E F G H I J L M N O]
time 6449ms: Process K (tau 95ms) completed I/O; added to ready queue [Q A B D E F G H I J K L M N O]
time 6493ms: Process P (tau 36ms) completed a CPU burst; 10 bursts to go [Q A B D E F G H I J K L M N O]
time 6493ms: Recalculated tau = 88ms for process P [Q A B D E F G H I J K L M N O]
time 6493ms: Process P switching out of CPU; will block on I/O until time 6554ms [Q A B D E F G H I J K L M N O]
time 6497ms: Process L (tau 10ms) started using the CPU for 164ms burst [Q A B D E F G H I J K M N O]
time 6554ms: Process P (tau 88ms) completed I/O; added to ready queue [Q A B D E F G H I J K M N O P]
time 6661ms: Process L (tau 10ms) completed a CPU burst; 1 burst to go [Q A B D E F G H I J K M N O P]
time 6661ms: Recalculated tau = 126ms for process L [Q A B D E F G H I J K M N O P]
time 6661ms: Process L switching out of CPU; will block on I/O until time 6713ms [Q A B D E F G H I J K M N O P]
time 6665ms: Process H (tau 52ms) started using the CPU for 87ms burst [Q A B D E F G I J K M N O P]
time 6713ms: Process L (tau 126ms) completed I/O; added to ready queue [Q A B D E F G I J K L M N O P]
time 6752ms: Process H (tau 52ms) completed a CPU burst; 74 bursts to go [Q A B D E F G I J K L M N O P]
time 6752ms: Recalculated tau = 78ms for process H [Q A B D E F G I J K L M N O P]
time 6752ms: Process H switching out of CPU; will block on I/O until time 6811ms [Q A B D E F G I J K L M N O P]
time 6756ms: Process A (tau 64ms) started using the CPU for 122ms burst [Q B D E F G I J K L M N O P]
time 6811ms: Process H (tau 78ms) completed I/O; added to ready queue [Q B D E F G H I J K L M N O P]
time 6878ms: Process A (tau 64ms) completed a CPU burst; 4 bursts to go [Q B D E F G H I J K L M N O P]
time 6878ms: Recalculated tau = 108ms for process A [Q B D E F G H I J K L M N O P]
time 6878ms: Process A switching out of CPU; will block on I/O until time 6913ms [Q B D E F G H I J K L M N O P]
time 6882ms: Process H (tau 78ms) started using the CPU for 156ms burst [Q B D E F G I J K L M N O P]
time 6913ms: Process A (tau 108ms) completed I/O; added to ready queue [Q A B D E F G I J K L M N O P]
time 7038ms: Process H (tau 78ms) completed a CPU burst; 73 bursts to go [Q A B D E F G I J K L M N O P]
time 7038ms: Recalculated tau = 137ms for process H [Q A B D E F G I J K L M N O P]
time 7038ms: Process H switching out of CPU; will block on I/O until time 7096ms [Q A B D E F G I J K L M N O P]
time 7042ms: Process P (tau 88ms) started using the CPU for 16ms burst [Q A B D E F G I J K L M N O]
time 7058ms: Process P (tau 88ms) completed a CPU burst; 9 bursts to go [Q A B D E F G I J K L M N O]
time 7058ms: Recalculated tau = 34ms for process P [Q A B D E F G I J K L M N O]
time 7058ms: Process P switching out of CPU; will block on I/O until time 7125ms [Q A B D E F G I J K L M N O]
time 7062ms: Process K (tau 95ms) started using the CPU for 199ms burst [Q A B D E F G I J L M N O]
time 7096ms: Process H (tau 137ms) completed I/O; added to ready queue [Q A B D E F G H I J L M N O]
time 7125ms: Process P (tau 34ms) completed I/O; added to ready queue [Q A B D E F G H I J L M N O P]
time 7261ms: Process K (tau 95ms) completed a CPU burst; 1 burst to go [Q A B D E F G H I J L M N O P]
time 7261ms: Recalculated tau = 173ms for process K [Q A B D E F G H I J L M N O P]
time 7261ms: Process K switching out of CPU; will block on I/O until time 7328ms [Q A B D E F G H I J L M N O P]
time 7265ms: Process P (tau 34ms) started using the CPU for 219ms burst [Q A B D E F G H I J L M N O]
time 7328ms: Process K (tau 173ms) completed I/O; added to ready queue [Q A B D E F G H I J K L M N O]
time 7484ms: Process P (tau 34ms) completed a CPU burst; 8 bursts to go [Q A B D E F G H I J K L M N O]
time 7484ms: Recalculated tau = 173ms for process P [Q A B D E F G H I J K L M N O]
time 7484ms: Process P switching out of CPU; will block on I/O until time 7691ms [Q A B D E F G H I J K L M N O]
time 7488ms: Process A (tau 108ms) started using the CPU for 9ms burst [Q B D E F G H I J K L M N O]
time 7497ms: Process A (tau 108ms) completed a CPU burst; 3 bursts to go [Q B D E F G H I J K L M N O]
time 7497ms: Recalculated tau = 34ms for process A [Q B D E F G H I J K L M N O]
time 7497ms: Process A switching out of CPU; will block on I/O until time 7567ms [Q B D E F G H I J K L M N O]
time 7501ms: Process L (tau 126ms) started using the CPU for 111ms burst [Q B D E F G H I J K M N O]
time 7567ms: Process A (tau 34ms) completed I/O; added to ready queue [Q A B D E F G H I J K M N O]
time 7612ms: Process L terminated [Q A B D E F G H I J K M N O]
time 7616ms: Process A (tau 34ms) started using the CPU for 62ms burst [Q B D E F G H I J K M N O]
time 7678ms: Process A (tau 34ms) completed a CPU burst; 2 bursts to go [Q B D E F G H I J K M N O]
time 7678ms: Recalculated tau = 55ms for process A [Q B D E F G H I J K M N O]
time 7678ms: Process A switching out of CPU; will block on I/O until time 7757ms [Q B D E F G H I J K M N O]
time 7682ms: Process D (tau 136ms) started using the CPU for 211ms burst [Q B E F G H I J K M N O]
time 7691ms: Process P (tau 173ms) completed I/O; added to ready queue [Q B E F G H I J K M N O P]
time 7757ms: Process A (tau 55ms) completed I/O; added to ready queue [Q A B E F G H I J K M N O P]
time 7893ms: Process D (tau 136ms) completed a CPU burst; 9 bursts to go [Q A B E F G H I J K M N O P]
time 7893ms: Recalculated tau = 192ms for process D [Q A B E F G H I J K M N O P]
time 7893ms: Process D switching out of CPU; will block on I/O until time 8109ms [Q A B E F G H I J K M N O P]
time 7897ms: Process A (tau 55ms) started using the CPU for 200ms burst [Q B E F G H I J K M N O P]
time 8097ms: Process A (tau 55ms) completed a CPU burst; 1 burst to go [Q B E F G H I J K M N O P]
time 8097ms: Recalculated tau = 164ms for process A [Q B E F G H I J K M N O P]
time 8097ms: Process A switching out of CPU; will block on I/O until time 8110ms [Q B E F G H I J K M N O P]
time 8101ms: Process H (tau 137ms) started using the CPU for 184ms burst [Q B E F G I J K M N O P]
time 8109ms: Process D (tau 192ms) completed I/O; added to ready queue [Q B D E F G I J K M N O P]
time 8110ms: Process A (tau 164ms) completed I/O; added to ready queue [Q A B D E F G I J K M N O P]
time 8285ms: Process H (tau 137ms) completed a CPU burst; 72 bursts to go [Q A B D E F G I J K M N O P]
time 8285ms: Recalculated tau = 172ms for process H [Q A B D E F G I J K M N O P]
time 8285ms: Process H switching out of CPU; will block on I/O until time 8313ms [Q A B D E F G I J K M N O P]
time 8289ms: Process E (tau 139ms) started using the CPU for 44ms burst [Q A B D F G I J K M N O P]
time 8313ms: Process H (tau 172ms) completed I/O; added to ready queue [Q A B D F G H I J K M N O P]
time 8333ms: Process E (tau 139ms) completed a CPU burst; 53 bursts to go [Q A B D F G H I J K M N O P]
time 8333ms: Recalculated tau = 68ms for process E [Q A B D F G H I J K M N O P]
time 8333ms: Process E switching out of CPU; will block on I/O until time 8391ms [Q A B D F G H I J K M N O P]
time 8337ms: Process O (tau 142ms) started using the CPU for 106ms burst [Q A B D F G H I J K M N P]
time 8391ms: Process E (tau 68ms) completed I/O; added to ready queue [Q A B D E F G H I J K M N P]
time 8443ms: Process O (tau 142ms) completed a CPU burst; 29 bursts to go [Q A B D E F G H I J K M N P]
time 8443ms: Recalculated tau = 115ms for process O [Q A B D E F G H I J K M N P]
time 8443ms: Process O switching out of CPU; will block on I/O until time 8694ms [Q A B D E F G H I J K M N P]
time 8447ms: Process E (tau 68ms) started using the CPU for 2ms burst [Q A B D F G H I J K M N P]
time 8449ms: Process E (tau 68ms) completed a CPU burst; 52 bursts to go [Q A B D F G H I J K M N P]
time 8449ms: Recalculated tau = 19ms for process E [Q A B D F G H I J K M N P]
time 8449ms: Process E switching out of CPU; will block on I/O until time 8476ms [Q A B D F G H I J K M N P]
time 8453ms: Process M (tau 151ms) started using the CPU for 200ms burst [Q A B D F G H I J K N P]
time 8476ms: Process E (tau 19ms) completed I/O; added to ready queue [Q A B D E F G H I J K N P]
time 8653ms: Process M (tau 151ms) completed a CPU burst; 40 bursts to go [Q A B D E F G H I J K N P]
time 8653ms: Recalculated tau = 188ms for process M [Q A B D E F G H I J K N P]
time 8653ms: Process M switching out of CPU; will block on I/O until time 8786ms [Q A B D E F G H I J K N P]
time 8657ms: Process E (tau 19ms) started using the CPU for 42ms burst [Q A B D F G H I J K N P]
time 8694ms: Process O (tau 115ms) completed I/O; added to ready queue [Q A B D F G H I J K N O P]
time 8699ms: Process E (tau 19ms) completed a CPU burst; 51 bursts to go [Q A B D F G H I J K N O P]
time 8699ms: Recalculated tau = 36ms for process E [Q A B D F G H I J K N O P]
time 8699ms: Process E switching out of CPU; will block on I/O until time 8706ms [Q A B D F G H I J K N O P]
time 8703ms: Process O (tau 115ms) started using the CPU for 57ms burst [Q A B D F G H I J K N P]
time 8706ms: Process E (tau 36ms) completed I/O; added to ready queue [Q A B D E F G H I J K N P]
time 8760ms: Process O (tau 115ms) completed a CPU burst; 28 bursts to go [Q A B D E F G H I J K N P]
time 8760ms: Recalculated tau = 72ms for process O [Q A B D E F G H I J K N P]
time 8760ms: Process O switching out of CPU; will block on I/O until time 8799ms [Q A B D E F G H I J K N P]
time 8764ms: Process E (tau 36ms) started using the CPU for 108ms burst [Q A B D F G H I J K N P]
time 8786ms: Process M (tau 188ms) completed I/O; added to ready queue [Q A B D F G H I J K M N P]
time 8799ms: Process O (tau 72ms) completed I/O; added to ready queue [Q A B D F G H I J K M N O P]
time 8872ms: Process E (tau 36ms) completed a CPU burst; 50 bursts to go [Q A B D F G H I J K M N O P]
time 8872ms: Recalculated tau = 90ms for process E [Q A B D F G H I J K M N O P]
time 8872ms: Process E switching out of CPU; will block on I/O until time 8883ms [Q A B D F G H I J K M N O P]
time 8876ms: Process O (tau 72ms) started using the CPU for 13ms burst [Q A B D F G H I J K M N P]
time 8883ms: Process E (tau 90ms) completed I/O; added to ready queue [Q A B D E F G H I J K M N P]
time 8889ms: Process O (tau 72ms) completed a CPU burst; 27 bursts to go [Q A B D E F G H I J K M N P]
time 8889ms: Recalculated tau = 28ms for process O [Q A B D E F G H I J K M N P]
time 8889ms: Process O switching out of CPU; will block on I/O until time 9024ms [Q A B D E F G H I J K M N P]
time 8893ms: Process E (tau 90ms) started using the CPU for 6ms burst [Q A B D F G H I J K M N P]
time 8899ms: Process E (tau 90ms) completed a CPU burst; 49 bursts to go [Q A B D F G H I J K M N P]
time 8899ms: Recalculated tau = 27ms for process E [Q A B D F G H I J K M N P]
time 8899ms: Process E switching out of CPU; will block on I/O until time 8933ms [Q A B D F G H I J K M N P]
time 8903ms: Process G (tau 159ms) started using the CPU for 6ms burst [Q A B D F H I J K M N P]
time 8909ms: Process G (tau 159ms) completed a CPU burst; 63 bursts to go [Q A B D F H I J K M N P]
time 8909ms: Recalculated tau = 44ms for process G [Q A B D F H I J K M N P]
time 8909ms: Process G switching out of CPU; will block on I/O until time 9059ms [Q A B D F H I J K M N P]
time 8913ms: Process F (tau 161ms) started using the CPU for 72ms burst [Q A B D H I J K M N P]
time 8933ms: Process E (tau 27ms) completed I/O; added to ready queue [Q A B D E H I J K M N P]
time 8985ms: Process F (tau 161ms) completed a CPU burst; 30 bursts to go [Q A B D E H I J K M N P]
time 8985ms: Recalculated tau = 94ms for process F [Q A B D E H I J K M N P]
time 8985ms: Process F switching out of CPU; will block on I/O until time 9013ms [Q A B D E H I J K M N P]
time 8989ms: Process E (tau 27ms) started using the CPU for 112ms burst [Q A B D H I J K M N P]
time 9013ms: Process F (tau 94ms) completed I/O; added to ready queue [Q A B D F H I J K M N P]
time 9024ms: Process O (tau 28ms) completed I/O; added to ready queue [Q A B D F H I J K M N O P]
time 9059ms: Process G (tau 44ms) completed I/O; added to ready queue [Q A B D F G H I J K M N O P]
time 9101ms: Process E (tau 27ms) completed a CPU burst; 48 bursts to go [Q A B D F G H I J K M N O P]
time 9101ms: Recalculated tau = 91ms for process E [Q A B D F G H I J K M N O P]
time 9101ms: Process E switching out of CPU; will block on I/O until time 9214ms [Q A B D F G H I J K M N O P]
time 9105ms: Process O (tau 28ms) started using the CPU for 130ms burst [Q A B D F G H I J K M N P]
time 9214ms: Process E (tau 91ms) completed I/O; added to ready queue [Q A B D E F G H I J K M N P]
time 9235ms: Process O (tau 28ms) completed a CPU burst; 26 bursts to go [Q A B D E F G H I J K M N P]
time 9235ms: Recalculated tau = 105ms for process O [Q A B D E F G H I J K M N P]
time 9235ms: Process O switching out of CPU; will block on I/O until time 9308ms [Q A B D E F G H I J K M N P]
time 9239ms: Process G (tau 44ms) started using the CPU for 37ms burst [Q A B D E F H I J K M N P]
time 9276ms: Process G (tau 44ms) completed a CPU burst; 62 bursts to go [Q A B D E F H I J K M N P]
time 9276ms: Recalculated tau = 39ms for process G [Q A B D E F H I J K M N P]
time 9276ms: Process G switching out of CPU; will block on I/O until time 9409ms [Q A B D E F H I J K M N P]
time 9280ms: Process E (tau 91ms) started using the CPU for 12ms burst [Q A B D F H I J K M N P]
time 9292ms: Process E (tau 91ms) completed a CPU burst; 47 bursts to go [Q A B D F H I J K M N P]
time 9292ms: Recalculated tau = 32ms for process E [Q A B D F H I J K M N P]
time 9292ms: Process E switching out of CPU; will block on I/O until time 9339ms [Q A B D F H I J K M N P]
time 9296ms: Process F (tau 94ms) started using the CPU for 8ms burst [Q A B D H I J K M N P]
time 9304ms: Process F (tau 94ms) completed a CPU burst; 29 bursts to go [Q A B D H I J K M N P]
time 9304ms: Recalculated tau = 30ms for process F [Q A B D H I J K M N P]
time 9304ms: Process F switching out of CPU; will block on I/O until time 9339ms [Q A B D H I J K M N P]
time 9308ms: Process A (tau 164ms) started using the CPU for 197ms burst [Q B D H I J K M N P]
time 9308ms: Process O (tau 105ms) completed I/O; added to ready queue [Q B D H I J K M N O P]
time 9339ms: Process E (tau 32ms) completed I/O; added to ready queue [Q B D E H I J K M N O P]
time 9340ms: Process F (tau 30ms) completed I/O; added to ready queue [Q B D E F H I J K M N O P]
time 9409ms: Process G (tau 39ms) completed I/O; added to ready queue [Q B D E F G H I J K M N O P]
time 9505ms: Process A terminated [Q B D E F G H I J K M N O P]
time 9509ms: Process F (tau 30ms) started using the CPU for 230ms burst [Q B D E G H I J K M N O P]
time 9739ms: Process F (tau 30ms) completed a CPU burst; 28 bursts to go [Q B D E G H I J K M N O P]
time 9739ms: Recalculated tau = 180ms for process F [Q B D E G H I J K M N O P]
time 9739ms: Process F switching out of CPU; will block on I/O until time 9744ms [Q B D E G H I J K M N O P]
time 9743ms: Process E (tau 32ms) started using the CPU for 9ms burst [Q B D G H I J K M N O P]
time 9744ms: Process F (tau 180ms) completed I/O; added to ready queue [Q B D F G H I J K M N O P]
time 9752ms: Process E (tau 32ms) completed a CPU burst; 46 bursts to go [Q B D F G H I J K M N O P]
time 9752ms: Recalculated tau = 15ms for process E [Q B D F G H I J K M N O P]
time 9752ms: Process E switching out of CPU; will block on I/O until time 9821ms [Q B D F G H I J K M N O P]
time 9756ms: Process G (tau 39ms) started using the CPU for 15ms burst [Q B D F H I J K M N O P]
time 9771ms: Process G (tau 39ms) completed a CPU burst; 61 bursts to go [Q B D F H I J K M N O P]
time 9771ms: Recalculated tau = 21ms for process G [Q B D F H I J K M N O P]
time 9771ms: Process G switching out of CPU; will block on I/O until time 9795ms [Q B D F H I J K M N O P]
time 9775ms: Process O (tau 105ms) started using the CPU for 68ms burst [Q B D F H I J K M N P]
time 9795ms: Process G (tau 21ms) completed I/O; added to ready queue [Q B D F G H I J K M N P]
time 9821ms: Process E (tau 15ms) completed I/O; added to ready queue [Q B D E F G H I J K M N P]
time 9843ms: Process O (tau 105ms) completed a CPU burst; 25 bursts to go [Q B D E F G H I J K M N P]
time 9843ms: Recalculated tau = 77ms for process O [Q B D E F G H I J K M N P]
time 9843ms: Process O switching out of CPU; will block on I/O until time 9962ms [Q B D E F G H I J K M N P]
time 9847ms: Process E (tau 15ms) started using the CPU for 62ms burst [Q B D F G H I J K M N P]
time 9909ms: Process E (tau 15ms) completed a CPU burst; 45 bursts to go [Q B D F G H I J K M N P]
time 9909ms: Recalculated tau = 50ms for process E [Q B D F G H I J K M N P]
time 9909ms: Process E switching out of CPU; will block on I/O until time 9971ms [Q B D F G H I J K M N P]
time 9913ms: Process G (tau 21ms) started using the CPU for 47ms burst [Q B D F H I J K M N P]
time 9960ms: Process G (tau 21ms) completed a CPU burst; 60 bursts to go [Q B D F H I J K M N P]
time 9960ms: Recalculated tau = 41ms for process G [Q B D F H I J K M N P]
time 9960ms: Process G switching out of CPU; will block on I/O until time 10038ms [Q B D F H I J K M N P]
time 9962ms: Process O (tau 77ms) completed I/O; added to ready queue [Q B D F H I K M N O P]
time 9964ms: Process J (tau 167ms) started using the CPU for 28ms burst [Q B D F H I K M N O P]
time 9971ms: Process E (tau 50ms) completed I/O; added to ready queue [Q B D E F H I K M N O P]
time 9992ms: Process J (tau 167ms) completed a CPU burst; 7 bursts to go [Q B D E F H I K M N O P]
time 9992ms: Recalculated tau = 63ms for process J [Q B D E F H I K M N O P]
time 9992ms: Process J switching out of CPU; will block on I/O until time 10016ms [Q B D E F H I K M N O P]
time 9996ms: Process E (tau 50ms) started using the CPU for 213ms burst [Q B D F H I K M N O P]
time 10016ms: Process J (tau 63ms) completed I/O; added to ready queue [Q B D F H I J K M N O P]
time 10038ms: Process G (tau 41ms) completed I/O; added to ready queue [Q B D F G H I J K M N O P]
time 10209ms: Process E (tau 50ms) completed a CPU burst; 44 bursts to go [Q B D F G H I J K M N O P]
time 10209ms: Recalculated tau = 172ms for process E [Q B D F G H I J K M N O P]
time 10209ms: Process E switching out of CPU; will block on I/O until time 10404ms [Q B D F G H I J K M N O P]
time 10213ms: Process G (tau 41ms) started using the CPU for 82ms burst [Q B D F H I J K M N O P]
time 10295ms: Process G (tau 41ms) completed a CPU burst; 59 bursts to go [Q B D F H I J K M N O P]
time 10295ms: Recalculated tau = 72ms for process G [Q B D F H I J K M N O P]
time 10295ms: Process G switching out of CPU; will block on I/O until time 10300ms [Q B D F H I J K M N O P]
time 10299ms: Process J (tau 63ms) started using the CPU for 120ms burst [Q B D F H I K M N O P]
time 10300ms: Process G (tau 72ms) completed I/O; added to ready queue [Q B D F G H I K M N O P]
time 10404ms: Process E (tau 172ms) completed I/O; added to ready queue [Q B D E F G H I K M N O P]
time 10419ms: Process J (tau 63ms) completed a CPU burst; 6 bursts to go [Q B D E F G H I K M N O P]
time 10419ms: Recalculated tau = 106ms for process J [Q B D E F G H I K M N O P]
time 10419ms: Process J switching out of CPU; will block on I/O until time 10477ms [Q B D E F G H I K M N O P]
time 10423ms: Process G (tau 72ms) started using the CPU for 57ms burst [Q B D E F H I K M N O P]
time 10477ms: Process J (tau 106ms) completed I/O; added to ready queue [Q B D E F H I J K M N O P]
time 10480ms: Process G (tau 72ms) completed a CPU burst; 58 bursts to go [Q B D E F H I J K M N O P]
time 10480ms: Recalculated tau = 61ms for process G [Q B D E F H I J K M N O P]
time 10480ms: Process G switching out of CPU; will block on I/O until time 10503ms [Q B D E F H I J K M N O P]
time 10484ms: Process O (tau 77ms) started using the CPU for 136ms burst [Q B D E F H I J K M N P]
time 10503ms: Process G (tau 61ms) completed I/O; added to ready queue [Q B D E F G H I J K M N P]
time 10620ms: Process O (tau 77ms) completed a CPU burst; 24 bursts to go [Q B D E F G H I J K M N P]
time 10620ms: Recalculated tau = 121ms for process O [Q B D E F G H I J K M N P]
time 10620ms: Process O switching out of CPU; will block on I/O until time 10727ms [Q B D E F G H I J K M N P]
time 10624ms: Process G (tau 61ms) started using the CPU for 89ms burst [Q B D E F H I J K M N P]
time 10713ms: Process G (tau 61ms) completed a CPU burst; 57 bursts to go [Q B D E F H I J K M N P]
time 10713ms: Recalculated tau = 82ms for process G [Q B D E F H I J K M N P]
time 10713ms: Process G switching out of CPU; will block on I/O until time 10807ms [Q B D E F H I J K M N P]
time 10717ms: Process J (tau 106ms) started using the CPU for 31ms burst [Q B D E F H I K M N P]
time 10727ms: Process O (tau 121ms) completed I/O; added to ready queue [Q B D E F H I K M N O P]
time 10748ms: Process J (tau 106ms) completed a CPU burst; 5 bursts to go [Q B D E F H I K M N O P]
time 10748ms: Recalculated tau = 50ms for process J [Q B D E F H I K M N O P]
time 10748ms: Process J switching out of CPU; will block on I/O until time 10836ms [Q B D E F H I K M N O P]
time 10752ms: Process O (tau 121ms) started using the CPU for 69ms burst [Q B D E F H I K M N P]
time 10807ms: Process G (tau 82ms) completed I/O; added to ready queue [Q B D E F G H I K M N P]
time 10821ms: Process O (tau 121ms) completed a CPU burst; 23 bursts to go [Q B D E F G H I K M N P]
time 10821ms: Recalculated tau = 82ms for process O [Q B D E F G H I K M N P]
time 10821ms: Process O switching out of CPU; will block on I/O until time 10898ms [Q B D E F G H I K M N P]
time 10825ms: Process G (tau 82ms) started using the CPU for 3ms burst [Q B D E F H I K M N P]
time 10828ms: Process G (tau 82ms) completed a CPU burst; 56 bursts to go [Q B D E F H I K M N P]
time 10828ms: Recalculated tau = 23ms for process G [Q B D E F H I K M N P]
time 10828ms: Process G switching out of CPU; will block on I/O until time 10966ms [Q B D E F H I K M N P]
time 10832ms: Process E (tau 172ms) started using the CPU for 54ms burst [Q B D F H I K M N P]
time 10836ms: Process J (tau 50ms) completed I/O; added to ready queue [Q B D F H I J K M N P]
time 10886ms: Process E (tau 172ms) completed a CPU burst; 43 bursts to go [Q B D F H I J K M N P]
time 10886ms: Recalculated tau = 84ms for process E [Q B D F H I J K M N P]
time 10886ms: Process E switching out of CPU; will block on I/O until time 10983ms [Q B D F H I J K M N P]
time 10890ms: Process J (tau 50ms) started using the CPU for 32ms burst [Q B D F H I K M N P]
time 10898ms: Process O (tau 82ms) completed I/O; added to ready queue [Q B D F H I K M N O P]
time 10922ms: Process J (tau 50ms) completed a CPU burst; 4 bursts to go [Q B D F H I K M N O P]
time 10922ms: Recalculated tau = 37ms for process J [Q B D F H I K M N O P]
time 10922ms: Process J switching out of CPU; will block on I/O until time 10937ms [Q B D F H I K M N O P]
time 10926ms: Process O (tau 82ms) started using the CPU for 6ms burst [Q B D F H I K M N P]
time 10932ms: Process O (tau 82ms) completed a CPU burst; 22 bursts to go [Q B D F H I K M N P]
time 10932ms: Recalculated tau = 25ms for process O [Q B D F H I K M N P]
time 10932ms: Process O switching out of CPU; will block on I/O until time 11098ms [Q B D F H I K M N P]
time 10936ms: Process H (tau 172ms) started using the CPU for 2ms burst [Q B D F I K M N P]
time 10937ms: Process J (tau 37ms) completed I/O; added to ready queue [Q B D F I J K M N P]
time 10938ms: Process H (tau 172ms) completed a CPU burst; 71 bursts to go [Q B D F I J K M N P]
time 10938ms: Recalculated tau = 45ms for process H [Q B D F I J K M N P]
time 10938ms: Process H switching out of CPU; will block on I/O until time 10954ms [Q B D F I J K M N P]
time 10942ms: Process J (tau 37ms) started using the CPU for 23ms burst [Q B D F I K M N P]
time 10954ms: Process H (tau 45ms) completed I/O; added to ready queue [Q B D F H I K M N P]
time 10965ms: Process J (tau 37ms) completed a CPU burst; 3 bursts to go [Q B D F H I K M N P]
time 10965ms: Recalculated tau = 27ms for process J [Q B D F H I K M N P]
time 10965ms: Process J switching out of CPU; will block on I/O until time 10983ms [Q B D F H I K M N P]
time 10966ms: Process G (tau 23ms) completed I/O; added to ready queue [Q B D F G I K M N P]
time 10969ms: Process H (tau 45ms) started using the CPU for 29ms burst [Q B D F G I K M N P]
time 10983ms: Process E (tau 84ms) completed I/O; added to ready queue [Q B D E F G I K M N P]
time 10984ms: Process J (tau 27ms) completed I/O; added to ready queue [Q B D E F G I J K M N P]
time 10998ms: Process H (tau 45ms) completed a CPU burst; 70 bursts to go [Q B D E F G I J K M N P]
time 10998ms: Recalculated tau = 33ms for process H [Q B D E F G I J K M N P]
time 10998ms: Process H switching out of CPU; will block on I/O until time 11222ms [Q B D E F G I J K M N P]
time 11002ms: Process G (tau 23ms) started using the CPU for 11ms burst [Q B D E F I J K M N P]
time 11013ms: Process G (tau 23ms) completed a CPU burst; 55 bursts to go [Q B D E F I J K M N P]
time 11013ms: Recalculated tau = 14ms for process G [Q B D E F I J K M N P]
time 11013ms: Process G switching out of CPU; will block on I/O until time 11260ms [Q B D E F I J K M N P]
time 11017ms: Process J (tau 27ms) started using the CPU for 51ms burst [Q B D E F I K M N P]
time 11068ms: Process J (tau 27ms) completed a CPU burst; 2 bursts to go [Q B D E F I K M N P]
time 11068ms: Recalculated tau = 45ms for process J [Q B D E F I K M N P]
time 11068ms: Process J switching out of CPU; will block on I/O until time 11167ms [Q B D E F I K M N P]
time 11072ms: Process E (tau 84ms) started using the CPU for 126ms burst [Q B D F I K M N P]
time 11098ms: Process O (tau 25ms) completed I/O; added to ready queue [Q B D F I K M N O P]
time 11167ms: Process J (tau 45ms) completed I/O; added to ready queue [Q B D F I J K M N O P]
time 11198ms: Process E (tau 84ms) completed a CPU burst; 42 bursts to go [Q B D F I J K M N O P]
time 11198ms: Recalculated tau = 116ms for process E [Q B D F I J K M N O P]
time 11198ms: Process E switching out of CPU; will block on I/O until time 11398ms [Q B D F I J K M N O P]
time 11202ms: Process O (tau 25ms) started using the CPU for 187ms burst [Q B D F I J K M N P]
time 11222ms: Process H (tau 33ms) completed I/O; added to ready queue [Q B D F H I J K M N P]
time 11260ms: Process G (tau 14ms) completed I/O; added to ready queue [Q B D F G H I J K M N P]
time 11389ms: Process O (tau 25ms) completed a CPU burst; 21 bursts to go [Q B D F G H I J K M N P]
time 11389ms: Recalculated tau = 147ms for process O [Q B D F G H I J K M N P]
time 11389ms: Process O switching out of CPU; will block on I/O until time 11558ms [Q B D F G H I J K M N P]
time 11393ms: Process G (tau 14ms) started using the CPU for 17ms burst [Q B D F H I J K M N P]
time 11398ms: Process E (tau 116ms) completed I/O; added to ready queue [Q B D E F H I J K M N P]
time 11410ms: Process G (tau 14ms) completed a CPU burst; 54 bursts to go [Q B D E F H I J K M N P]
time 11410ms: Recalculated tau = 16ms for process G [Q B D E F H I J K M N P]
time 11410ms: Process G switching out of CPU; will block on I/O until time 11477ms [Q B D E F H I J K M N P]
time 11414ms: Process H (tau 33ms) started using the CPU for 76ms burst [Q B D E F I J K M N P]
time 11477ms: Process G (tau 16ms) completed I/O; added to ready queue [Q B D E F G I J K M N P]
time 11490ms: Process H (tau 33ms) completed a CPU burst; 69 bursts to go [Q B D E F G I J K M N P]
time 11490ms: Recalculated tau = 65ms for process H [Q B D E F G I J K M N P]
time 11490ms: Process H switching out of CPU; will block on I/O until time 11704ms [Q B D E F G I J K M N P]
time 11494ms: Process G (tau 16ms) started using the CPU for 55ms burst [Q B D E F I J K M N P]
time 11549ms: Process G (tau 16ms) completed a CPU burst; 53 bursts to go [Q B D E F I J K M N P]
time 11549ms: Recalculated tau = 45ms for process G [Q B D E F I J K M N P]
time 11549ms: Process G switching out of CPU; will block on I/O until time 11755ms [Q B D E F I J K M N P]
time 11553ms: Process J (tau 45ms) started using the CPU for 216ms burst [Q B D E F I K M N P]
time 11558ms: Process O (tau 147ms) completed I/O; added to ready queue [Q B D E F I K M N O P]
time 11704ms: Process H (tau 65ms) completed I/O; added to ready queue [Q B D E F H I K M N O P]
time 11755ms: Process G (tau 45ms) completed I/O; added to ready queue [Q B D E F G H I K M N O P]
time 11769ms: Process J (tau 45ms) completed a CPU burst; 1 burst to go [Q B D E F G H I K M N O P]
time 11769ms: Recalculated tau = 173ms for process J [Q B D E F G H I K M N O P]
time 11769ms: Process J switching out of CPU; will block on I/O until time 11779ms [Q B D E F G H I K M N O P]
time 11773ms: Process G (tau 45ms) started using the CPU for 52ms burst [Q B D E F H I K M N O P]
time 11779ms: Process J (tau 173ms) completed I/O; added to ready queue [Q B D E F H I J K M N O P]
time 11825ms: Process G (tau 45ms) completed a CPU burst; 52 bursts to go [Q B D E F H I J K M N O P]
time 11825ms: Recalculated tau = 50ms for process G [Q B D E F H I J K M N O P]
time 11825ms: Process G switching out of CPU; will block on I/O until time 11923ms [Q B D E F H I J K M N O P]
time 11829ms: Process H (tau 65ms) started using the CPU for 143ms burst [Q B D E F I J K M N O P]
time 11923ms: Process G (tau 50ms) completed I/O; added to ready queue [Q B D E F G I J K M N O P]
time 11972ms: Process H (tau 65ms) completed a CPU burst; 68 bursts to go [Q B D E F G I J K M N O P]
time 11972ms: Recalculated tau = 124ms for process H [Q B D E F G I J K M N O P]
time 11972ms: Process H switching out of CPU; will block on I/O until time 12158ms [Q B D E F G I J K M N O P]
time 11976ms: Process G (tau 50ms) started using the CPU for 199ms burst [Q B D E F I J K M N O P]
time 12158ms: Process H (tau 124ms) completed I/O; added to ready queue [Q B D E F H I J K M N O P]
time 12175ms: Process G (tau 50ms) completed a CPU burst; 51 bursts to go [Q B D E F H I J K M N O P]
time 12175ms: Recalculated tau = 162ms for process G [Q B D E F H I J K M N O P]
time 12175ms: Process G switching out of CPU; will block on I/O until time 12187ms [Q B D E F H I J K M N O P]
time 12179ms: Process E (tau 116ms) started using the CPU for 168ms burst [Q B D F H I J K M N O P]
time 12187ms: Process G (tau 162ms) completed I/O; added to ready queue [Q B D F G H I J K M N O P]
time 12347ms: Process E (tau 116ms) completed a CPU burst; 41 bursts to go [Q B D F G H I J K M N O P]
time 12347ms: Recalculated tau = 155ms for process E [Q B D F G H I J K M N O P]
time 12347ms: Process E switching out of CPU; will block on I/O until time 12399ms [Q B D F G H I J K M N O P]
time 12351ms: Process H (tau 124ms) started using the CPU for 32ms burst [Q B D F G I J K M N O P]
time 12383ms: Process H (tau 124ms) completed a CPU burst; 67 bursts to go [Q B D F G I J K M N O P]
time 12383ms: Recalculated tau = 55ms for process H [Q B D F G I J K M N O P]
time 12383ms: Process H switching out of CPU; will block on I/O until time 12467ms [Q B D F G I J K M N O P]
time 12387ms: Process O (tau 147ms) started using the CPU for 89ms burst [Q B D F G I J K M N P]
time 12399ms: Process E (tau 155ms) completed I/O; added to ready queue [Q B D E F G I J K M N P]
time 12467ms: Process H (tau 55ms) completed I/O; added to ready queue [Q B D E F G H I J K M N P]
time 12476ms: Process O (tau 147ms) completed a CPU burst; 20 bursts to go [Q B D E F G H I J K M N P]
time 12476ms: Recalculated tau = 104ms for process O [Q B D E F G H I J K M N P]
time 12476ms: Process O switching out of CPU; will block on I/O until time 12618ms [Q B D E F G H I J K M N P]
time 12480ms: Process H (tau 55ms) started using the CPU for 78ms burst [Q B D E F G I J K M N P]
time 12558ms: Process H (tau 55ms) completed a CPU burst; 66 bursts to go [Q B D E F G I J K M N P]
time 12558ms: Recalculated tau = 72ms for process H [Q B D E F G I J K M N P]
time 12558ms: Process H switching out of CPU; will block on I/O until time 12566ms [Q B D E F G I J K M N P]
time 12562ms: Process E (tau 155ms) started using the CPU for 23ms burst [Q B D F G I J K M N P]
time 12566ms: Process H (tau 72ms) completed I/O; added to ready queue [Q B D F G H I J K M N P]
time 12585ms: Process E (tau 155ms) completed a CPU burst; 40 bursts to go [Q B D F G H I J K M N P]
time 12585ms: Recalculated tau = 56ms for process E [Q B D F G H I J K M N P]
time 12585ms: Process E switching out of CPU; will block on I/O until time 12596ms [Q B D F G H I J K M N P]
time 12589ms: Process H (tau 72ms) started using the CPU for 16ms burst [Q B D F G I J K M N P]
time 12596ms: Process E (tau 56ms) completed I/O; added to ready queue [Q B D E F G I J K M N P]
time 12605ms: Process H (tau 72ms) completed a CPU burst; 65 bursts to go [Q B D E F G I J K M N P]
time 12605ms: Recalculated tau = 30ms for process H [Q B D E F G I J K M N P]
time 12605ms: Process H switching out of CPU; will block on I/O until time 12662ms [Q B D E F G I J K M N P]
time 12609ms: Process E (tau 56ms) started using the CPU for 68ms burst [Q B D F G I J K M N P]
time 12618ms: Process O (tau 104ms) completed I/O; added to ready queue [Q B D F G I J K M N O P]
time 12662ms: Process H (tau 30ms) completed I/O; added to ready queue [Q B D F G H I J K M N O P]
time 12677ms: Process E (tau 56ms) completed a CPU burst; 39 bursts to go [Q B D F G H I J K M N O P]
time 12677ms: Recalculated tau = 65ms for process E [Q B D F G H I J K M N O P]
time 12677ms: Process E switching out of CPU; will block on I/O until time 12737ms [Q B D F G H I J K M N O P]
time 12681ms: Process H (tau 30ms) started using the CPU for 142ms burst [Q B D F G I J K M N O P]
time 12737ms: Process E (tau 65ms) completed I/O; added to ready queue [Q B D E F G I J K M N O P]
time 12823ms: Process H (tau 30ms) completed a CPU burst; 64 bursts to go [Q B D E F G I J K M N O P]
time 12823ms: Recalculated tau = 114ms for process H [Q B D E F G I J K M N O P]
time 12823ms: Process H switching out of CPU; will block on I/O until time 12922ms [Q B D E F G I J K M N O P]
time 12827ms: Process E (tau 65ms) started using the CPU for 41ms burst [Q B D F G I J K M N O P]
time 12868ms: Process E (tau 65ms) completed a CPU burst; 38 bursts to go [Q B D F G I J K M N O P]
time 12868ms: Recalculated tau = 47ms for process E [Q B D F G I J K M N O P]
time 12868ms: Process E switching out of CPU; will block on I/O until time 12890ms [Q B D F G I J K M N O P]
time 12872ms: Process O (tau 104ms) started using the CPU for 45ms burst [Q B D F G I J K M N P]
time 12890ms: Process E (tau 47ms) completed I/O; added to ready queue [Q B D E F G I J K M N P]
time 12917ms: Process O (tau 104ms) completed a CPU burst; 19 bursts to go [Q B D E F G I J K M N P]
time 12917ms: Recalculated tau = 60ms for process O [Q B D E F G I J K M N P]
time 12917ms: Process O switching out of CPU; will block on I/O until time 12965ms [Q B D E F G I J K M N P]
time 12921ms: Process E (tau 47ms) started using the CPU for 44ms burst [Q B D F G I J K M N P]
time 12922ms: Process H (tau 114ms) completed I/O; added to ready queue [Q B D F G H I J K M N P]
time 12965ms: Process E (tau 47ms) completed a CPU burst; 37 bursts to go [Q B D F G H I J K M N P]
time 12965ms: Recalculated tau = 45ms for process E [Q B D F G H I J K M N P]
time 12965ms: Process E switching out of CPU; will block on I/O until time 13028ms [Q B D F G H I J K M N P]
time 12965ms: Process O (tau 60ms) completed I/O; added to ready queue [Q B D F G H I J K M N O P]
time 12969ms: Process O (tau 60ms) started using the CPU for 50ms burst [Q B D F G H I J K M N P]
time 13019ms: Process O (tau 60ms) completed a CPU burst; 18 bursts to go [Q B D F G H I J K M N P]
time 13019ms: Recalculated tau = 53ms for process O [Q B D F G H I J K M N P]
time 13019ms: Process O switching out of CPU; will block on I/O until time 13132ms [Q B D F G H I J K M N P]
time 13023ms: Process H (tau 114ms) started using the CPU for 62ms burst [Q B D F G I J K M N P]
time 13028ms: Process E (tau 45ms) completed I/O; added to ready queue [Q B D E F G I J K M N P]
time 13085ms: Process H (tau 114ms) completed a CPU burst; 63 bursts to go [Q B D E F G I J K M N P]
time 13085ms: Recalculated tau = 75ms for process H [Q B D E F G I J K M N P]
time 13085ms: Process H switching out of CPU; will block on I/O until time 13112ms [Q B D E F G I J K M N P]
time 13089ms: Process E (tau 45ms) started using the CPU for 74ms burst [Q B D F G I J K M N P]
time 13112ms: Process H (tau 75ms) completed I/O; added to ready queue [Q B D F G H I J K M N P]
time 13132ms: Process O (tau 53ms) completed I/O; added to ready queue [Q B D F G H I J K M N O P]
time 13163ms: Process E (tau 45ms) completed a CPU burst; 36 bursts to go [Q B D F G H I J K M N O P]
time 13163ms: Recalculated tau = 67ms for process E [Q B D F G H I J K M N O P]
time 13163ms: Process E switching out of CPU; will block on I/O until time 13351ms [Q B D F G H I J K M N O P]
time 13167ms: Process O (tau 53ms) started using the CPU for 133ms burst [Q B D F G H I J K M N P]
time 13300ms: Process O (tau 53ms) completed a CPU burst; 17 bursts to go [Q B D F G H I J K M N P]
time 13300ms: Recalculated tau = 113ms for process O [Q B D F G H I J K M N P]
time 13300ms: Process O switching out of CPU; will block on I/O until time 13430ms [Q B D F G H I J K M N P]
time 13304ms: Process H (tau 75ms) started using the CPU for 248ms burst [Q B D F G I J K M N P]
time 13351ms: Process E (tau 67ms) completed I/O; added to ready queue [Q B D E F G I J K M N P]
time 13430ms: Process O (tau 113ms) completed I/O; added to ready queue [Q B D E F G I J K M N O P]
time 13552ms: Process H (tau 75ms) completed a CPU burst; 62 bursts to go [Q B D E F G I J K M N O P]
time 13552ms: Recalculated tau = 205ms for process H [Q B D E F G I J K M N O P]
time 13552ms: Process H switching out of CPU; will block on I/O until time 13636ms [Q B D E F G I J K M N O P]
time 13556ms: Process E (tau 67ms) started using the CPU for 117ms burst [Q B D F G I J K M N O P]
time 13636ms: Process H (tau 205ms) completed I/O; added to ready queue [Q B D F G H I J K M N O P]
time 13673ms: Process E (tau 67ms) completed a CPU burst; 35 bursts to go [Q B D F G H I J K M N O P]
time 13673ms: Recalculated tau = 105ms for process E [Q B D F G H I J K M N O P]
time 13673ms: Process E switching out of CPU; will block on I/O until time 13775ms [Q B D F G H I J K M N O P]
time 13677ms: Process O (tau 113ms) started using the CPU for 74ms burst [Q B D F G H I J K M N P]
time 13751ms: Process O (tau 113ms) completed a CPU burst; 16 bursts to go [Q B D F G H I J K M N P]
time 13751ms: Recalculated tau = 84ms for process O [Q B D F G H I J K M N P]
time 13751ms: Process O switching out of CPU; will block on I/O until time 13842ms [Q B D F G H I J K M N P]
time 13755ms: Process G (tau 162ms) started using the CPU for 35ms burst [Q B D F H I J K M N P]
time 13775ms: Process E (tau 105ms) completed I/O; added to ready queue [Q B D E F H I J K M N P]
time 13790ms: Process G (tau 162ms) completed a CPU burst; 50 bursts to go [Q B D E F H I J K M N P]
time 13790ms: Recalculated tau = 67ms for process G [Q B D E F H I J K M N P]
time 13790ms: Process G switching out of CPU; will block on I/O until time 13863ms [Q B D E F H I J K M N P]
time 13794ms: Process E (tau 105ms) started using the CPU for 14ms burst [Q B D F H I J K M N P]
time 13808ms: Process E (tau 105ms) completed a CPU burst; 34 bursts to go [Q B D F H I J K M N P]
time 13808ms: Recalculated tau = 37ms for process E [Q B D F H I J K M N P]
time 13808ms: Process E switching out of CPU; will block on I/O until time 13812ms [Q B D F H I J K M N P]
time 13812ms: Process J (tau 173ms) started using the CPU for 7ms burst [Q B D F H I K M N P]
time 13812ms: Process E (tau 37ms) completed I/O; added to ready queue [Q B D E F H I K M N P]
time 13819ms: Process J terminated [Q B D E F H I K M N P]
time 13823ms: Process E (tau 37ms) started using the CPU for 156ms burst [Q B D F H I K M N P]
time 13842ms: Process O (tau 84ms) completed I/O; added to ready queue [Q B D F H I K M N O P]
time 13863ms: Process G (tau 67ms) completed I/O; added to ready queue [Q B D F G H I K M N O P]
time 13979ms: Process E (tau 37ms) completed a CPU burst; 33 bursts to go [Q B D F G H I K M N O P]
time 13979ms: Recalculated tau = 126ms for process E [Q B D F G H I K M N O P]
time 13979ms: Process E switching out of CPU; will block on I/O until time 14081ms [Q B D F G H I K M N O P]
time 13983ms: Process G (tau 67ms) started using the CPU for 44ms burst [Q B D F H I K M N O P]
time 14027ms: Process G (tau 67ms) completed a CPU burst; 49 bursts to go [Q B D F H I K M N O P]
time 14027ms: Recalculated tau = 50ms for process G [Q B D F H I K M N O P]
time 14027ms: Process G switching out of CPU; will block on I/O until time 14053ms [Q B D F H I K M N O P]
time 14031ms: Process O (tau 84ms) started using the CPU for 41ms burst [Q B D F H I K M N P]
time 14053ms: Process G (tau 50ms) completed I/O; added to ready queue [Q B D F G H I K M N P]
time 14072ms: Process O (tau 84ms) completed a CPU burst; 15 bursts to go [Q B D F G H I K M N P]
time 14072ms: Recalculated tau = 52ms for process O [Q B D F G H I K M N P]
time 14072ms: Process O switching out of CPU; will block on I/O until time 14131ms [Q B D F G H I K M N P]
time 14076ms: Process G (tau 50ms) started using the CPU for 27ms burst [Q B D F H I K M N P]
time 14081ms: Process E (tau 126ms) completed I/O; added to ready queue [Q B D E F H I K M N P]
time 14103ms: Process G (tau 50ms) completed a CPU burst; 48 bursts to go [Q B D E F H I K M N P]
time 14103ms: Recalculated tau = 33ms for process G [Q B D E F H I K M N P]
time 14103ms: Process G switching out of CPU; will block on I/O until time 14228ms [Q B D E F H I K M N P]
time 14107ms: Process E (tau 126ms) started using the CPU for 18ms burst [Q B D F H I K M N P]
time 14125ms: Process E (tau 126ms) completed a CPU burst; 32 bursts to go [Q B D F H I K M N P]
time 14125ms: Recalculated tau = 45ms for process E [Q B D F H I K M N P]
time 14125ms: Process E switching out of CPU; will block on I/O until time 14171ms [Q B D F H I K M N P]
time 14129ms: Process K (tau 173ms) started using the CPU for 47ms burst [Q B D F H I M N P]
time 14131ms: Process O (tau 52ms) completed I/O; added to ready queue [Q B D F H I M N O P]
time 14171ms: Process E (tau 45ms) completed I/O; added to ready queue [Q B D E F H I M N O P]
time 14176ms: Process K terminated [Q B D E F H I M N O P]
time 14180ms: Process E (tau 45ms) started using the CPU for 215ms burst [Q B D F H I M N O P]
time 14228ms: Process G (tau 33ms) completed I/O; added to ready queue [Q B D F G H I M N O P]
time 14395ms: Process E (tau 45ms) completed a CPU burst; 31 bursts to go [Q B D F G H I M N O P]
time 14395ms: Recalculated tau = 173ms for process E [Q B D F G H I M N O P]
time 14395ms: Process E switching out of CPU; will block on I/O until time 14406ms [Q B D F G H I M N O P]
time 14399ms: Process G (tau 33ms) started using the CPU for 171ms burst [Q B D F H I M N O P]
time 14406ms: Process E (tau 173ms) completed I/O; added to ready queue [Q B D E F H I M N O P]
time 14570ms: Process G (tau 33ms) completed a CPU burst; 47 bursts to go [Q B D E F H I M N O P]
time 14570ms: Recalculated tau = 137ms for process G [Q B D E F H I M N O P]
time 14570ms: Process G switching out of CPU; will block on I/O until time 14601ms [Q B D E F H I M N O P]
time 14574ms: Process O (tau 52ms) started using the CPU for 57ms burst [Q B D E F H I M N P]
time 14601ms: Process G (tau 137ms) completed I/O; added to ready queue [Q B D E F G H I M N P]
time 14631ms: Process O (tau 52ms) completed a CPU burst; 14 bursts to go [Q B D E F G H I M N P]
time 14631ms: Recalculated tau = 56ms for process O [Q B D E F G H I M N P]
time 14631ms: Process O switching out of CPU; will block on I/O until time 14661ms [Q B D E F G H I M N P]
time 14635ms: Process G (tau 137ms) started using the CPU for 3ms burst [Q B D E F H I M N P]
time 14638ms: Process G (tau 137ms) completed a CPU burst; 46 bursts to go [Q B D E F H I M N P]
time 14638ms: Recalculated tau = 37ms for process G [Q B D E F H I M N P]
time 14638ms: Process G switching out of CPU; will block on I/O until time 14770ms [Q B D E F H I M N P]
time 14642ms: Process E (tau 173ms) started using the CPU for 224ms burst [Q B D F H I M N P]
time 14661ms: Process O (tau 56ms) completed I/O; added to ready queue [Q B D F H I M N O P]
time 14770ms: Process G (tau 37ms) completed I/O; added to ready queue [Q B D F G H I M N O P]
time 14866ms: Process E (tau 173ms) completed a CPU burst; 30 bursts to go [Q B D F G H I M N O P]
time 14866ms: Recalculated tau = 211ms for process E [Q B D F G H I M N O P]
time 14866ms: Process E switching out of CPU; will block on I/O until time 14976ms [Q B D F G H I M N O P]
time 14870ms: Process G (tau 37ms) started using the CPU for 107ms burst [Q B D F H I M N O P]
time 14976ms: Process E (tau 211ms) completed I/O; added to ready queue [Q B D E F H I M N O P]
time 14977ms: Process G (tau 37ms) completed a CPU burst; 45 bursts to go [Q B D E F H I M N O P]
time 14977ms: Recalculated tau = 90ms for process G [Q B D E F H I M N O P]
time 14977ms: Process G switching out of CPU; will block on I/O until time 14996ms [Q B D E F H I M N O P]
time 14981ms: Process O (tau 56ms) started using the CPU for 159ms burst [Q B D E F H I M N P]
time 14996ms: Process G (tau 90ms) completed I/O; added to ready queue [Q B D E F G H I M N P]
time 15140ms: Process O (tau 56ms) completed a CPU burst; 13 bursts to go [Q B D E F G H I M N P]
time 15140ms: Recalculated tau = 133ms for process O [Q B D E F G H I M N P]
time 15140ms: Process O switching out of CPU; will block on I/O until time 15243ms [Q B D E F G H I M N P]
time 15144ms: Process G (tau 90ms) started using the CPU for 111ms burst [Q B D E F H I M N P]
time 15243ms: Process O (tau 133ms) completed I/O; added to ready queue [Q B D E F H I M N O P]
time 15255ms: Process G (tau 90ms) completed a CPU burst; 44 bursts to go [Q B D E F H I M N O P]
time 15255ms: Recalculated tau = 106ms for process G [Q B D E F H I M N O P]
time 15255ms: Process G switching out of CPU; will block on I/O until time 15288ms [Q B D E F H I M N O P]
time 15259ms: Process O (tau 133ms) started using the CPU for 87ms burst [Q B D E F H I M N P]
time 15288ms: Process G (tau 106ms) completed I/O; added to ready queue [Q B D E F G H I M N P]
time 15346ms: Process O (tau 133ms) completed a CPU burst; 12 bursts to go [Q B D E F G H I M N P]
time 15346ms: Recalculated tau = 99ms for process O [Q B D E F G H I M N P]
time 15346ms: Process O switching out of CPU; will block on I/O until time 15509ms [Q B D E F G H I M N P]
time 15350ms: Process G (tau 106ms) started using the CPU for 11ms burst [Q B D E F H I M N P]
time 15361ms: Process G (tau 106ms) completed a CPU burst; 43 bursts to go [Q B D E F H I M N P]
time 15361ms: Recalculated tau = 35ms for process G [Q B D E F H I M N P]
time 15361ms: Process G switching out of CPU; will block on I/O until time 15441ms [Q B D E F H I M N P]
time 15365ms: Process P (tau 173ms) started using the CPU for 70ms burst [Q B D E F H I M N]
time 15435ms: Process P (tau 173ms) completed a CPU burst; 7 bursts to go [Q B D E F H I M N]
time 15435ms: Recalculated tau = 96ms for process P [Q B D E F H I M N]
time 15435ms: Process P switching out of CPU; will block on I/O until time 15564ms [Q B D E F H I M N]
time 15439ms: Process B (tau 175ms) started using the CPU for 208ms burst [Q D E F H I M N]
time 15441ms: Process G (tau 35ms) completed I/O; added to ready queue [Q D E F G H I M N]
time 15509ms: Process O (tau 99ms) completed I/O; added to ready queue [Q D E F G H I M N O]
time 15564ms: Process P (tau 96ms) completed I/O; added to ready queue [Q D E F G H I M N O P]
time 15647ms: Process B (tau 175ms) completed a CPU burst; 18 bursts to go [Q D E F G H I M N O P]
time 15647ms: Recalculated tau = 200ms for process B [Q D E F G H I M N O P]
time 15647ms: Process B switching out of CPU; will block on I/O until time 15811ms [Q D E F G H I M N O P]
time 15651ms: Process G (tau 35ms) started using the CPU for 28ms burst [Q D E F H I M N O P]
time 15679ms: Process G (tau 35ms) completed a CPU burst; 42 bursts to go [Q D E F H I M N O P]
time 15679ms: Recalculated tau = 30ms for process G [Q D E F H I M N O P]
time 15679ms: Process G switching out of CPU; will block on I/O until time 15687ms [Q D E F H I M N O P]
time 15683ms: Process P (tau 96ms) started using the CPU for 55ms burst [Q D E F H I M N O]
time 15687ms: Process G (tau 30ms) completed I/O; added to ready queue [Q D E F G H I M N O]
time 15738ms: Process P (tau 96ms) completed a CPU burst; 6 bursts to go [Q D E F G H I M N O]
time 15738ms: Recalculated tau = 65ms for process P [Q D E F G H I M N O]
time 15738ms: Process P switching out of CPU; will block on I/O until time 15985ms [Q D E F G H I M N O]
time 15742ms: Process G (tau 30ms) started using the CPU for 137ms burst [Q D E F H I M N O]
time 15811ms: Process B (tau 200ms) completed I/O; added to ready queue [Q B D E F H I M N O]
time 15879ms: Process G (tau 30ms) completed a CPU burst; 41 bursts to go [Q B D E F H I M N O]
time 15879ms: Recalculated tau = 110ms for process G [Q B D E F H I M N O]
time 15879ms: Process G switching out of CPU; will block on I/O until time 15936ms [Q B D E F H I M N O]
time 15883ms: Process O (tau 99ms) started using the CPU for 127ms burst [Q B D E F H I M N]
time 15936ms: Process G (tau 110ms) completed I/O; added to ready queue [Q B D E F G H I M N]
time 15985ms: Process P (tau 65ms) completed I/O; added to ready queue [Q B D E F G H I M N P]
time 16010ms: Process O (tau 99ms) completed a CPU burst; 11 bursts to go [Q B D E F G H I M N P]
time 16010ms: Recalculated tau = 120ms for process O [Q B D E F G H I M N P]
time 16010ms: Process O switching out of CPU; will block on I/O until time 16228ms [Q B D E F G H I M N P]
time 16014ms: Process P (tau 65ms) started using the CPU for 212ms burst [Q B D E F G H I M N]
time 16226ms: Process P (tau 65ms) completed a CPU burst; 5 bursts to go [Q B D E F G H I M N]
time 16226ms: Recalculated tau = 175ms for process P [Q B D E F G H I M N]
time 16226ms: Process P switching out of CPU; will block on I/O until time 16445ms [Q B D E F G H I M N]
time 16228ms: Process O (tau 120ms) completed I/O; added to ready queue [Q B D E F H I M N O]
time 16230ms: Process G (tau 110ms) started using the CPU for 124ms burst [Q B D E F H I M N O]
time 16354ms: Process G (tau 110ms) completed a CPU burst; 40 bursts to go [Q B D E F H I M N O]
time 16354ms: Recalculated tau = 121ms for process G [Q B D E F H I M N O]
time 16354ms: Process G switching out of CPU; will block on I/O until time 16431ms [Q B D E F H I M N O]
time 16358ms: Process O (tau 120ms) started using the CPU for 9ms burst [Q B D E F H I M N]
time 16367ms: Process O (tau 120ms) completed a CPU burst; 10 bursts to go [Q B D E F H I M N]
time 16367ms: Recalculated tau = 37ms for process O [Q B D E F H I M N]
time 16367ms: Process O switching out of CPU; will block on I/O until time 16376ms [Q B D E F H I M N]
time 16371ms: Process F (tau 180ms) started using the CPU for 33ms burst [Q B D E H I M N]
time 16376ms: Process O (tau 37ms) completed I/O; added to ready queue [Q B D E H I M N O]
time 16404ms: Process F (tau 180ms) completed a CPU burst; 27 bursts to go [Q B D E H I M N O]
time 16404ms: Recalculated tau = 70ms for process F [Q B D E H I M N O]
time 16404ms: Process F switching out of CPU; will block on I/O until time 16462ms [Q B D E H I M N O]
time 16408ms: Process O (tau 37ms) started using the CPU for 54ms burst [Q B D E H I M N]
time 16431ms: Process G (tau 121ms) completed I/O; added to ready queue [Q B D E G H I M N]
time 16445ms: Process P (tau 175ms) completed I/O; added to ready queue [Q B D E G H I M N P]
time 16462ms: Process O (tau 37ms) completed a CPU burst; 9 bursts to go [Q B D E G H I M N P]
time 16462ms: Recalculated tau = 50ms for process O [Q B D E G H I M N P]
time 16462ms: Process O switching out of CPU; will block on I/O until time 16487ms [Q B D E G H I M N P]
time 16462ms: Process F (tau 70ms) completed I/O; added to ready queue [Q B D E F G H I M N P]
time 16466ms: Process F (tau 70ms) started using the CPU for 76ms burst [Q B D E G H I M N P]
time 16487ms: Process O (tau 50ms) completed I/O; added to ready queue [Q B D E G H I M N O P]
time 16542ms: Process F (tau 70ms) completed a CPU burst; 26 bursts to go [Q B D E G H I M N O P]
time 16542ms: Recalculated tau = 75ms for process F [Q B D E G H I M N O P]
time 16542ms: Process F switching out of CPU; will block on I/O until time 16582ms [Q B D E G H I M N O P]
time 16546ms: Process O (tau 50ms) started using the CPU for 41ms burst [Q B D E G H I M N P]
time 16582ms: Process F (tau 75ms) completed I/O; added to ready queue [Q B D E F G H I M N P]
time 16587ms: Process O (tau 50ms) completed a CPU burst; 8 bursts to go [Q B D E F G H I M N P]
time 16587ms: Recalculated tau = 43ms for process O [Q B D E F G H I M N P]
time 16587ms: Process O switching out of CPU; will block on I/O until time 16616ms [Q B D E F G H I M N P]
time 16591ms: Process F (tau 75ms) started using the CPU for 107ms burst [Q B D E G H I M N P]
time 16616ms: Process O (tau 43ms) completed I/O; added to ready queue [Q B D E G H I M N O P]
time 16698ms: Process F (tau 75ms) completed a CPU burst; 25 bursts to go [Q B D E G H I M N O P]
time 16698ms: Recalculated tau = 99ms for process F [Q B D E G H I M N O P]
time 16698ms: Process F switching out of CPU; will block on I/O until time 16718ms [Q B D E G H I M N O P]
time 16702ms: Process O (tau 43ms) started using the CPU for 190ms burst [Q B D E G H I M N P]
time 16718ms: Process F (tau 99ms) completed I/O; added to ready queue [Q B D E F G H I M N P]
time 16892ms: Process O (tau 43ms) completed a CPU burst; 7 bursts to go [Q B D E F G H I M N P]
time 16892ms: Recalculated tau = 153ms for process O [Q B D E F G H I M N P]
time 16892ms: Process O switching out of CPU; will block on I/O until time 16916ms [Q B D E F G H I M N P]
time 16896ms: Process F (tau 99ms) started using the CPU for 89ms burst [Q B D E G H I M N P]
time 16916ms: Process O (tau 153ms) completed I/O; added to ready queue [Q B D E G H I M N O P]
time 16985ms: Process F (tau 99ms) completed a CPU burst; 24 bursts to go [Q B D E G H I M N O P]
time 16985ms: Recalculated tau = 92ms for process F [Q B D E G H I M N O P]
time 16985ms: Process F switching out of CPU; will block on I/O until time 17070ms [Q B D E G H I M N O P]
time 16989ms: Process G (tau 121ms) started using the CPU for 108ms burst [Q B D E H I M N O P]
time 17070ms: Process F (tau 92ms) completed I/O; added to ready queue [Q B D E F H I M N O P]
time 17097ms: Process G (tau 121ms) completed a CPU burst; 39 bursts to go [Q B D E F H I M N O P]
time 17097ms: Recalculated tau = 111ms for process G [Q B D E F H I M N O P]
time 17097ms: Process G switching out of CPU; will block on I/O until time 17216ms [Q B D E F H I M N O P]
time 17101ms: Process F (tau 92ms) started using the CPU for 102ms burst [Q B D E H I M N O P]
time 17203ms: Process F (tau 92ms) completed a CPU burst; 23 bursts to go [Q B D E H I M N O P]
time 17203ms: Recalculated tau = 100ms for process F [Q B D E H I M N O P]
time 17203ms: Process F switching out of CPU; will block on I/O until time 17340ms [Q B D E H I M N O P]
time 17207ms: Process O (tau 153ms) started using the CPU for 30ms burst [Q B D E H I M N P]
time 17216ms: Process G (tau 111ms) completed I/O; added to ready queue [Q B D E G H I M N P]
time 17237ms: Process O (tau 153ms) completed a CPU burst; 6 bursts to go [Q B D E G H I M N P]
time 17237ms: Recalculated tau = 61ms for process O [Q B D E G H I M N P]
time 17237ms: Process O switching out of CPU; will block on I/O until time 17270ms [Q B D E G H I M N P]
time 17241ms: Process G (tau 111ms) started using the CPU for 110ms burst [Q B D E H I M N P]
time 17270ms: Process O (tau 61ms) completed I/O; added to ready queue [Q B D E H I M N O P]
time 17340ms: Process F (tau 100ms) completed I/O; added to ready queue [Q B D E F H I M N O P]
time 17351ms: Process G (tau 111ms) completed a CPU burst; 38 bursts to go [Q B D E F H I M N O P]
time 17351ms: Recalculated tau = 110ms for process G [Q B D E F H I M N O P]
time 17351ms: Process G switching out of CPU; will block on I/O until time 17510ms [Q B D E F H I M N O P]
time 17355ms: Process O (tau 61ms) started using the CPU for 250ms burst [Q B D E F H I M N P]
time 17510ms: Process G (tau 110ms) completed I/O; added to ready queue [Q B D E F G H I M N P]
time 17605ms: Process O (tau 61ms) completed a CPU burst; 5 bursts to go [Q B D E F G H I M N P]
time 17605ms: Recalculated tau = 203ms for process O [Q B D E F G H I M N P]
time 17605ms: Process O switching out of CPU; will block on I/O until time 17659ms [Q B D E F G H I M N P]
time 17609ms: Process F (tau 100ms) started using the CPU for 147ms burst [Q B D E G H I M N P]
time 17659ms: Process O (tau 203ms) completed I/O; added to ready queue [Q B D E G H I M N O P]
